Workbook

Sheet Summary
A2: Paper: | B2: ISTQB
A4: Human turns | B4: 132 | D4: Writing logs: 114 turns. Peer-review revision: 18 turns.
A5: No substantive next AI reply | B5: 1 | D5: Counts describe visible behavior; category totals can overlap.
A7: Interaction type | B7: Primary count | C7: Any occurrence | D7: Share of prompts | F7: Agency mode | G7: Turns | H7: Share | J7: Expertise evidence | K7: Turns | L7: Share
A8: Delegation | B8: =COUNTIFS(Coding!$E$2:$E$133,A8) -> 7 | C8: =SUM(Coding!P2:P133) -> 7 | D8: =C8/$B$4 -> 0.053030303 | F8: Delegative | G8: =COUNTIFS(Coding!$G$2:$G$133,F8) -> 7 | H8: =G8/$B$4 -> 0.053030303 | J8: domain correction | K8: =SUM(Coding!Y2:Y133) -> 4 | L8: =K8/$B$4 -> 0.03030303
A9: Directed delegation | B9: =COUNTIFS(Coding!$E$2:$E$133,A9) -> 42 | C9: =SUM(Coding!Q2:Q133) -> 80 | D9: =C9/$B$4 -> 0.60606061 | F9: Directive | G9: =COUNTIFS(Coding!$G$2:$G$133,F9) -> 90 | H9: =G9/$B$4 -> 0.68181818 | J9: conceptual discrimination | K9: =SUM(Coding!Z2:Z133) -> 15 | L9: =K9/$B$4 -> 0.11363636
A10: Evaluation | B10: =COUNTIFS(Coding!$E$2:$E$133,A10) -> 6 | C10: =SUM(Coding!R2:R133) -> 16 | D10: =C10/$B$4 -> 0.12121212 | F10: Evaluative | G10: =COUNTIFS(Coding!$G$2:$G$133,F10) -> 5 | H10: =G10/$B$4 -> 0.037878788 | J10: evidence judgment | K10: =SUM(Coding!AA2:AA133) -> 23 | L10: =K10/$B$4 -> 0.17424242
A11: Correction/Challenge | B11: =COUNTIFS(Coding!$E$2:$E$133,A11) -> 20 | C11: =SUM(Coding!S2:S133) -> 23 | D11: =C11/$B$4 -> 0.17424242 | F11: Critical | G11: =COUNTIFS(Coding!$G$2:$G$133,F11) -> 21 | H11: =G11/$B$4 -> 0.15909091 | J11: methodological judgment | K11: =SUM(Coding!AB2:AB133) -> 39 | L11: =K11/$B$4 -> 0.29545455
A12: Redirection | B12: =COUNTIFS(Coding!$E$2:$E$133,A12) -> 5 | C12: =SUM(Coding!T2:T133) -> 23 | D12: =C12/$B$4 -> 0.17424242 | F12: Deliberative | G12: =COUNTIFS(Coding!$G$2:$G$133,F12) -> 9 | H12: =G12/$B$4 -> 0.068181818 | J12: argumentative judgment | K12: =SUM(Coding!AC2:AC133) -> 33 | L12: =K12/$B$4 -> 0.25
A13: Knowledge injection | B13: =COUNTIFS(Coding!$E$2:$E$133,A13) -> 12 | C13: =SUM(Coding!U2:U133) -> 46 | D13: =C13/$B$4 -> 0.34848485 | J13: genre/writing expertise | K13: =SUM(Coding!AD2:AD133) -> 49 | L13: =K13/$B$4 -> 0.37121212
A14: Selection/Rejection | B14: =COUNTIFS(Coding!$E$2:$E$133,A14) -> 32 | C14: =SUM(Coding!V2:V133) -> 40 | D14: =C14/$B$4 -> 0.3030303 | J14: none | K14: =SUM(Coding!AE2:AE133) -> 40 | L14: =K14/$B$4 -> 0.3030303
A15: Deliberation | B15: =COUNTIFS(Coding!$E$2:$E$133,A15) -> 8 | C15: =SUM(Coding!W2:W133) -> 9 | D15: =C15/$B$4 -> 0.068181818
A18: Source / phase | B18: First turn | C18: Last turn | D18: Turns | E18: Delegative | F18: Directive | G18: Evaluative | H18: Critical | I18: Deliberative
A19: Writing log 1 | B19: 1 | C19: 65 | D19: =COUNTIFS(Coding!$C$2:$C$133,A19) -> 65 | E19: =COUNTIFS(Coding!$C$2:$C$133,$A19,Coding!$G$2:$G$133,"Delegative") -> 4 | F19: =COUNTIFS(Coding!$C$2:$C$133,$A19,Coding!$G$2:$G$133,"Directive") -> 43 | G19: =COUNTIFS(Coding!$C$2:$C$133,$A19,Coding!$G$2:$G$133,"Evaluative") -> 4 | H19: =COUNTIFS(Coding!$C$2:$C$133,$A19,Coding!$G$2:$G$133,"Critical") -> 8 | I19: =COUNTIFS(Coding!$C$2:$C$133,$A19,Coding!$G$2:$G$133,"Deliberative") -> 6
A20: Writing log 2 | B20: 66 | C20: 114 | D20: =COUNTIFS(Coding!$C$2:$C$133,A20) -> 49 | E20: =COUNTIFS(Coding!$C$2:$C$133,$A20,Coding!$G$2:$G$133,"Delegative") -> 2 | F20: =COUNTIFS(Coding!$C$2:$C$133,$A20,Coding!$G$2:$G$133,"Directive") -> 35 | G20: =COUNTIFS(Coding!$C$2:$C$133,$A20,Coding!$G$2:$G$133,"Evaluative") -> 1 | H20: =COUNTIFS(Coding!$C$2:$C$133,$A20,Coding!$G$2:$G$133,"Critical") -> 9 | I20: =COUNTIFS(Coding!$C$2:$C$133,$A20,Coding!$G$2:$G$133,"Deliberative") -> 2
A21: Peer-review revision | B21: 115 | C21: 132 | D21: =COUNTIFS(Coding!$C$2:$C$133,A21) -> 18 | E21: =COUNTIFS(Coding!$C$2:$C$133,$A21,Coding!$G$2:$G$133,"Delegative") -> 1 | F21: =COUNTIFS(Coding!$C$2:$C$133,$A21,Coding!$G$2:$G$133,"Directive") -> 12 | G21: =COUNTIFS(Coding!$C$2:$C$133,$A21,Coding!$G$2:$G$133,"Evaluative") -> 0 | H21: =COUNTIFS(Coding!$C$2:$C$133,$A21,Coding!$G$2:$G$133,"Critical") -> 4 | I21: =COUNTIFS(Coding!$C$2:$C$133,$A21,Coding!$G$2:$G$133,"Deliberative") -> 1
A25: Source / phase | B25: Expertise observed | C25: None observed | D25: Share with evidence
A26: Writing log 1 | B26: =D19-C26 -> 50 | C26: =SUMIFS(Coding!$AE$2:$AE$133,Coding!$C$2:$C$133,A26) -> 15 | D26: =B26/D19 -> 0.76923077
A27: Writing log 2 | B27: =D20-C27 -> 28 | C27: =SUMIFS(Coding!$AE$2:$AE$133,Coding!$C$2:$C$133,A27) -> 21 | D27: =B27/D20 -> 0.57142857
A28: Peer-review revision | B28: =D21-C28 -> 14 | C28: =SUMIFS(Coding!$AE$2:$AE$133,Coding!$C$2:$C$133,A28) -> 4 | D28: =B28/D21 -> 0.77777778
A31: Key patterns and limits
A32: Directive agency: 90/132 (68.2%). Critical: 21 (15.9%). Deliberative: 9 (6.8%). Delegative: 7 (5.3%). Evaluative: 5 (3.8%).
A33: Constrained execution is frequent: Directed delegation appears in 80 turns (60.6%). Selection/Rejection appears in 40 (30.3%), including brief approvals.
A34: Positive expertise evidence appears in 92 turns (69.7%). Genre/writing: 49; methodological: 39; argumentative: 33; evidence judgment: 23.
A35: Early framing develops through scope decisions: Value/Use/Critique becomes Value/Critique (12–19), then ISTQB’s technical and pedagogical role is added (27–31).
A36: Conceptual scrutiny qualifies STBoK and prior knowledge (49–53), de-facto standard (96), and overlapping criticism themes (102/107).
A37: Evidence control intensifies in writing log 2: pool reconciliation and reported URL checks (76–79), paragraph-level traceability (85–91), and source attribution challenges (104–105).
A38: Revision remains actively directed: 12/18 Directive, 4/18 Critical. The researcher corrects the grey-literature argument and distinguishes manuscript from response-letter prose (122–128).
A39: Researcher judgment must be separated from reviewer input. Supplying a reviewer’s construct-validity critique (131) does not itself demonstrate the researcher originated that critique.
A40: Unverified AI completion claims recur: simulated search (63), filtering explanation (76), thematic convergence (121), and prior expert definitions (131). Outcomes record what AI says.
A41: One missing AI reply (78); an embedded block of prior prompts (79); an ambiguous setup cue (115). All remain in sequence, with row-level cautions.
A42: Single first-pass coding. Counts are category presence, not intensity or competence. Paper 1’s incomplete record limits cross-paper comparisons.

Sheet Coding
A1: Turn ID | B1: Sequence | C1: Phase | D1: Prompt excerpt | E1: Primary interaction type | F1: Additional interaction types | G1: Agency mode | H1: Expertise evidence | I1: Coding rationale | J1: Observed outcome / notes | K1: Prompt provenance | L1: Response provenance | M1: Attachment / contextual material | N1: Response availability | O1: Coding caution | P1: Open Delegation | Q1: Directed delegation | R1: Evaluation | S1: Correction/Challenge | T1: Redirection | U1: Knowledge injection | V1: Acceptance/ Rejection | W1: Deliberation | X1: Expertise | Y1: Subject-matter correction | Z1: Conceptual differentiation | AA1: Evidence judgment | AB1: Methodological judgment | AC1: Argumentative judgment | AD1: Genre/ writing expertise | AE1: none
A2: P7-W1-001 | B2: 1 | C2: Writing log 1 | D2: ISTQB has 22+ Certifications (https://istqb.org/certifications/). each come with a comprehensive Syllabus PDF file (I attach three of them). suggest interesting "exploratory" / insightful paper topic on these Syllabuses | E2: Directed delegation | F2: Knowledge injection | G2: Directive | H2: none | I2: Specifies syllabus-based exploratory topic generation and supplies materials; no explicit analytical judgment yet. | J2: AI proposes seven syllabus-based topics. | K2: W1 p1 L4-p1 L5 | L2: W1 p1 L7-p1 L30 | M2: Referenced attachment/material; attachment contents are not separate human turns. | N2: Visible next AI response | O2: Syllabus attachment contents are not separately present in the log export. Attachment provision alone is not evidence of expertise. | P2: =IF(OR(E2="Delegation",ISNUMBER(SEARCH("; Delegation; ","; "&F2&"; "))),1,0) -> 0 | Q2: =IF(OR(E2="Directed delegation",ISNUMBER(SEARCH("; Directed delegation; ","; "&F2&"; "))),1,0) -> 1 | R2: =IF(OR(E2="Evaluation",ISNUMBER(SEARCH("; Evaluation; ","; "&F2&"; "))),1,0) -> 0 | S2: =IF(OR(E2="Correction/Challenge",ISNUMBER(SEARCH("; Correction/Challenge; ","; "&F2&"; "))),1,0) -> 0 | T2: =IF(OR(E2="Redirection",ISNUMBER(SEARCH("; Redirection; ","; "&F2&"; "))),1,0) -> 0 | U2: =IF(OR(E2="Knowledge injection",ISNUMBER(SEARCH("; Knowledge injection; ","; "&F2&"; "))),1,0) -> 1 | V2: =IF(OR(E2="Selection/Rejection",ISNUMBER(SEARCH("; Selection/Rejection; ","; "&F2&"; "))),1,0) -> 0 | W2: =IF(OR(E2="Deliberation",ISNUMBER(SEARCH("; Deliberation; ","; "&F2&"; "))),1,0) -> 0 | X2: =SUM(Paper7Coding[[#This Row],[Subject-matter correction]:[Genre/ writing expertise]]) -> 0 | Y2: =IF(ISNUMBER(SEARCH("; domain correction; ","; "&H2&"; ")),1,0) -> 0 | Z2: =IF(ISNUMBER(SEARCH("; conceptual discrimination; ","; "&H2&"; ")),1,0) -> 0 | AA2: =IF(ISNUMBER(SEARCH("; evidence judgment; ","; "&H2&"; ")),1,0) -> 0 | AB2: =IF(ISNUMBER(SEARCH("; methodological judgment; ","; "&H2&"; ")),1,0) -> 0 | AC2: =IF(ISNUMBER(SEARCH("; argumentative judgment; ","; "&H2&"; ")),1,0) -> 0 | AD2: =IF(ISNUMBER(SEARCH("; genre/writing expertise; ","; "&H2&"; ")),1,0) -> 0 | AE2: =IF(ISNUMBER(SEARCH("; none; ","; "&H2&"; ")),1,0) -> 1
A3: P7-W1-002 | B3: 2 | C3: Writing log 1 | D3: I did not like those topic. they do not seem to be useful | E3: Correction/Challenge | F3: Selection/Rejection | G3: Critical | H3: argumentative judgment | I3: Rejects the proposed topics using their perceived usefulness as the criterion. | J3: AI proposes more pragmatic topics. | K3: W1 p1 L32-p1 L32 | L3: W1 p1 L34-p2 L12 | N3: Visible next AI response | P3: =IF(OR(E3="Delegation",ISNUMBER(SEARCH("; Delegation; ","; "&F3&"; "))),1,0) -> 0 | Q3: =IF(OR(E3="Directed delegation",ISNUMBER(SEARCH("; Directed delegation; ","; "&F3&"; "))),1,0) -> 0 | R3: =IF(OR(E3="Evaluation",ISNUMBER(SEARCH("; Evaluation; ","; "&F3&"; "))),1,0) -> 0 | S3: =IF(OR(E3="Correction/Challenge",ISNUMBER(SEARCH("; Correction/Challenge; ","; "&F3&"; "))),1,0) -> 1 | T3: =IF(OR(E3="Redirection",ISNUMBER(SEARCH("; Redirection; ","; "&F3&"; "))),1,0) -> 0 | U3: =IF(OR(E3="Knowledge injection",ISNUMBER(SEARCH("; Knowledge injection; ","; "&F3&"; "))),1,0) -> 0 | V3: =IF(OR(E3="Selection/Rejection",ISNUMBER(SEARCH("; Selection/Rejection; ","; "&F3&"; "))),1,0) -> 1 | W3: =IF(OR(E3="Deliberation",ISNUMBER(SEARCH("; Deliberation; ","; "&F3&"; "))),1,0) -> 0 | X3: =SUM(Paper7Coding[[#This Row],[Subject-matter correction]:[Genre/ writing expertise]]) -> 1 | Y3: =IF(ISNUMBER(SEARCH("; domain correction; ","; "&H3&"; ")),1,0) -> 0 | Z3: =IF(ISNUMBER(SEARCH("; conceptual discrimination; ","; "&H3&"; ")),1,0) -> 0 | AA3: =IF(ISNUMBER(SEARCH("; evidence judgment; ","; "&H3&"; ")),1,0) -> 0 | AB3: =IF(ISNUMBER(SEARCH("; methodological judgment; ","; "&H3&"; ")),1,0) -> 0 | AC3: =IF(ISNUMBER(SEARCH("; argumentative judgment; ","; "&H3&"; ")),1,0) -> 1 | AD3: =IF(ISNUMBER(SEARCH("; genre/writing expertise; ","; "&H3&"; ")),1,0) -> 0 | AE3: =IF(ISNUMBER(SEARCH("; none; ","; "&H3&"; ")),1,0) -> 0
A4: P7-W1-003 | B4: 3 | C4: Writing log 1 | D4: let's change gears. what about a paper which reviews all benefits / criticism of the ISTQB Certifications, by sntheszing knowledge from the grey literature (online sources) | E4: Redirection | F4: Directed delegation; Knowledge injection | G4: Directive | H4: methodological judgment; argumentative judgment | I4: Reframes the project as synthesis of certification benefits and criticisms from grey literature. | J4: AI develops a grey-literature review framing and outline. | K4: W1 p2 L14-p2 L15 | L4: W1 p2 L17-p2 L37 | N4: Visible next AI response | P4: =IF(OR(E4="Delegation",ISNUMBER(SEARCH("; Delegation; ","; "&F4&"; "))),1,0) -> 0 | Q4: =IF(OR(E4="Directed delegation",ISNUMBER(SEARCH("; Directed delegation; ","; "&F4&"; "))),1,0) -> 1 | R4: =IF(OR(E4="Evaluation",ISNUMBER(SEARCH("; Evaluation; ","; "&F4&"; "))),1,0) -> 0 | S4: =IF(OR(E4="Correction/Challenge",ISNUMBER(SEARCH("; Correction/Challenge; ","; "&F4&"; "))),1,0) -> 0 | T4: =IF(OR(E4="Redirection",ISNUMBER(SEARCH("; Redirection; ","; "&F4&"; "))),1,0) -> 1 | U4: =IF(OR(E4="Knowledge injection",ISNUMBER(SEARCH("; Knowledge injection; ","; "&F4&"; "))),1,0) -> 1 | V4: =IF(OR(E4="Selection/Rejection",ISNUMBER(SEARCH("; Selection/Rejection; ","; "&F4&"; "))),1,0) -> 0 | W4: =IF(OR(E4="Deliberation",ISNUMBER(SEARCH("; Deliberation; ","; "&F4&"; "))),1,0) -> 0 | X4: =SUM(Paper7Coding[[#This Row],[Subject-matter correction]:[Genre/ writing expertise]]) -> 2 | Y4: =IF(ISNUMBER(SEARCH("; domain correction; ","; "&H4&"; ")),1,0) -> 0 | Z4: =IF(ISNUMBER(SEARCH("; conceptual discrimination; ","; "&H4&"; ")),1,0) -> 0 | AA4: =IF(ISNUMBER(SEARCH("; evidence judgment; ","; "&H4&"; ")),1,0) -> 0 | AB4: =IF(ISNUMBER(SEARCH("; methodological judgment; ","; "&H4&"; ")),1,0) -> 1 | AC4: =IF(ISNUMBER(SEARCH("; argumentative judgment; ","; "&H4&"; ")),1,0) -> 1 | AD4: =IF(ISNUMBER(SEARCH("; genre/writing expertise; ","; "&H4&"; ")),1,0) -> 0 | AE4: =IF(ISNUMBER(SEARCH("; none; ","; "&H4&"; ")),1,0) -> 0
A5: P7-W1-004 | B5: 4 | C5: Writing log 1 | D5: by doing deep research, can you identify all grey sources talking about Criticisms, and synthesize / cateogrize them? | E5: Directed delegation | G5: Directive | H5: methodological judgment | I5: Requests research and categorization focused on criticisms, defining the review task. | J5: AI asks for scope clarification before research. | K5: W1 p2 L39-p2 L40 | L5: W1 p2 L42-p3 L2 | N5: Visible next AI response | P5: =IF(OR(E5="Delegation",ISNUMBER(SEARCH("; Delegation; ","; "&F5&"; "))),1,0) -> 0 | Q5: =IF(OR(E5="Directed delegation",ISNUMBER(SEARCH("; Directed delegation; ","; "&F5&"; "))),1,0) -> 1 | R5: =IF(OR(E5="Evaluation",ISNUMBER(SEARCH("; Evaluation; ","; "&F5&"; "))),1,0) -> 0 | S5: =IF(OR(E5="Correction/Challenge",ISNUMBER(SEARCH("; Correction/Challenge; ","; "&F5&"; "))),1,0) -> 0 | T5: =IF(OR(E5="Redirection",ISNUMBER(SEARCH("; Redirection; ","; "&F5&"; "))),1,0) -> 0 | U5: =IF(OR(E5="Knowledge injection",ISNUMBER(SEARCH("; Knowledge injection; ","; "&F5&"; "))),1,0) -> 0 | V5: =IF(OR(E5="Selection/Rejection",ISNUMBER(SEARCH("; Selection/Rejection; ","; "&F5&"; "))),1,0) -> 0 | W5: =IF(OR(E5="Deliberation",ISNUMBER(SEARCH("; Deliberation; ","; "&F5&"; "))),1,0) -> 0 | X5: =SUM(Paper7Coding[[#This Row],[Subject-matter correction]:[Genre/ writing expertise]]) -> 1 | Y5: =IF(ISNUMBER(SEARCH("; domain correction; ","; "&H5&"; ")),1,0) -> 0 | Z5: =IF(ISNUMBER(SEARCH("; conceptual discrimination; ","; "&H5&"; ")),1,0) -> 0 | AA5: =IF(ISNUMBER(SEARCH("; evidence judgment; ","; "&H5&"; ")),1,0) -> 0 | AB5: =IF(ISNUMBER(SEARCH("; methodological judgment; ","; "&H5&"; ")),1,0) -> 1 | AC5: =IF(ISNUMBER(SEARCH("; argumentative judgment; ","; "&H5&"; ")),1,0) -> 0 | AD5: =IF(ISNUMBER(SEARCH("; genre/writing expertise; ","; "&H5&"; ")),1,0) -> 0 | AE5: =IF(ISNUMBER(SEARCH("; none; ","; "&H5&"; ")),1,0) -> 0
A6: P7-W1-005 | B6: 5 | C6: Writing log 1 | D6: RE: Should I focus on criticisms of all ISTQB certifications (e.g., Foundation, Advanced, Specialist), or just the Foundation Level? all. in your results, also give the criticisms per levels (e.g., Foundation, Advanced, Specialist) RE:Do you want a global perspective, or focus on specific regions… | E6: Directed delegation | F6: Selection/Rejection | G6: Directive | H6: methodological judgment | I6: Defines coverage across levels, regions and stakeholder roles and requests separate reporting. | J6: AI supplies a categorized criticism overview after announcing research. | K6: W1 p3 L4-p3 L12 | L6: W1 p3 L14-p10 L13 | N6: Visible next AI response | P6: =IF(OR(E6="Delegation",ISNUMBER(SEARCH("; Delegation; ","; "&F6&"; "))),1,0) -> 0 | Q6: =IF(OR(E6="Directed delegation",ISNUMBER(SEARCH("; Directed delegation; ","; "&F6&"; "))),1,0) -> 1 | R6: =IF(OR(E6="Evaluation",ISNUMBER(SEARCH("; Evaluation; ","; "&F6&"; "))),1,0) -> 0 | S6: =IF(OR(E6="Correction/Challenge",ISNUMBER(SEARCH("; Correction/Challenge; ","; "&F6&"; "))),1,0) -> 0 | T6: =IF(OR(E6="Redirection",ISNUMBER(SEARCH("; Redirection; ","; "&F6&"; "))),1,0) -> 0 | U6: =IF(OR(E6="Knowledge injection",ISNUMBER(SEARCH("; Knowledge injection; ","; "&F6&"; "))),1,0) -> 0 | V6: =IF(OR(E6="Selection/Rejection",ISNUMBER(SEARCH("; Selection/Rejection; ","; "&F6&"; "))),1,0) -> 1 | W6: =IF(OR(E6="Deliberation",ISNUMBER(SEARCH("; Deliberation; ","; "&F6&"; "))),1,0) -> 0 | X6: =SUM(Paper7Coding[[#This Row],[Subject-matter correction]:[Genre/ writing expertise]]) -> 1 | Y6: =IF(ISNUMBER(SEARCH("; domain correction; ","; "&H6&"; ")),1,0) -> 0 | Z6: =IF(ISNUMBER(SEARCH("; conceptual discrimination; ","; "&H6&"; ")),1,0) -> 0 | AA6: =IF(ISNUMBER(SEARCH("; evidence judgment; ","; "&H6&"; ")),1,0) -> 0 | AB6: =IF(ISNUMBER(SEARCH("; methodological judgment; ","; "&H6&"; ")),1,0) -> 1 | AC6: =IF(ISNUMBER(SEARCH("; argumentative judgment; ","; "&H6&"; ")),1,0) -> 0 | AD6: =IF(ISNUMBER(SEARCH("; genre/writing expertise; ","; "&H6&"; ")),1,0) -> 0 | AE6: =IF(ISNUMBER(SEARCH("; none; ","; "&H6&"; ")),1,0) -> 0
A7: P7-W1-006 | B7: 6 | C7: Writing log 1 | D7: good stuff. keep these in mind to include them in the paper, that we will write;. do not forget them ! | E7: Selection/Rejection | F7: Directed delegation | G7: Directive | H7: none | I7: Approves the findings and asks AI to retain them; no substantive assessment criteria are given. | J7: AI acknowledges a request to remember findings. | K7: W1 p10 L15-p10 L15 | L7: W1 p10 L17-p10 L18 | N7: Visible next AI response | P7: =IF(OR(E7="Delegation",ISNUMBER(SEARCH("; Delegation; ","; "&F7&"; "))),1,0) -> 0 | Q7: =IF(OR(E7="Directed delegation",ISNUMBER(SEARCH("; Directed delegation; ","; "&F7&"; "))),1,0) -> 1 | R7: =IF(OR(E7="Evaluation",ISNUMBER(SEARCH("; Evaluation; ","; "&F7&"; "))),1,0) -> 0 | S7: =IF(OR(E7="Correction/Challenge",ISNUMBER(SEARCH("; Correction/Challenge; ","; "&F7&"; "))),1,0) -> 0 | T7: =IF(OR(E7="Redirection",ISNUMBER(SEARCH("; Redirection; ","; "&F7&"; "))),1,0) -> 0 | U7: =IF(OR(E7="Knowledge injection",ISNUMBER(SEARCH("; Knowledge injection; ","; "&F7&"; "))),1,0) -> 0 | V7: =IF(OR(E7="Selection/Rejection",ISNUMBER(SEARCH("; Selection/Rejection; ","; "&F7&"; "))),1,0) -> 1 | W7: =IF(OR(E7="Deliberation",ISNUMBER(SEARCH("; Deliberation; ","; "&F7&"; "))),1,0) -> 0 | X7: =SUM(Paper7Coding[[#This Row],[Subject-matter correction]:[Genre/ writing expertise]]) -> 0 | Y7: =IF(ISNUMBER(SEARCH("; domain correction; ","; "&H7&"; ")),1,0) -> 0 | Z7: =IF(ISNUMBER(SEARCH("; conceptual discrimination; ","; "&H7&"; ")),1,0) -> 0 | AA7: =IF(ISNUMBER(SEARCH("; evidence judgment; ","; "&H7&"; ")),1,0) -> 0 | AB7: =IF(ISNUMBER(SEARCH("; methodological judgment; ","; "&H7&"; ")),1,0) -> 0 | AC7: =IF(ISNUMBER(SEARCH("; argumentative judgment; ","; "&H7&"; ")),1,0) -> 0 | AD7: =IF(ISNUMBER(SEARCH("; genre/writing expertise; ","; "&H7&"; ")),1,0) -> 0 | AE7: =IF(ISNUMBER(SEARCH("; none; ","; "&H7&"; ")),1,0) -> 1
A8: P7-W1-007 | B8: 7 | C8: Writing log 1 | D8: suggest a few other paper title alternatives | E8: Delegation | G8: Delegative | H8: none | I8: Requests title alternatives with little new specification. | J8: AI offers title alternatives. | K8: W1 p10 L20-p10 L20 | L8: W1 p10 L22-p11 L2 | N8: Visible next AI response | P8: =IF(OR(E8="Delegation",ISNUMBER(SEARCH("; Delegation; ","; "&F8&"; "))),1,0) -> 1 | Q8: =IF(OR(E8="Directed delegation",ISNUMBER(SEARCH("; Directed delegation; ","; "&F8&"; "))),1,0) -> 0 | R8: =IF(OR(E8="Evaluation",ISNUMBER(SEARCH("; Evaluation; ","; "&F8&"; "))),1,0) -> 0 | S8: =IF(OR(E8="Correction/Challenge",ISNUMBER(SEARCH("; Correction/Challenge; ","; "&F8&"; "))),1,0) -> 0 | T8: =IF(OR(E8="Redirection",ISNUMBER(SEARCH("; Redirection; ","; "&F8&"; "))),1,0) -> 0 | U8: =IF(OR(E8="Knowledge injection",ISNUMBER(SEARCH("; Knowledge injection; ","; "&F8&"; "))),1,0) -> 0 | V8: =IF(OR(E8="Selection/Rejection",ISNUMBER(SEARCH("; Selection/Rejection; ","; "&F8&"; "))),1,0) -> 0 | W8: =IF(OR(E8="Deliberation",ISNUMBER(SEARCH("; Deliberation; ","; "&F8&"; "))),1,0) -> 0 | X8: =SUM(Paper7Coding[[#This Row],[Subject-matter correction]:[Genre/ writing expertise]]) -> 0 | Y8: =IF(ISNUMBER(SEARCH("; domain correction; ","; "&H8&"; ")),1,0) -> 0 | Z8: =IF(ISNUMBER(SEARCH("; conceptual discrimination; ","; "&H8&"; ")),1,0) -> 0 | AA8: =IF(ISNUMBER(SEARCH("; evidence judgment; ","; "&H8&"; ")),1,0) -> 0 | AB8: =IF(ISNUMBER(SEARCH("; methodological judgment; ","; "&H8&"; ")),1,0) -> 0 | AC8: =IF(ISNUMBER(SEARCH("; argumentative judgment; ","; "&H8&"; ")),1,0) -> 0 | AD8: =IF(ISNUMBER(SEARCH("; genre/writing expertise; ","; "&H8&"; ")),1,0) -> 0 | AE8: =IF(ISNUMBER(SEARCH("; none; ","; "&H8&"; ")),1,0) -> 1
A9: P7-W1-008 | B9: 8 | C9: Writing log 1 | D9: I like this: ISTQB Under the Lens: A Synthesis of Practitioner Opinions on Certification Value, Use, and Critique | E9: Selection/Rejection | G9: Directive | H9: none | I9: Chooses a title without an explicit rationale. | J9: AI acknowledges the selected title. | K9: W1 p11 L4-p11 L4 | L9: W1 p11 L6-p11 L6 | N9: Visible next AI response | P9: =IF(OR(E9="Delegation",ISNUMBER(SEARCH("; Delegation; ","; "&F9&"; "))),1,0) -> 0 | Q9: =IF(OR(E9="Directed delegation",ISNUMBER(SEARCH("; Directed delegation; ","; "&F9&"; "))),1,0) -> 0 | R9: =IF(OR(E9="Evaluation",ISNUMBER(SEARCH("; Evaluation; ","; "&F9&"; "))),1,0) -> 0 | S9: =IF(OR(E9="Correction/Challenge",ISNUMBER(SEARCH("; Correction/Challenge; ","; "&F9&"; "))),1,0) -> 0 | T9: =IF(OR(E9="Redirection",ISNUMBER(SEARCH("; Redirection; ","; "&F9&"; "))),1,0) -> 0 | U9: =IF(OR(E9="Knowledge injection",ISNUMBER(SEARCH("; Knowledge injection; ","; "&F9&"; "))),1,0) -> 0 | V9: =IF(OR(E9="Selection/Rejection",ISNUMBER(SEARCH("; Selection/Rejection; ","; "&F9&"; "))),1,0) -> 1 | W9: =IF(OR(E9="Deliberation",ISNUMBER(SEARCH("; Deliberation; ","; "&F9&"; "))),1,0) -> 0 | X9: =SUM(Paper7Coding[[#This Row],[Subject-matter correction]:[Genre/ writing expertise]]) -> 0 | Y9: =IF(ISNUMBER(SEARCH("; domain correction; ","; "&H9&"; ")),1,0) -> 0 | Z9: =IF(ISNUMBER(SEARCH("; conceptual discrimination; ","; "&H9&"; ")),1,0) -> 0 | AA9: =IF(ISNUMBER(SEARCH("; evidence judgment; ","; "&H9&"; ")),1,0) -> 0 | AB9: =IF(ISNUMBER(SEARCH("; methodological judgment; ","; "&H9&"; ")),1,0) -> 0 | AC9: =IF(ISNUMBER(SEARCH("; argumentative judgment; ","; "&H9&"; ")),1,0) -> 0 | AD9: =IF(ISNUMBER(SEARCH("; genre/writing expertise; ","; "&H9&"; ")),1,0) -> 0 | AE9: =IF(ISNUMBER(SEARCH("; none; ","; "&H9&"; ")),1,0) -> 1
A10: P7-W1-009 | B10: 9 | C10: Writing log 1 | D10: give the paper structure | E10: Delegation | G10: Delegative | H10: none | I10: Requests a paper structure with no new detailed constraints. | J10: AI proposes a paper outline. | K10: W1 p11 L8-p11 L8 | L10: W1 p11 L10-p11 L27 | N10: Visible next AI response | P10: =IF(OR(E10="Delegation",ISNUMBER(SEARCH("; Delegation; ","; "&F10&"; "))),1,0) -> 1 | Q10: =IF(OR(E10="Directed delegation",ISNUMBER(SEARCH("; Directed delegation; ","; "&F10&"; "))),1,0) -> 0 | R10: =IF(OR(E10="Evaluation",ISNUMBER(SEARCH("; Evaluation; ","; "&F10&"; "))),1,0) -> 0 | S10: =IF(OR(E10="Correction/Challenge",ISNUMBER(SEARCH("; Correction/Challenge; ","; "&F10&"; "))),1,0) -> 0 | T10: =IF(OR(E10="Redirection",ISNUMBER(SEARCH("; Redirection; ","; "&F10&"; "))),1,0) -> 0 | U10: =IF(OR(E10="Knowledge injection",ISNUMBER(SEARCH("; Knowledge injection; ","; "&F10&"; "))),1,0) -> 0 | V10: =IF(OR(E10="Selection/Rejection",ISNUMBER(SEARCH("; Selection/Rejection; ","; "&F10&"; "))),1,0) -> 0 | W10: =IF(OR(E10="Deliberation",ISNUMBER(SEARCH("; Deliberation; ","; "&F10&"; "))),1,0) -> 0 | X10: =SUM(Paper7Coding[[#This Row],[Subject-matter correction]:[Genre/ writing expertise]]) -> 0 | Y10: =IF(ISNUMBER(SEARCH("; domain correction; ","; "&H10&"; ")),1,0) -> 0 | Z10: =IF(ISNUMBER(SEARCH("; conceptual discrimination; ","; "&H10&"; ")),1,0) -> 0 | AA10: =IF(ISNUMBER(SEARCH("; evidence judgment; ","; "&H10&"; ")),1,0) -> 0 | AB10: =IF(ISNUMBER(SEARCH("; methodological judgment; ","; "&H10&"; ")),1,0) -> 0 | AC10: =IF(ISNUMBER(SEARCH("; argumentative judgment; ","; "&H10&"; ")),1,0) -> 0 | AD10: =IF(ISNUMBER(SEARCH("; genre/writing expertise; ","; "&H10&"; ")),1,0) -> 0 | AE10: =IF(ISNUMBER(SEARCH("; none; ","; "&H10&"; ")),1,0) -> 1
A11: P7-W1-010 | B11: 10 | C11: Writing log 1 | D11: Findings section shall include: Certification Value, Use, and Critique | E11: Directed delegation | G11: Directive | H11: conceptual discrimination; genre/writing expertise | I11: Specifies a three-part findings structure distinguishing value, use and critique. | J11: AI adopts the three findings categories. | K11: W1 p11 L29-p11 L29 | L11: W1 p11 L31-p11 L33 | N11: Visible next AI response | P11: =IF(OR(E11="Delegation",ISNUMBER(SEARCH("; Delegation; ","; "&F11&"; "))),1,0) -> 0 | Q11: =IF(OR(E11="Directed delegation",ISNUMBER(SEARCH("; Directed delegation; ","; "&F11&"; "))),1,0) -> 1 | R11: =IF(OR(E11="Evaluation",ISNUMBER(SEARCH("; Evaluation; ","; "&F11&"; "))),1,0) -> 0 | S11: =IF(OR(E11="Correction/Challenge",ISNUMBER(SEARCH("; Correction/Challenge; ","; "&F11&"; "))),1,0) -> 0 | T11: =IF(OR(E11="Redirection",ISNUMBER(SEARCH("; Redirection; ","; "&F11&"; "))),1,0) -> 0 | U11: =IF(OR(E11="Knowledge injection",ISNUMBER(SEARCH("; Knowledge injection; ","; "&F11&"; "))),1,0) -> 0 | V11: =IF(OR(E11="Selection/Rejection",ISNUMBER(SEARCH("; Selection/Rejection; ","; "&F11&"; "))),1,0) -> 0 | W11: =IF(OR(E11="Deliberation",ISNUMBER(SEARCH("; Deliberation; ","; "&F11&"; "))),1,0) -> 0 | X11: =SUM(Paper7Coding[[#This Row],[Subject-matter correction]:[Genre/ writing expertise]]) -> 2 | Y11: =IF(ISNUMBER(SEARCH("; domain correction; ","; "&H11&"; ")),1,0) -> 0 | Z11: =IF(ISNUMBER(SEARCH("; conceptual discrimination; ","; "&H11&"; ")),1,0) -> 1 | AA11: =IF(ISNUMBER(SEARCH("; evidence judgment; ","; "&H11&"; ")),1,0) -> 0 | AB11: =IF(ISNUMBER(SEARCH("; methodological judgment; ","; "&H11&"; ")),1,0) -> 0 | AC11: =IF(ISNUMBER(SEARCH("; argumentative judgment; ","; "&H11&"; ")),1,0) -> 0 | AD11: =IF(ISNUMBER(SEARCH("; genre/writing expertise; ","; "&H11&"; ")),1,0) -> 1 | AE11: =IF(ISNUMBER(SEARCH("; none; ","; "&H11&"; ")),1,0) -> 0
A12: P7-W1-011 | B12: 11 | C12: Writing log 1 | D12: these should also be broken down by certification level, and stakeholder role. -- remove classification by region, from all parts | E12: Redirection | F12: Directed delegation; Selection/Rejection | G12: Directive | H12: methodological judgment; genre/writing expertise | I12: Removes regional classification while retaining level and role breakdowns. | J12: AI confirms the revised classification dimensions. | K12: W1 p11 L35-p11 L36 | L12: W1 p12 L2-p12 L4 | N12: Visible next AI response | P12: =IF(OR(E12="Delegation",ISNUMBER(SEARCH("; Delegation; ","; "&F12&"; "))),1,0) -> 0 | Q12: =IF(OR(E12="Directed delegation",ISNUMBER(SEARCH("; Directed delegation; ","; "&F12&"; "))),1,0) -> 1 | R12: =IF(OR(E12="Evaluation",ISNUMBER(SEARCH("; Evaluation; ","; "&F12&"; "))),1,0) -> 0 | S12: =IF(OR(E12="Correction/Challenge",ISNUMBER(SEARCH("; Correction/Challenge; ","; "&F12&"; "))),1,0) -> 0 | T12: =IF(OR(E12="Redirection",ISNUMBER(SEARCH("; Redirection; ","; "&F12&"; "))),1,0) -> 1 | U12: =IF(OR(E12="Knowledge injection",ISNUMBER(SEARCH("; Knowledge injection; ","; "&F12&"; "))),1,0) -> 0 | V12: =IF(OR(E12="Selection/Rejection",ISNUMBER(SEARCH("; Selection/Rejection; ","; "&F12&"; "))),1,0) -> 1 | W12: =IF(OR(E12="Deliberation",ISNUMBER(SEARCH("; Deliberation; ","; "&F12&"; "))),1,0) -> 0 | X12: =SUM(Paper7Coding[[#This Row],[Subject-matter correction]:[Genre/ writing expertise]]) -> 2 | Y12: =IF(ISNUMBER(SEARCH("; domain correction; ","; "&H12&"; ")),1,0) -> 0 | Z12: =IF(ISNUMBER(SEARCH("; conceptual discrimination; ","; "&H12&"; ")),1,0) -> 0 | AA12: =IF(ISNUMBER(SEARCH("; evidence judgment; ","; "&H12&"; ")),1,0) -> 0 | AB12: =IF(ISNUMBER(SEARCH("; methodological judgment; ","; "&H12&"; ")),1,0) -> 1 | AC12: =IF(ISNUMBER(SEARCH("; argumentative judgment; ","; "&H12&"; ")),1,0) -> 0 | AD12: =IF(ISNUMBER(SEARCH("; genre/writing expertise; ","; "&H12&"; ")),1,0) -> 1 | AE12: =IF(ISNUMBER(SEARCH("; none; ","; "&H12&"; ")),1,0) -> 0
A13: P7-W1-012 | B13: 12 | C13: Writing log 1 | D13: how would you differentiate Certification Value from Use? | E13: Deliberation | F13: Evaluation | G13: Deliberative | H13: conceptual discrimination | I13: Asks how two proposed analytical categories differ; initiates conceptual comparison. | J13: AI contrasts perceived value with practical use. | K13: W1 p12 L6-p12 L6 | L13: W1 p12 L8-p12 L17 | N13: Visible next AI response | P13: =IF(OR(E13="Delegation",ISNUMBER(SEARCH("; Delegation; ","; "&F13&"; "))),1,0) -> 0 | Q13: =IF(OR(E13="Directed delegation",ISNUMBER(SEARCH("; Directed delegation; ","; "&F13&"; "))),1,0) -> 0 | R13: =IF(OR(E13="Evaluation",ISNUMBER(SEARCH("; Evaluation; ","; "&F13&"; "))),1,0) -> 1 | S13: =IF(OR(E13="Correction/Challenge",ISNUMBER(SEARCH("; Correction/Challenge; ","; "&F13&"; "))),1,0) -> 0 | T13: =IF(OR(E13="Redirection",ISNUMBER(SEARCH("; Redirection; ","; "&F13&"; "))),1,0) -> 0 | U13: =IF(OR(E13="Knowledge injection",ISNUMBER(SEARCH("; Knowledge injection; ","; "&F13&"; "))),1,0) -> 0 | V13: =IF(OR(E13="Selection/Rejection",ISNUMBER(SEARCH("; Selection/Rejection; ","; "&F13&"; "))),1,0) -> 0 | W13: =IF(OR(E13="Deliberation",ISNUMBER(SEARCH("; Deliberation; ","; "&F13&"; "))),1,0) -> 1 | X13: =SUM(Paper7Coding[[#This Row],[Subject-matter correction]:[Genre/ writing expertise]]) -> 1 | Y13: =IF(ISNUMBER(SEARCH("; domain correction; ","; "&H13&"; ")),1,0) -> 0 | Z13: =IF(ISNUMBER(SEARCH("; conceptual discrimination; ","; "&H13&"; ")),1,0) -> 1 | AA13: =IF(ISNUMBER(SEARCH("; evidence judgment; ","; "&H13&"; ")),1,0) -> 0 | AB13: =IF(ISNUMBER(SEARCH("; methodological judgment; ","; "&H13&"; ")),1,0) -> 0 | AC13: =IF(ISNUMBER(SEARCH("; argumentative judgment; ","; "&H13&"; ")),1,0) -> 0 | AD13: =IF(ISNUMBER(SEARCH("; genre/writing expertise; ","; "&H13&"; ")),1,0) -> 0 | AE13: =IF(ISNUMBER(SEARCH("; none; ","; "&H13&"; ")),1,0) -> 0
A14: P7-W1-013 | B14: 13 | C14: Writing log 1 | D14: like the deep research that you did for Critique part, I will later ask you to do similar deep research and synthesiding of literature for "Value" and "Use" | E14: Directed delegation | G14: Directive | H14: methodological judgment | I14: Plans parallel research and synthesis for Value and Use using the previous Critique approach. | J14: AI acknowledges a future research request. | K14: W1 p12 L19-p12 L20 | L14: W1 p12 L22-p12 L23 | N14: Visible next AI response | P14: =IF(OR(E14="Delegation",ISNUMBER(SEARCH("; Delegation; ","; "&F14&"; "))),1,0) -> 0 | Q14: =IF(OR(E14="Directed delegation",ISNUMBER(SEARCH("; Directed delegation; ","; "&F14&"; "))),1,0) -> 1 | R14: =IF(OR(E14="Evaluation",ISNUMBER(SEARCH("; Evaluation; ","; "&F14&"; "))),1,0) -> 0 | S14: =IF(OR(E14="Correction/Challenge",ISNUMBER(SEARCH("; Correction/Challenge; ","; "&F14&"; "))),1,0) -> 0 | T14: =IF(OR(E14="Redirection",ISNUMBER(SEARCH("; Redirection; ","; "&F14&"; "))),1,0) -> 0 | U14: =IF(OR(E14="Knowledge injection",ISNUMBER(SEARCH("; Knowledge injection; ","; "&F14&"; "))),1,0) -> 0 | V14: =IF(OR(E14="Selection/Rejection",ISNUMBER(SEARCH("; Selection/Rejection; ","; "&F14&"; "))),1,0) -> 0 | W14: =IF(OR(E14="Deliberation",ISNUMBER(SEARCH("; Deliberation; ","; "&F14&"; "))),1,0) -> 0 | X14: =SUM(Paper7Coding[[#This Row],[Subject-matter correction]:[Genre/ writing expertise]]) -> 1 | Y14: =IF(ISNUMBER(SEARCH("; domain correction; ","; "&H14&"; ")),1,0) -> 0 | Z14: =IF(ISNUMBER(SEARCH("; conceptual discrimination; ","; "&H14&"; ")),1,0) -> 0 | AA14: =IF(ISNUMBER(SEARCH("; evidence judgment; ","; "&H14&"; ")),1,0) -> 0 | AB14: =IF(ISNUMBER(SEARCH("; methodological judgment; ","; "&H14&"; ")),1,0) -> 1 | AC14: =IF(ISNUMBER(SEARCH("; argumentative judgment; ","; "&H14&"; ")),1,0) -> 0 | AD14: =IF(ISNUMBER(SEARCH("; genre/writing expertise; ","; "&H14&"; ")),1,0) -> 0 | AE14: =IF(ISNUMBER(SEARCH("; none; ","; "&H14&"; ")),1,0) -> 0
A15: P7-W1-014 | B15: 14 | C15: Writing log 1 | D15: how is this title? ISTQB Under the Lens: A Synthesis of Global Voices on Certification Value, Use, and Critique | E15: Evaluation | F15: Knowledge injection | G15: Evaluative | H15: genre/writing expertise | I15: Offers a revised title and requests evaluation of its broader voice framing. | J15: AI compares the old and new titles and suggests wording. | K15: W1 p12 L25-p12 L25 | L15: W1 p12 L27-p12 L32 | N15: Visible next AI response | P15: =IF(OR(E15="Delegation",ISNUMBER(SEARCH("; Delegation; ","; "&F15&"; "))),1,0) -> 0 | Q15: =IF(OR(E15="Directed delegation",ISNUMBER(SEARCH("; Directed delegation; ","; "&F15&"; "))),1,0) -> 0 | R15: =IF(OR(E15="Evaluation",ISNUMBER(SEARCH("; Evaluation; ","; "&F15&"; "))),1,0) -> 1 | S15: =IF(OR(E15="Correction/Challenge",ISNUMBER(SEARCH("; Correction/Challenge; ","; "&F15&"; "))),1,0) -> 0 | T15: =IF(OR(E15="Redirection",ISNUMBER(SEARCH("; Redirection; ","; "&F15&"; "))),1,0) -> 0 | U15: =IF(OR(E15="Knowledge injection",ISNUMBER(SEARCH("; Knowledge injection; ","; "&F15&"; "))),1,0) -> 1 | V15: =IF(OR(E15="Selection/Rejection",ISNUMBER(SEARCH("; Selection/Rejection; ","; "&F15&"; "))),1,0) -> 0 | W15: =IF(OR(E15="Deliberation",ISNUMBER(SEARCH("; Deliberation; ","; "&F15&"; "))),1,0) -> 0 | X15: =SUM(Paper7Coding[[#This Row],[Subject-matter correction]:[Genre/ writing expertise]]) -> 1 | Y15: =IF(ISNUMBER(SEARCH("; domain correction; ","; "&H15&"; ")),1,0) -> 0 | Z15: =IF(ISNUMBER(SEARCH("; conceptual discrimination; ","; "&H15&"; ")),1,0) -> 0 | AA15: =IF(ISNUMBER(SEARCH("; evidence judgment; ","; "&H15&"; ")),1,0) -> 0 | AB15: =IF(ISNUMBER(SEARCH("; methodological judgment; ","; "&H15&"; ")),1,0) -> 0 | AC15: =IF(ISNUMBER(SEARCH("; argumentative judgment; ","; "&H15&"; ")),1,0) -> 0 | AD15: =IF(ISNUMBER(SEARCH("; genre/writing expertise; ","; "&H15&"; ")),1,0) -> 1 | AE15: =IF(ISNUMBER(SEARCH("; none; ","; "&H15&"; ")),1,0) -> 0
A16: P7-W1-015 | B16: 15 | C16: Writing log 1 | D16: how is this? ISTQB Certifications Under the Lens: Synthesizing Global Perspectives on Value, Use, and Critique | E16: Evaluation | F16: Knowledge injection | G16: Evaluative | H16: genre/writing expertise | I16: Offers a more precise revised title and asks for assessment. | J16: AI endorses the revised title. | K16: W1 p12 L34-p12 L35 | L16: W1 p13 L2-p13 L5 | N16: Visible next AI response | P16: =IF(OR(E16="Delegation",ISNUMBER(SEARCH("; Delegation; ","; "&F16&"; "))),1,0) -> 0 | Q16: =IF(OR(E16="Directed delegation",ISNUMBER(SEARCH("; Directed delegation; ","; "&F16&"; "))),1,0) -> 0 | R16: =IF(OR(E16="Evaluation",ISNUMBER(SEARCH("; Evaluation; ","; "&F16&"; "))),1,0) -> 1 | S16: =IF(OR(E16="Correction/Challenge",ISNUMBER(SEARCH("; Correction/Challenge; ","; "&F16&"; "))),1,0) -> 0 | T16: =IF(OR(E16="Redirection",ISNUMBER(SEARCH("; Redirection; ","; "&F16&"; "))),1,0) -> 0 | U16: =IF(OR(E16="Knowledge injection",ISNUMBER(SEARCH("; Knowledge injection; ","; "&F16&"; "))),1,0) -> 1 | V16: =IF(OR(E16="Selection/Rejection",ISNUMBER(SEARCH("; Selection/Rejection; ","; "&F16&"; "))),1,0) -> 0 | W16: =IF(OR(E16="Deliberation",ISNUMBER(SEARCH("; Deliberation; ","; "&F16&"; "))),1,0) -> 0 | X16: =SUM(Paper7Coding[[#This Row],[Subject-matter correction]:[Genre/ writing expertise]]) -> 1 | Y16: =IF(ISNUMBER(SEARCH("; domain correction; ","; "&H16&"; ")),1,0) -> 0 | Z16: =IF(ISNUMBER(SEARCH("; conceptual discrimination; ","; "&H16&"; ")),1,0) -> 0 | AA16: =IF(ISNUMBER(SEARCH("; evidence judgment; ","; "&H16&"; ")),1,0) -> 0 | AB16: =IF(ISNUMBER(SEARCH("; methodological judgment; ","; "&H16&"; ")),1,0) -> 0 | AC16: =IF(ISNUMBER(SEARCH("; argumentative judgment; ","; "&H16&"; ")),1,0) -> 0 | AD16: =IF(ISNUMBER(SEARCH("; genre/writing expertise; ","; "&H16&"; ")),1,0) -> 1 | AE16: =IF(ISNUMBER(SEARCH("; none; ","; "&H16&"; ")),1,0) -> 0
A17: P7-W1-016 | B17: 16 | C17: Writing log 1 | D17: how is this? ISTQB Certifications Under the Lens: Synthesizing Global Perspectives on their Value, Use, and Critique --- btw, shall I add any other compoent in addition to these three: Value, Use, and Critique ? | E17: Deliberation | F17: Evaluation; Knowledge injection | G17: Deliberative | H17: conceptual discrimination; argumentative judgment; genre/writing expertise | I17: Asks whether the three-part framing needs another component while assessing a title. | J17: AI discusses optional dimensions and recommends keeping three. | K17: W1 p13 L7-p13 L8 | L17: W1 p13 L10-p13 L20 | N17: Visible next AI response | P17: =IF(OR(E17="Delegation",ISNUMBER(SEARCH("; Delegation; ","; "&F17&"; "))),1,0) -> 0 | Q17: =IF(OR(E17="Directed delegation",ISNUMBER(SEARCH("; Directed delegation; ","; "&F17&"; "))),1,0) -> 0 | R17: =IF(OR(E17="Evaluation",ISNUMBER(SEARCH("; Evaluation; ","; "&F17&"; "))),1,0) -> 1 | S17: =IF(OR(E17="Correction/Challenge",ISNUMBER(SEARCH("; Correction/Challenge; ","; "&F17&"; "))),1,0) -> 0 | T17: =IF(OR(E17="Redirection",ISNUMBER(SEARCH("; Redirection; ","; "&F17&"; "))),1,0) -> 0 | U17: =IF(OR(E17="Knowledge injection",ISNUMBER(SEARCH("; Knowledge injection; ","; "&F17&"; "))),1,0) -> 1 | V17: =IF(OR(E17="Selection/Rejection",ISNUMBER(SEARCH("; Selection/Rejection; ","; "&F17&"; "))),1,0) -> 0 | W17: =IF(OR(E17="Deliberation",ISNUMBER(SEARCH("; Deliberation; ","; "&F17&"; "))),1,0) -> 1 | X17: =SUM(Paper7Coding[[#This Row],[Subject-matter correction]:[Genre/ writing expertise]]) -> 3 | Y17: =IF(ISNUMBER(SEARCH("; domain correction; ","; "&H17&"; ")),1,0) -> 0 | Z17: =IF(ISNUMBER(SEARCH("; conceptual discrimination; ","; "&H17&"; ")),1,0) -> 1 | AA17: =IF(ISNUMBER(SEARCH("; evidence judgment; ","; "&H17&"; ")),1,0) -> 0 | AB17: =IF(ISNUMBER(SEARCH("; methodological judgment; ","; "&H17&"; ")),1,0) -> 0 | AC17: =IF(ISNUMBER(SEARCH("; argumentative judgment; ","; "&H17&"; ")),1,0) -> 1 | AD17: =IF(ISNUMBER(SEARCH("; genre/writing expertise; ","; "&H17&"; ")),1,0) -> 1 | AE17: =IF(ISNUMBER(SEARCH("; none; ","; "&H17&"; ")),1,0) -> 0
A18: P7-W1-017 | B18: 17 | C18: Writing log 1 | D18: yep | E18: Selection/Rejection | G18: Directive | H18: none | I18: Accepts the preceding offer to finalize the title; no new expertise evidence. | J18: AI acknowledges title selection. | K18: W1 p13 L22-p13 L22 | L18: W1 p13 L24-p13 L25 | N18: Visible next AI response | P18: =IF(OR(E18="Delegation",ISNUMBER(SEARCH("; Delegation; ","; "&F18&"; "))),1,0) -> 0 | Q18: =IF(OR(E18="Directed delegation",ISNUMBER(SEARCH("; Directed delegation; ","; "&F18&"; "))),1,0) -> 0 | R18: =IF(OR(E18="Evaluation",ISNUMBER(SEARCH("; Evaluation; ","; "&F18&"; "))),1,0) -> 0 | S18: =IF(OR(E18="Correction/Challenge",ISNUMBER(SEARCH("; Correction/Challenge; ","; "&F18&"; "))),1,0) -> 0 | T18: =IF(OR(E18="Redirection",ISNUMBER(SEARCH("; Redirection; ","; "&F18&"; "))),1,0) -> 0 | U18: =IF(OR(E18="Knowledge injection",ISNUMBER(SEARCH("; Knowledge injection; ","; "&F18&"; "))),1,0) -> 0 | V18: =IF(OR(E18="Selection/Rejection",ISNUMBER(SEARCH("; Selection/Rejection; ","; "&F18&"; "))),1,0) -> 1 | W18: =IF(OR(E18="Deliberation",ISNUMBER(SEARCH("; Deliberation; ","; "&F18&"; "))),1,0) -> 0 | X18: =SUM(Paper7Coding[[#This Row],[Subject-matter correction]:[Genre/ writing expertise]]) -> 0 | Y18: =IF(ISNUMBER(SEARCH("; domain correction; ","; "&H18&"; ")),1,0) -> 0 | Z18: =IF(ISNUMBER(SEARCH("; conceptual discrimination; ","; "&H18&"; ")),1,0) -> 0 | AA18: =IF(ISNUMBER(SEARCH("; evidence judgment; ","; "&H18&"; ")),1,0) -> 0 | AB18: =IF(ISNUMBER(SEARCH("; methodological judgment; ","; "&H18&"; ")),1,0) -> 0 | AC18: =IF(ISNUMBER(SEARCH("; argumentative judgment; ","; "&H18&"; ")),1,0) -> 0 | AD18: =IF(ISNUMBER(SEARCH("; genre/writing expertise; ","; "&H18&"; ")),1,0) -> 0 | AE18: =IF(ISNUMBER(SEARCH("; none; ","; "&H18&"; ")),1,0) -> 1
A19: P7-W1-018 | B19: 18 | C19: Writing log 1 | D19: explani these aspects again: Value, Use, Critique. I am not sure if "use" is necessary | E19: Deliberation | F19: Evaluation | G19: Deliberative | H19: conceptual discrimination; argumentative judgment | I19: Questions whether Use adds a distinct dimension and requests an explanation. | J19: AI explains category distinctions and presents options for keeping or merging Use. | K19: W1 p13 L27-p13 L27 | L19: W1 p13 L29-p14 L8 | N19: Visible next AI response | P19: =IF(OR(E19="Delegation",ISNUMBER(SEARCH("; Delegation; ","; "&F19&"; "))),1,0) -> 0 | Q19: =IF(OR(E19="Directed delegation",ISNUMBER(SEARCH("; Directed delegation; ","; "&F19&"; "))),1,0) -> 0 | R19: =IF(OR(E19="Evaluation",ISNUMBER(SEARCH("; Evaluation; ","; "&F19&"; "))),1,0) -> 1 | S19: =IF(OR(E19="Correction/Challenge",ISNUMBER(SEARCH("; Correction/Challenge; ","; "&F19&"; "))),1,0) -> 0 | T19: =IF(OR(E19="Redirection",ISNUMBER(SEARCH("; Redirection; ","; "&F19&"; "))),1,0) -> 0 | U19: =IF(OR(E19="Knowledge injection",ISNUMBER(SEARCH("; Knowledge injection; ","; "&F19&"; "))),1,0) -> 0 | V19: =IF(OR(E19="Selection/Rejection",ISNUMBER(SEARCH("; Selection/Rejection; ","; "&F19&"; "))),1,0) -> 0 | W19: =IF(OR(E19="Deliberation",ISNUMBER(SEARCH("; Deliberation; ","; "&F19&"; "))),1,0) -> 1 | X19: =SUM(Paper7Coding[[#This Row],[Subject-matter correction]:[Genre/ writing expertise]]) -> 2 | Y19: =IF(ISNUMBER(SEARCH("; domain correction; ","; "&H19&"; ")),1,0) -> 0 | Z19: =IF(ISNUMBER(SEARCH("; conceptual discrimination; ","; "&H19&"; ")),1,0) -> 1 | AA19: =IF(ISNUMBER(SEARCH("; evidence judgment; ","; "&H19&"; ")),1,0) -> 0 | AB19: =IF(ISNUMBER(SEARCH("; methodological judgment; ","; "&H19&"; ")),1,0) -> 0 | AC19: =IF(ISNUMBER(SEARCH("; argumentative judgment; ","; "&H19&"; ")),1,0) -> 1 | AD19: =IF(ISNUMBER(SEARCH("; genre/writing expertise; ","; "&H19&"; ")),1,0) -> 0 | AE19: =IF(ISNUMBER(SEARCH("; none; ","; "&H19&"; ")),1,0) -> 0
A20: P7-W1-019 | B20: 19 | C20: Writing log 1 | D20: reduce to two dimensions: Value and Critique | E20: Selection/Rejection | F20: Redirection | G20: Directive | H20: conceptual discrimination; methodological judgment | I20: Chooses to reduce the analytical framework to Value and Critique after comparison. | J20: AI confirms the two-dimension framework. | K20: W1 p14 L10-p14 L10 | L20: W1 p14 L12-p14 L13 | N20: Visible next AI response | P20: =IF(OR(E20="Delegation",ISNUMBER(SEARCH("; Delegation; ","; "&F20&"; "))),1,0) -> 0 | Q20: =IF(OR(E20="Directed delegation",ISNUMBER(SEARCH("; Directed delegation; ","; "&F20&"; "))),1,0) -> 0 | R20: =IF(OR(E20="Evaluation",ISNUMBER(SEARCH("; Evaluation; ","; "&F20&"; "))),1,0) -> 0 | S20: =IF(OR(E20="Correction/Challenge",ISNUMBER(SEARCH("; Correction/Challenge; ","; "&F20&"; "))),1,0) -> 0 | T20: =IF(OR(E20="Redirection",ISNUMBER(SEARCH("; Redirection; ","; "&F20&"; "))),1,0) -> 1 | U20: =IF(OR(E20="Knowledge injection",ISNUMBER(SEARCH("; Knowledge injection; ","; "&F20&"; "))),1,0) -> 0 | V20: =IF(OR(E20="Selection/Rejection",ISNUMBER(SEARCH("; Selection/Rejection; ","; "&F20&"; "))),1,0) -> 1 | W20: =IF(OR(E20="Deliberation",ISNUMBER(SEARCH("; Deliberation; ","; "&F20&"; "))),1,0) -> 0 | X20: =SUM(Paper7Coding[[#This Row],[Subject-matter correction]:[Genre/ writing expertise]]) -> 2 | Y20: =IF(ISNUMBER(SEARCH("; domain correction; ","; "&H20&"; ")),1,0) -> 0 | Z20: =IF(ISNUMBER(SEARCH("; conceptual discrimination; ","; "&H20&"; ")),1,0) -> 1 | AA20: =IF(ISNUMBER(SEARCH("; evidence judgment; ","; "&H20&"; ")),1,0) -> 0 | AB20: =IF(ISNUMBER(SEARCH("; methodological judgment; ","; "&H20&"; ")),1,0) -> 1 | AC20: =IF(ISNUMBER(SEARCH("; argumentative judgment; ","; "&H20&"; ")),1,0) -> 0 | AD20: =IF(ISNUMBER(SEARCH("; genre/writing expertise; ","; "&H20&"; ")),1,0) -> 0 | AE20: =IF(ISNUMBER(SEARCH("; none; ","; "&H20&"; ")),1,0) -> 0
A21: P7-W1-020 | B21: 20 | C21: Writing log 1 | D21: recall to include in the paper a section on: Why were ISTQB Certifications developed in the first place | E21: Directed delegation | G21: Directive | H21: argumentative judgment; genre/writing expertise | I21: Requires background explaining why certifications were originally developed. | J21: AI acknowledges the planned section. | K21: W1 p14 L15-p14 L15 | L21: W1 p14 L17-p14 L18 | N21: Visible next AI response | P21: =IF(OR(E21="Delegation",ISNUMBER(SEARCH("; Delegation; ","; "&F21&"; "))),1,0) -> 0 | Q21: =IF(OR(E21="Directed delegation",ISNUMBER(SEARCH("; Directed delegation; ","; "&F21&"; "))),1,0) -> 1 | R21: =IF(OR(E21="Evaluation",ISNUMBER(SEARCH("; Evaluation; ","; "&F21&"; "))),1,0) -> 0 | S21: =IF(OR(E21="Correction/Challenge",ISNUMBER(SEARCH("; Correction/Challenge; ","; "&F21&"; "))),1,0) -> 0 | T21: =IF(OR(E21="Redirection",ISNUMBER(SEARCH("; Redirection; ","; "&F21&"; "))),1,0) -> 0 | U21: =IF(OR(E21="Knowledge injection",ISNUMBER(SEARCH("; Knowledge injection; ","; "&F21&"; "))),1,0) -> 0 | V21: =IF(OR(E21="Selection/Rejection",ISNUMBER(SEARCH("; Selection/Rejection; ","; "&F21&"; "))),1,0) -> 0 | W21: =IF(OR(E21="Deliberation",ISNUMBER(SEARCH("; Deliberation; ","; "&F21&"; "))),1,0) -> 0 | X21: =SUM(Paper7Coding[[#This Row],[Subject-matter correction]:[Genre/ writing expertise]]) -> 2 | Y21: =IF(ISNUMBER(SEARCH("; domain correction; ","; "&H21&"; ")),1,0) -> 0 | Z21: =IF(ISNUMBER(SEARCH("; conceptual discrimination; ","; "&H21&"; ")),1,0) -> 0 | AA21: =IF(ISNUMBER(SEARCH("; evidence judgment; ","; "&H21&"; ")),1,0) -> 0 | AB21: =IF(ISNUMBER(SEARCH("; methodological judgment; ","; "&H21&"; ")),1,0) -> 0 | AC21: =IF(ISNUMBER(SEARCH("; argumentative judgment; ","; "&H21&"; ")),1,0) -> 1 | AD21: =IF(ISNUMBER(SEARCH("; genre/writing expertise; ","; "&H21&"; ")),1,0) -> 1 | AE21: =IF(ISNUMBER(SEARCH("; none; ","; "&H21&"; ")),1,0) -> 0
A22: P7-W1-021 | B22: 21 | C22: Writing log 1 | D22: let me tell you about the research approach for this work. it will get data from two sources: 1-Systematic Review of the relevant Academic and Grey Literature 2-Survey questionanare from test engineers and managers working in several Turkish and Azerbaijani companies about the Value and Critique … | E22: Knowledge injection | F22: Directed delegation | G22: Directive | H22: methodological judgment | I22: Supplies a two-source research design combining literature review and a practitioner survey. | J22: AI acknowledges the two research components. | K22: W1 p14 L20-p14 L22 | L22: W1 p14 L24-p14 L25 | N22: Visible next AI response | P22: =IF(OR(E22="Delegation",ISNUMBER(SEARCH("; Delegation; ","; "&F22&"; "))),1,0) -> 0 | Q22: =IF(OR(E22="Directed delegation",ISNUMBER(SEARCH("; Directed delegation; ","; "&F22&"; "))),1,0) -> 1 | R22: =IF(OR(E22="Evaluation",ISNUMBER(SEARCH("; Evaluation; ","; "&F22&"; "))),1,0) -> 0 | S22: =IF(OR(E22="Correction/Challenge",ISNUMBER(SEARCH("; Correction/Challenge; ","; "&F22&"; "))),1,0) -> 0 | T22: =IF(OR(E22="Redirection",ISNUMBER(SEARCH("; Redirection; ","; "&F22&"; "))),1,0) -> 0 | U22: =IF(OR(E22="Knowledge injection",ISNUMBER(SEARCH("; Knowledge injection; ","; "&F22&"; "))),1,0) -> 1 | V22: =IF(OR(E22="Selection/Rejection",ISNUMBER(SEARCH("; Selection/Rejection; ","; "&F22&"; "))),1,0) -> 0 | W22: =IF(OR(E22="Deliberation",ISNUMBER(SEARCH("; Deliberation; ","; "&F22&"; "))),1,0) -> 0 | X22: =SUM(Paper7Coding[[#This Row],[Subject-matter correction]:[Genre/ writing expertise]]) -> 1 | Y22: =IF(ISNUMBER(SEARCH("; domain correction; ","; "&H22&"; ")),1,0) -> 0 | Z22: =IF(ISNUMBER(SEARCH("; conceptual discrimination; ","; "&H22&"; ")),1,0) -> 0 | AA22: =IF(ISNUMBER(SEARCH("; evidence judgment; ","; "&H22&"; ")),1,0) -> 0 | AB22: =IF(ISNUMBER(SEARCH("; methodological judgment; ","; "&H22&"; ")),1,0) -> 1 | AC22: =IF(ISNUMBER(SEARCH("; argumentative judgment; ","; "&H22&"; ")),1,0) -> 0 | AD22: =IF(ISNUMBER(SEARCH("; genre/writing expertise; ","; "&H22&"; ")),1,0) -> 0 | AE22: =IF(ISNUMBER(SEARCH("; none; ","; "&H22&"; ")),1,0) -> 0
A23: P7-W1-022 | B23: 22 | C23: Writing log 1 | D23: give me a rough paper structure. here is a starting structure I have mind: 1 INTRODUCTION 1 2 RELATED WORK 2 3 GOAL AND RESEARCH DESIGN 2 3.1 Research questions 2 3.2 Systematic review of the relevant Academic and Grey Literature 2 3.2.1 Design of the Rapid Review 3 3.2.2 Pool of Online Sources I… | E23: Directed delegation | F23: Knowledge injection | G23: Directive | H23: methodological judgment; genre/writing expertise | I23: Supplies a detailed starting outline and asks AI to refine it. | J23: AI produces a reorganized outline with RQ-linked results. | K23: W1 p14 L27-p14 L33 | L23: W1 p14 L35-p15 L14 | M23: Includes supplied outline, draft or previously generated text. | N23: Visible next AI response | P23: =IF(OR(E23="Delegation",ISNUMBER(SEARCH("; Delegation; ","; "&F23&"; "))),1,0) -> 0 | Q23: =IF(OR(E23="Directed delegation",ISNUMBER(SEARCH("; Directed delegation; ","; "&F23&"; "))),1,0) -> 1 | R23: =IF(OR(E23="Evaluation",ISNUMBER(SEARCH("; Evaluation; ","; "&F23&"; "))),1,0) -> 0 | S23: =IF(OR(E23="Correction/Challenge",ISNUMBER(SEARCH("; Correction/Challenge; ","; "&F23&"; "))),1,0) -> 0 | T23: =IF(OR(E23="Redirection",ISNUMBER(SEARCH("; Redirection; ","; "&F23&"; "))),1,0) -> 0 | U23: =IF(OR(E23="Knowledge injection",ISNUMBER(SEARCH("; Knowledge injection; ","; "&F23&"; "))),1,0) -> 1 | V23: =IF(OR(E23="Selection/Rejection",ISNUMBER(SEARCH("; Selection/Rejection; ","; "&F23&"; "))),1,0) -> 0 | W23: =IF(OR(E23="Deliberation",ISNUMBER(SEARCH("; Deliberation; ","; "&F23&"; "))),1,0) -> 0 | X23: =SUM(Paper7Coding[[#This Row],[Subject-matter correction]:[Genre/ writing expertise]]) -> 2 | Y23: =IF(ISNUMBER(SEARCH("; domain correction; ","; "&H23&"; ")),1,0) -> 0 | Z23: =IF(ISNUMBER(SEARCH("; conceptual discrimination; ","; "&H23&"; ")),1,0) -> 0 | AA23: =IF(ISNUMBER(SEARCH("; evidence judgment; ","; "&H23&"; ")),1,0) -> 0 | AB23: =IF(ISNUMBER(SEARCH("; methodological judgment; ","; "&H23&"; ")),1,0) -> 1 | AC23: =IF(ISNUMBER(SEARCH("; argumentative judgment; ","; "&H23&"; ")),1,0) -> 0 | AD23: =IF(ISNUMBER(SEARCH("; genre/writing expertise; ","; "&H23&"; ")),1,0) -> 1 | AE23: =IF(ISNUMBER(SEARCH("; none; ","; "&H23&"; ")),1,0) -> 0
A24: P7-W1-023 | B24: 23 | C24: Writing log 1 | D24: discuss Motivation for the study, and potential benefits of its results | E24: Directed delegation | G24: Directive | H24: argumentative judgment | I24: Defines the requested content as motivation and benefits of the study. | J24: AI drafts motivation and potential benefits. | K24: W1 p15 L16-p15 L16 | L24: W1 p15 L18-p15 L37 | N24: Visible next AI response | P24: =IF(OR(E24="Delegation",ISNUMBER(SEARCH("; Delegation; ","; "&F24&"; "))),1,0) -> 0 | Q24: =IF(OR(E24="Directed delegation",ISNUMBER(SEARCH("; Directed delegation; ","; "&F24&"; "))),1,0) -> 1 | R24: =IF(OR(E24="Evaluation",ISNUMBER(SEARCH("; Evaluation; ","; "&F24&"; "))),1,0) -> 0 | S24: =IF(OR(E24="Correction/Challenge",ISNUMBER(SEARCH("; Correction/Challenge; ","; "&F24&"; "))),1,0) -> 0 | T24: =IF(OR(E24="Redirection",ISNUMBER(SEARCH("; Redirection; ","; "&F24&"; "))),1,0) -> 0 | U24: =IF(OR(E24="Knowledge injection",ISNUMBER(SEARCH("; Knowledge injection; ","; "&F24&"; "))),1,0) -> 0 | V24: =IF(OR(E24="Selection/Rejection",ISNUMBER(SEARCH("; Selection/Rejection; ","; "&F24&"; "))),1,0) -> 0 | W24: =IF(OR(E24="Deliberation",ISNUMBER(SEARCH("; Deliberation; ","; "&F24&"; "))),1,0) -> 0 | X24: =SUM(Paper7Coding[[#This Row],[Subject-matter correction]:[Genre/ writing expertise]]) -> 1 | Y24: =IF(ISNUMBER(SEARCH("; domain correction; ","; "&H24&"; ")),1,0) -> 0 | Z24: =IF(ISNUMBER(SEARCH("; conceptual discrimination; ","; "&H24&"; ")),1,0) -> 0 | AA24: =IF(ISNUMBER(SEARCH("; evidence judgment; ","; "&H24&"; ")),1,0) -> 0 | AB24: =IF(ISNUMBER(SEARCH("; methodological judgment; ","; "&H24&"; ")),1,0) -> 0 | AC24: =IF(ISNUMBER(SEARCH("; argumentative judgment; ","; "&H24&"; ")),1,0) -> 1 | AD24: =IF(ISNUMBER(SEARCH("; genre/writing expertise; ","; "&H24&"; ")),1,0) -> 0 | AE24: =IF(ISNUMBER(SEARCH("; none; ","; "&H24&"; ")),1,0) -> 0
A25: P7-W1-024 | B25: 24 | C25: Writing log 1 | D25: not now. but remember to include it when I ask to get Sec 1 | E25: Redirection | F25: Directed delegation | G25: Directive | H25: genre/writing expertise | I25: Defers incorporation until drafting Section 1 and specifies where the material belongs. | J25: AI acknowledges the timing and placement instruction. | K25: W1 p15 L39-p15 L39 | L25: W1 p15 L41-p15 L42 | N25: Visible next AI response | P25: =IF(OR(E25="Delegation",ISNUMBER(SEARCH("; Delegation; ","; "&F25&"; "))),1,0) -> 0 | Q25: =IF(OR(E25="Directed delegation",ISNUMBER(SEARCH("; Directed delegation; ","; "&F25&"; "))),1,0) -> 1 | R25: =IF(OR(E25="Evaluation",ISNUMBER(SEARCH("; Evaluation; ","; "&F25&"; "))),1,0) -> 0 | S25: =IF(OR(E25="Correction/Challenge",ISNUMBER(SEARCH("; Correction/Challenge; ","; "&F25&"; "))),1,0) -> 0 | T25: =IF(OR(E25="Redirection",ISNUMBER(SEARCH("; Redirection; ","; "&F25&"; "))),1,0) -> 1 | U25: =IF(OR(E25="Knowledge injection",ISNUMBER(SEARCH("; Knowledge injection; ","; "&F25&"; "))),1,0) -> 0 | V25: =IF(OR(E25="Selection/Rejection",ISNUMBER(SEARCH("; Selection/Rejection; ","; "&F25&"; "))),1,0) -> 0 | W25: =IF(OR(E25="Deliberation",ISNUMBER(SEARCH("; Deliberation; ","; "&F25&"; "))),1,0) -> 0 | X25: =SUM(Paper7Coding[[#This Row],[Subject-matter correction]:[Genre/ writing expertise]]) -> 1 | Y25: =IF(ISNUMBER(SEARCH("; domain correction; ","; "&H25&"; ")),1,0) -> 0 | Z25: =IF(ISNUMBER(SEARCH("; conceptual discrimination; ","; "&H25&"; ")),1,0) -> 0 | AA25: =IF(ISNUMBER(SEARCH("; evidence judgment; ","; "&H25&"; ")),1,0) -> 0 | AB25: =IF(ISNUMBER(SEARCH("; methodological judgment; ","; "&H25&"; ")),1,0) -> 0 | AC25: =IF(ISNUMBER(SEARCH("; argumentative judgment; ","; "&H25&"; ")),1,0) -> 0 | AD25: =IF(ISNUMBER(SEARCH("; genre/writing expertise; ","; "&H25&"; ")),1,0) -> 1 | AE25: =IF(ISNUMBER(SEARCH("; none; ","; "&H25&"; ")),1,0) -> 0
A26: P7-W1-025 | B26: 25 | C26: Writing log 1 | D26: I updated the structure like this: … comment on it. I do not like the Sec 4- Results sturcture. how can we improve it? | E26: Evaluation | F26: Correction/Challenge; Knowledge injection; Directed delegation | G26: Critical | H26: argumentative judgment; genre/writing expertise | I26: Provides an updated outline, diagnoses dissatisfaction with results organization and requests improvement. | J26: AI proposes a less repetitive results structure. | K26: W1 p16 L2-p16 L11 | L26: W1 p16 L13-p16 L25 | M26: Includes supplied outline, draft or previously generated text. | N26: Visible next AI response | P26: =IF(OR(E26="Delegation",ISNUMBER(SEARCH("; Delegation; ","; "&F26&"; "))),1,0) -> 0 | Q26: =IF(OR(E26="Directed delegation",ISNUMBER(SEARCH("; Directed delegation; ","; "&F26&"; "))),1,0) -> 1 | R26: =IF(OR(E26="Evaluation",ISNUMBER(SEARCH("; Evaluation; ","; "&F26&"; "))),1,0) -> 1 | S26: =IF(OR(E26="Correction/Challenge",ISNUMBER(SEARCH("; Correction/Challenge; ","; "&F26&"; "))),1,0) -> 1 | T26: =IF(OR(E26="Redirection",ISNUMBER(SEARCH("; Redirection; ","; "&F26&"; "))),1,0) -> 0 | U26: =IF(OR(E26="Knowledge injection",ISNUMBER(SEARCH("; Knowledge injection; ","; "&F26&"; "))),1,0) -> 1 | V26: =IF(OR(E26="Selection/Rejection",ISNUMBER(SEARCH("; Selection/Rejection; ","; "&F26&"; "))),1,0) -> 0 | W26: =IF(OR(E26="Deliberation",ISNUMBER(SEARCH("; Deliberation; ","; "&F26&"; "))),1,0) -> 0 | X26: =SUM(Paper7Coding[[#This Row],[Subject-matter correction]:[Genre/ writing expertise]]) -> 2 | Y26: =IF(ISNUMBER(SEARCH("; domain correction; ","; "&H26&"; ")),1,0) -> 0 | Z26: =IF(ISNUMBER(SEARCH("; conceptual discrimination; ","; "&H26&"; ")),1,0) -> 0 | AA26: =IF(ISNUMBER(SEARCH("; evidence judgment; ","; "&H26&"; ")),1,0) -> 0 | AB26: =IF(ISNUMBER(SEARCH("; methodological judgment; ","; "&H26&"; ")),1,0) -> 0 | AC26: =IF(ISNUMBER(SEARCH("; argumentative judgment; ","; "&H26&"; ")),1,0) -> 1 | AD26: =IF(ISNUMBER(SEARCH("; genre/writing expertise; ","; "&H26&"; ")),1,0) -> 1 | AE26: =IF(ISNUMBER(SEARCH("; none; ","; "&H26&"; ")),1,0) -> 0
A27: P7-W1-026 | B27: 26 | C27: Writing log 1 | D27: Why I cannot add files here??? | E27: Evaluation | G27: Evaluative | H27: none | I27: Asks about upload failure; operational troubleshooting rather than research expertise. | J27: AI provides upload troubleshooting advice. | K27: W1 p16 L27-p16 L27 | L27: W1 p16 L29-p16 L34 | N27: Visible next AI response | P27: =IF(OR(E27="Delegation",ISNUMBER(SEARCH("; Delegation; ","; "&F27&"; "))),1,0) -> 0 | Q27: =IF(OR(E27="Directed delegation",ISNUMBER(SEARCH("; Directed delegation; ","; "&F27&"; "))),1,0) -> 0 | R27: =IF(OR(E27="Evaluation",ISNUMBER(SEARCH("; Evaluation; ","; "&F27&"; "))),1,0) -> 1 | S27: =IF(OR(E27="Correction/Challenge",ISNUMBER(SEARCH("; Correction/Challenge; ","; "&F27&"; "))),1,0) -> 0 | T27: =IF(OR(E27="Redirection",ISNUMBER(SEARCH("; Redirection; ","; "&F27&"; "))),1,0) -> 0 | U27: =IF(OR(E27="Knowledge injection",ISNUMBER(SEARCH("; Knowledge injection; ","; "&F27&"; "))),1,0) -> 0 | V27: =IF(OR(E27="Selection/Rejection",ISNUMBER(SEARCH("; Selection/Rejection; ","; "&F27&"; "))),1,0) -> 0 | W27: =IF(OR(E27="Deliberation",ISNUMBER(SEARCH("; Deliberation; ","; "&F27&"; "))),1,0) -> 0 | X27: =SUM(Paper7Coding[[#This Row],[Subject-matter correction]:[Genre/ writing expertise]]) -> 0 | Y27: =IF(ISNUMBER(SEARCH("; domain correction; ","; "&H27&"; ")),1,0) -> 0 | Z27: =IF(ISNUMBER(SEARCH("; conceptual discrimination; ","; "&H27&"; ")),1,0) -> 0 | AA27: =IF(ISNUMBER(SEARCH("; evidence judgment; ","; "&H27&"; ")),1,0) -> 0 | AB27: =IF(ISNUMBER(SEARCH("; methodological judgment; ","; "&H27&"; ")),1,0) -> 0 | AC27: =IF(ISNUMBER(SEARCH("; argumentative judgment; ","; "&H27&"; ")),1,0) -> 0 | AD27: =IF(ISNUMBER(SEARCH("; genre/writing expertise; ","; "&H27&"; ")),1,0) -> 0 | AE27: =IF(ISNUMBER(SEARCH("; none; ","; "&H27&"; ")),1,0) -> 1
