Workbook

Sheet Summary
A2: Paper: | B2: Human oversight
A4: Human turns | B4: 90
A5: Turns with no substantive AI reply visible | B5: 12
J6: Expertise evidence
A7: Prompt (interaction) types | B7: Primary count | C7: Any occurrence | D7: Share of prompts | F7: Agency mode | G7: Turns | H7: Share | J7: Demonstrated human expertise types | K7: Turns | L7: Share
A8: Open delegation | B8: =COUNTIFS(Coding!$E$2:$E$91,A8) -> 0 | C8: =SUM(Coding!Q2:Q91) -> 3 | D8: =C8/$B$4 -> 0.033333333 | F8: Delegative | G8: =COUNTIFS(Coding!$G$2:$G$91,F8) -> 3 | H8: =G8/$B$4 -> 0.033333333 | J8: Domain correction | K8: =SUM(Coding!Z2:Z91) -> 0 | L8: =K8/$B$4 -> 0
A9: Directed delegation | B9: =COUNTIFS(Coding!$E$2:$E$91,A9) -> 29 | C9: =SUM(Coding!R2:R91) -> 58 | D9: =C9/$B$4 -> 0.64444444 | F9: Directive | G9: =COUNTIFS(Coding!$G$2:$G$91,F9) -> 47 | H9: =G9/$B$4 -> 0.52222222 | J9: Conceptual discrimination | K9: =SUM(Coding!AA2:AA91) -> 8 | L9: =K9/$B$4 -> 0.088888889
A10: Evaluation | B10: =COUNTIFS(Coding!$E$2:$E$91,A10) -> 14 | C10: =SUM(Coding!S2:S91) -> 19 | D10: =C10/$B$4 -> 0.21111111 | F10: Evaluative | G10: =COUNTIFS(Coding!$G$2:$G$91,F10) -> 15 | H10: =G10/$B$4 -> 0.16666667 | J10: Evidence judgment | K10: =SUM(Coding!AB2:AB91) -> 31 | L10: =K10/$B$4 -> 0.34444444
A11: Correction/Challenge | B11: =COUNTIFS(Coding!$E$2:$E$91,A11) -> 13 | C11: =SUM(Coding!T2:T91) -> 19 | D11: =C11/$B$4 -> 0.21111111 | F11: Critical | G11: =COUNTIFS(Coding!$G$2:$G$91,F11) -> 19 | H11: =G11/$B$4 -> 0.21111111 | J11: Methodological judgment | K11: =SUM(Coding!AC2:AC91) -> 12 | L11: =K11/$B$4 -> 0.13333333
A12: Redirection | B12: =COUNTIFS(Coding!$E$2:$E$91,A12) -> 6 | C12: =SUM(Coding!U2:U91) -> 16 | D12: =C12/$B$4 -> 0.17777778 | F12: Deliberative | G12: =COUNTIFS(Coding!$G$2:$G$91,F12) -> 6 | H12: =G12/$B$4 -> 0.066666667 | J12: Argumentative judgment | K12: =SUM(Coding!AD2:AD91) -> 34 | L12: =K12/$B$4 -> 0.37777778
A13: Knowledge injection | B13: =COUNTIFS(Coding!$E$2:$E$91,A13) -> 7 | C13: =SUM(Coding!V2:V91) -> 50 | D13: =C13/$B$4 -> 0.55555556 | J13: Genre/writing expertise | K13: =SUM(Coding!AE2:AE91) -> 44 | L13: =K13/$B$4 -> 0.48888889
A14: Selection/Rejection | B14: =COUNTIFS(Coding!$E$2:$E$91,A14) -> 12 | C14: =SUM(Coding!W2:W91) -> 29 | D14: =C14/$B$4 -> 0.32222222 | J14: None | K14: =SUM(Coding!AF2:AF91) -> 18 | L14: =K14/$B$4 -> 0.2
A15: Deliberation | B15: =COUNTIFS(Coding!$E$2:$E$91,A15) -> 6 | C15: =SUM(Coding!X2:X91) -> 6 | D15: =C15/$B$4 -> 0.066666667
A18: Phase | B18: First turn | C18: Last turn | D18: # of prompts (turns) | E18: Delegative | F18: Directive | G18: Evaluative | H18: Critical | I18: Deliberative
A19: Initial framing | B19: 1 | C19: 7 | D19: =C19-B19+1 -> 7 | E19: =COUNTIFS(Coding!$B$2:$B$91,">="&B19,Coding!$B$2:$B$91,"<="&C19,Coding!$G$2:$G$91,"Delegative") -> 1 | F19: =COUNTIFS(Coding!$B$2:$B$91,">="&B19,Coding!$B$2:$B$91,"<="&C19,Coding!$G$2:$G$91,"Directive") -> 4 | G19: =COUNTIFS(Coding!$B$2:$B$91,">="&B19,Coding!$B$2:$B$91,"<="&C19,Coding!$G$2:$G$91,"Evaluative") -> 1 | H19: =COUNTIFS(Coding!$B$2:$B$91,">="&B19,Coding!$B$2:$B$91,"<="&C19,Coding!$G$2:$G$91,"Critical") -> 1 | I19: =COUNTIFS(Coding!$B$2:$B$91,">="&B19,Coding!$B$2:$B$91,"<="&C19,Coding!$G$2:$G$91,"Deliberative") -> 0
A20: Source selection and citation repair | B20: 8 | C20: 19 | D20: =C20-B20+1 -> 12 | E20: =COUNTIFS(Coding!$B$2:$B$91,">="&B20,Coding!$B$2:$B$91,"<="&C20,Coding!$G$2:$G$91,"Delegative") -> 1 | F20: =COUNTIFS(Coding!$B$2:$B$91,">="&B20,Coding!$B$2:$B$91,"<="&C20,Coding!$G$2:$G$91,"Directive") -> 7 | G20: =COUNTIFS(Coding!$B$2:$B$91,">="&B20,Coding!$B$2:$B$91,"<="&C20,Coding!$G$2:$G$91,"Evaluative") -> 0 | H20: =COUNTIFS(Coding!$B$2:$B$91,">="&B20,Coding!$B$2:$B$91,"<="&C20,Coding!$G$2:$G$91,"Critical") -> 4 | I20: =COUNTIFS(Coding!$B$2:$B$91,">="&B20,Coding!$B$2:$B$91,"<="&C20,Coding!$G$2:$G$91,"Deliberative") -> 0
A21: Abstract and paper positioning | B21: 20 | C21: 36 | D21: =C21-B21+1 -> 17 | E21: =COUNTIFS(Coding!$B$2:$B$91,">="&B21,Coding!$B$2:$B$91,"<="&C21,Coding!$G$2:$G$91,"Delegative") -> 0 | F21: =COUNTIFS(Coding!$B$2:$B$91,">="&B21,Coding!$B$2:$B$91,"<="&C21,Coding!$G$2:$G$91,"Directive") -> 7 | G21: =COUNTIFS(Coding!$B$2:$B$91,">="&B21,Coding!$B$2:$B$91,"<="&C21,Coding!$G$2:$G$91,"Evaluative") -> 5 | H21: =COUNTIFS(Coding!$B$2:$B$91,">="&B21,Coding!$B$2:$B$91,"<="&C21,Coding!$G$2:$G$91,"Critical") -> 3 | I21: =COUNTIFS(Coding!$B$2:$B$91,">="&B21,Coding!$B$2:$B$91,"<="&C21,Coding!$G$2:$G$91,"Deliberative") -> 2
A22: Conceptual structure | B22: 37 | C22: 44 | D22: =C22-B22+1 -> 8 | E22: =COUNTIFS(Coding!$B$2:$B$91,">="&B22,Coding!$B$2:$B$91,"<="&C22,Coding!$G$2:$G$91,"Delegative") -> 0 | F22: =COUNTIFS(Coding!$B$2:$B$91,">="&B22,Coding!$B$2:$B$91,"<="&C22,Coding!$G$2:$G$91,"Directive") -> 6 | G22: =COUNTIFS(Coding!$B$2:$B$91,">="&B22,Coding!$B$2:$B$91,"<="&C22,Coding!$G$2:$G$91,"Evaluative") -> 0 | H22: =COUNTIFS(Coding!$B$2:$B$91,">="&B22,Coding!$B$2:$B$91,"<="&C22,Coding!$G$2:$G$91,"Critical") -> 0 | I22: =COUNTIFS(Coding!$B$2:$B$91,">="&B22,Coding!$B$2:$B$91,"<="&C22,Coding!$G$2:$G$91,"Deliberative") -> 2
A23: Supplement and section drafting | B23: 45 | C23: 59 | D23: =C23-B23+1 -> 15 | E23: =COUNTIFS(Coding!$B$2:$B$91,">="&B23,Coding!$B$2:$B$91,"<="&C23,Coding!$G$2:$G$91,"Delegative") -> 0 | F23: =COUNTIFS(Coding!$B$2:$B$91,">="&B23,Coding!$B$2:$B$91,"<="&C23,Coding!$G$2:$G$91,"Directive") -> 10 | G23: =COUNTIFS(Coding!$B$2:$B$91,">="&B23,Coding!$B$2:$B$91,"<="&C23,Coding!$G$2:$G$91,"Evaluative") -> 1 | H23: =COUNTIFS(Coding!$B$2:$B$91,">="&B23,Coding!$B$2:$B$91,"<="&C23,Coding!$G$2:$G$91,"Critical") -> 4 | I23: =COUNTIFS(Coding!$B$2:$B$91,">="&B23,Coding!$B$2:$B$91,"<="&C23,Coding!$G$2:$G$91,"Deliberative") -> 0
A24: Evidence audit and pool revision | B24: 60 | C24: 69 | D24: =C24-B24+1 -> 10 | E24: =COUNTIFS(Coding!$B$2:$B$91,">="&B24,Coding!$B$2:$B$91,"<="&C24,Coding!$G$2:$G$91,"Delegative") -> 0 | F24: =COUNTIFS(Coding!$B$2:$B$91,">="&B24,Coding!$B$2:$B$91,"<="&C24,Coding!$G$2:$G$91,"Directive") -> 3 | G24: =COUNTIFS(Coding!$B$2:$B$91,">="&B24,Coding!$B$2:$B$91,"<="&C24,Coding!$G$2:$G$91,"Evaluative") -> 4 | H24: =COUNTIFS(Coding!$B$2:$B$91,">="&B24,Coding!$B$2:$B$91,"<="&C24,Coding!$G$2:$G$91,"Critical") -> 3 | I24: =COUNTIFS(Coding!$B$2:$B$91,">="&B24,Coding!$B$2:$B$91,"<="&C24,Coding!$G$2:$G$91,"Deliberative") -> 0
A25: Completion and review requests | B25: 70 | C25: 78 | D25: =C25-B25+1 -> 9 | E25: =COUNTIFS(Coding!$B$2:$B$91,">="&B25,Coding!$B$2:$B$91,"<="&C25,Coding!$G$2:$G$91,"Delegative") -> 1 | F25: =COUNTIFS(Coding!$B$2:$B$91,">="&B25,Coding!$B$2:$B$91,"<="&C25,Coding!$G$2:$G$91,"Directive") -> 5 | G25: =COUNTIFS(Coding!$B$2:$B$91,">="&B25,Coding!$B$2:$B$91,"<="&C25,Coding!$G$2:$G$91,"Evaluative") -> 2 | H25: =COUNTIFS(Coding!$B$2:$B$91,">="&B25,Coding!$B$2:$B$91,"<="&C25,Coding!$G$2:$G$91,"Critical") -> 1 | I25: =COUNTIFS(Coding!$B$2:$B$91,">="&B25,Coding!$B$2:$B$91,"<="&C25,Coding!$G$2:$G$91,"Deliberative") -> 0
A26: Feedback and reframing | B26: 79 | C26: 90 | D26: =C26-B26+1 -> 12 | E26: =COUNTIFS(Coding!$B$2:$B$91,">="&B26,Coding!$B$2:$B$91,"<="&C26,Coding!$G$2:$G$91,"Delegative") -> 0 | F26: =COUNTIFS(Coding!$B$2:$B$91,">="&B26,Coding!$B$2:$B$91,"<="&C26,Coding!$G$2:$G$91,"Directive") -> 5 | G26: =COUNTIFS(Coding!$B$2:$B$91,">="&B26,Coding!$B$2:$B$91,"<="&C26,Coding!$G$2:$G$91,"Evaluative") -> 2 | H26: =COUNTIFS(Coding!$B$2:$B$91,">="&B26,Coding!$B$2:$B$91,"<="&C26,Coding!$G$2:$G$91,"Critical") -> 3 | I26: =COUNTIFS(Coding!$B$2:$B$91,">="&B26,Coding!$B$2:$B$91,"<="&C26,Coding!$G$2:$G$91,"Deliberative") -> 2
A29: Key patterns and limits
A30: Directive agency is most frequent: 47/90 turns (52.2%). Critical: 19 (21.1%); Evaluative: 15 (16.7%); Deliberative: 6 (6.7%); Delegative: 3 (3.3%).
A31: Drafting and scrutiny alternate. Human agency is visible through constraints, selection, verification and reframing, rather than a single linear shift toward deliberation.
A32: Citation repair: P2-013 rejects fake references; P2-014 challenges an entry still mislabeled after claimed verification; P2-018 supplies correct title and authors.
A33: Quotation audit: P2-060 to P2-065 check sources against burden categories. At P2-064, the assistant admits its earlier purported verbatim quotations are not in the source.
A34: Evidence control: P2-066 explicitly reduces ten sources to eight. P2-067 reports human-extracted quotes organized in table comments; actual comment access is unverified.
A35: Conceptual framing: P2-037 distinguishes IDE and chat-based tools. P2-042 merges overlapping cost categories. P2-050 removes a redundant category from the evidence table.
A36: Claim discipline: P2-006 and P2-025 moderate certainty. P2-073 labels the figure hypothetical. P2-083 to P2-090 negotiate column genre, evidence synthesis and voice.
A37: Turn-taking control: P2-083 asks AI to wait while the human develops responses; AI nevertheless drafts a reply. P2-084 reasserts human control over substantive replies.
A38: Twelve missing assistant replies limit outcome claims. The two identical review requests are retained. A visible yes approves only a contextual next step; P2-078 has no visible antecedent.
A39: Paper 1 has missing prompts, according to the user. The 22-versus-90 turn difference describes surviving records and cannot establish a difference in actual agency or expertise.
A40: Single-coder interpretive analysis. Source accuracy, final uptake and unseen attachments are not inferred. See Codebook for operational rules and ambiguous cases.

Sheet Coding
A1: Turn ID | B1: Sequence | C1: Phase | D1: Prompt excerpt | E1: Primary interaction type | F1: Additional interaction types | G1: Agency mode | H1: Expertise evidence | I1: Coding rationale | J1: Observed outcome / notes | K1: Prompt provenance | L1: Response provenance | M1: Attachment metadata | N1: Response availability | O1: Coding caution | P1: sum | Q1: Open Delegation | R1: Directed delegation | S1: Evaluation | T1: Correction/Challenge | U1: Redirection | V1: Knowledge injection | W1: Acceptance/ Rejection | X1: Deliberation | Y1: Expertise | Z1: Subject-matter correction | AA1: Conceptual differentiation | AB1: Evidence judgment | AC1: Methodological judgment | AD1: Argumentative judgment | AE1: Genre/ writing expertise | AF1: none
A2: P2-001 | B2: 1 | C2: Initial framing | D2: Hidden cost of AI-SE: Short opinion paper | E2: Delegation | G2: Delegative | H2: none | I2: Topic-only request for a short opinion paper, without substantive constraints. | J2: AI starts a short opinion draft and abstract. | K2: p4 L2-p4 L2 | L2: p4 L3-p4 L12 | N2: Visible substantive response | P2: =SUM(Paper2Coding[[#This Row],[Open Delegation]:[Expertise]]) -> 2 | Q2: =IF(OR(E2="Delegation",ISNUMBER(SEARCH("; Delegation; ","; "&F2&"; "))),1,0) -> 1 | R2: =IF(OR(E2="Directed delegation",ISNUMBER(SEARCH("; Directed delegation; ","; "&F2&"; "))),1,0) -> 0 | S2: =IF(OR(E2="Evaluation",ISNUMBER(SEARCH("; Evaluation; ","; "&F2&"; "))),1,0) -> 0 | T2: =IF(OR(E2="Correction/Challenge",ISNUMBER(SEARCH("; Correction/Challenge; ","; "&F2&"; "))),1,0) -> 0 | U2: =IF(OR(E2="Redirection",ISNUMBER(SEARCH("; Redirection; ","; "&F2&"; "))),1,0) -> 0 | V2: =IF(OR(E2="Knowledge injection",ISNUMBER(SEARCH("; Knowledge injection; ","; "&F2&"; "))),1,0) -> 0 | W2: =IF(OR(E2="Selection/Rejection",ISNUMBER(SEARCH("; Selection/Rejection; ","; "&F2&"; "))),1,0) -> 0 | X2: =IF(OR(E2="Deliberation",ISNUMBER(SEARCH("; Deliberation; ","; "&F2&"; "))),1,0) -> 0 | Y2: =SUM(Paper2Coding[[#This Row],[Subject-matter correction]:[none]]) -> 1 | Z2: =IF(ISNUMBER(SEARCH("; domain correction; ","; "&H2&"; ")),1,0) -> 0 | AA2: =IF(ISNUMBER(SEARCH("; conceptual discrimination; ","; "&H2&"; ")),1,0) -> 0 | AB2: =IF(ISNUMBER(SEARCH("; evidence judgment; ","; "&H2&"; ")),1,0) -> 0 | AC2: =IF(ISNUMBER(SEARCH("; methodological judgment; ","; "&H2&"; ")),1,0) -> 0 | AD2: =IF(ISNUMBER(SEARCH("; argumentative judgment; ","; "&H2&"; ")),1,0) -> 0 | AE2: =IF(ISNUMBER(SEARCH("; genre/writing expertise; ","; "&H2&"; ")),1,0) -> 0 | AF2: =IF(ISNUMBER(SEARCH("; none; ","; "&H2&"; ")),1,0) -> 1
A3: P2-002 | B3: 2 | C3: Initial framing | D3: I want to write a short "Opinion" paper for IEEE SW ... cannot present research findings ... first, suggest a clear title. | E3: Directed delegation | F3: Redirection; Knowledge injection | G3: Directive | H3: genre/writing expertise; argumentative judgment; methodological judgment | I3: Specifies venue, length, scope and objectives; explicitly rules out presenting original research findings. | J3: AI offers title options. The quantification objectives and opinion-only constraint create a tension, not resolved here. | K3: p4 L13-p4 L22 | L3: p4 L24-p4 L37 | N3: Visible substantive response | P3: =SUM(Paper2Coding[[#This Row],[Open Delegation]:[Expertise]]) -> 6 | Q3: =IF(OR(E3="Delegation",ISNUMBER(SEARCH("; Delegation; ","; "&F3&"; "))),1,0) -> 0 | R3: =IF(OR(E3="Directed delegation",ISNUMBER(SEARCH("; Directed delegation; ","; "&F3&"; "))),1,0) -> 1 | S3: =IF(OR(E3="Evaluation",ISNUMBER(SEARCH("; Evaluation; ","; "&F3&"; "))),1,0) -> 0 | T3: =IF(OR(E3="Correction/Challenge",ISNUMBER(SEARCH("; Correction/Challenge; ","; "&F3&"; "))),1,0) -> 0 | U3: =IF(OR(E3="Redirection",ISNUMBER(SEARCH("; Redirection; ","; "&F3&"; "))),1,0) -> 1 | V3: =IF(OR(E3="Knowledge injection",ISNUMBER(SEARCH("; Knowledge injection; ","; "&F3&"; "))),1,0) -> 1 | W3: =IF(OR(E3="Selection/Rejection",ISNUMBER(SEARCH("; Selection/Rejection; ","; "&F3&"; "))),1,0) -> 0 | X3: =IF(OR(E3="Deliberation",ISNUMBER(SEARCH("; Deliberation; ","; "&F3&"; "))),1,0) -> 0 | Y3: =SUM(Paper2Coding[[#This Row],[Subject-matter correction]:[none]]) -> 3 | Z3: =IF(ISNUMBER(SEARCH("; domain correction; ","; "&H3&"; ")),1,0) -> 0 | AA3: =IF(ISNUMBER(SEARCH("; conceptual discrimination; ","; "&H3&"; ")),1,0) -> 0 | AB3: =IF(ISNUMBER(SEARCH("; evidence judgment; ","; "&H3&"; ")),1,0) -> 0 | AC3: =IF(ISNUMBER(SEARCH("; methodological judgment; ","; "&H3&"; ")),1,0) -> 1 | AD3: =IF(ISNUMBER(SEARCH("; argumentative judgment; ","; "&H3&"; ")),1,0) -> 1 | AE3: =IF(ISNUMBER(SEARCH("; genre/writing expertise; ","; "&H3&"; ")),1,0) -> 1 | AF3: =IF(ISNUMBER(SEARCH("; none; ","; "&H3&"; ")),1,0) -> 0
A4: P2-003 | B4: 3 | C4: Initial framing | D4: make it shorter | E4: Directed delegation | G4: Directive | H4: genre/writing expertise | I4: Requests a shorter title, retaining control over brevity. | J4: AI offers shorter title options. | K4: p4 L38-p4 L38 | L4: p4 L39-p5 L6 | N4: Visible substantive response | P4: =SUM(Paper2Coding[[#This Row],[Open Delegation]:[Expertise]]) -> 2 | Q4: =IF(OR(E4="Delegation",ISNUMBER(SEARCH("; Delegation; ","; "&F4&"; "))),1,0) -> 0 | R4: =IF(OR(E4="Directed delegation",ISNUMBER(SEARCH("; Directed delegation; ","; "&F4&"; "))),1,0) -> 1 | S4: =IF(OR(E4="Evaluation",ISNUMBER(SEARCH("; Evaluation; ","; "&F4&"; "))),1,0) -> 0 | T4: =IF(OR(E4="Correction/Challenge",ISNUMBER(SEARCH("; Correction/Challenge; ","; "&F4&"; "))),1,0) -> 0 | U4: =IF(OR(E4="Redirection",ISNUMBER(SEARCH("; Redirection; ","; "&F4&"; "))),1,0) -> 0 | V4: =IF(OR(E4="Knowledge injection",ISNUMBER(SEARCH("; Knowledge injection; ","; "&F4&"; "))),1,0) -> 0 | W4: =IF(OR(E4="Selection/Rejection",ISNUMBER(SEARCH("; Selection/Rejection; ","; "&F4&"; "))),1,0) -> 0 | X4: =IF(OR(E4="Deliberation",ISNUMBER(SEARCH("; Deliberation; ","; "&F4&"; "))),1,0) -> 0 | Y4: =SUM(Paper2Coding[[#This Row],[Subject-matter correction]:[none]]) -> 1 | Z4: =IF(ISNUMBER(SEARCH("; domain correction; ","; "&H4&"; ")),1,0) -> 0 | AA4: =IF(ISNUMBER(SEARCH("; conceptual discrimination; ","; "&H4&"; ")),1,0) -> 0 | AB4: =IF(ISNUMBER(SEARCH("; evidence judgment; ","; "&H4&"; ")),1,0) -> 0 | AC4: =IF(ISNUMBER(SEARCH("; methodological judgment; ","; "&H4&"; ")),1,0) -> 0 | AD4: =IF(ISNUMBER(SEARCH("; argumentative judgment; ","; "&H4&"; ")),1,0) -> 0 | AE4: =IF(ISNUMBER(SEARCH("; genre/writing expertise; ","; "&H4&"; ")),1,0) -> 1 | AF4: =IF(ISNUMBER(SEARCH("; none; ","; "&H4&"; ")),1,0) -> 0
A5: P2-004 | B5: 4 | C5: Initial framing | D5: is rthis a good one: Hidden Cost of AI in Software Engineering: Efficiency versus Burden | E5: Evaluation | F5: Knowledge injection | G5: Evaluative | H5: genre/writing expertise; argumentative judgment | I5: Supplies a candidate title for assessment of its framing. | J5: AI endorses it and offers a slight refinement; no final choice yet. | K5: p5 L7-p5 L7 | L5: p5 L8-p5 L14 | N5: Visible substantive response | P5: =SUM(Paper2Coding[[#This Row],[Open Delegation]:[Expertise]]) -> 4 | Q5: =IF(OR(E5="Delegation",ISNUMBER(SEARCH("; Delegation; ","; "&F5&"; "))),1,0) -> 0 | R5: =IF(OR(E5="Directed delegation",ISNUMBER(SEARCH("; Directed delegation; ","; "&F5&"; "))),1,0) -> 0 | S5: =IF(OR(E5="Evaluation",ISNUMBER(SEARCH("; Evaluation; ","; "&F5&"; "))),1,0) -> 1 | T5: =IF(OR(E5="Correction/Challenge",ISNUMBER(SEARCH("; Correction/Challenge; ","; "&F5&"; "))),1,0) -> 0 | U5: =IF(OR(E5="Redirection",ISNUMBER(SEARCH("; Redirection; ","; "&F5&"; "))),1,0) -> 0 | V5: =IF(OR(E5="Knowledge injection",ISNUMBER(SEARCH("; Knowledge injection; ","; "&F5&"; "))),1,0) -> 1 | W5: =IF(OR(E5="Selection/Rejection",ISNUMBER(SEARCH("; Selection/Rejection; ","; "&F5&"; "))),1,0) -> 0 | X5: =IF(OR(E5="Deliberation",ISNUMBER(SEARCH("; Deliberation; ","; "&F5&"; "))),1,0) -> 0 | Y5: =SUM(Paper2Coding[[#This Row],[Subject-matter correction]:[none]]) -> 2 | Z5: =IF(ISNUMBER(SEARCH("; domain correction; ","; "&H5&"; ")),1,0) -> 0 | AA5: =IF(ISNUMBER(SEARCH("; conceptual discrimination; ","; "&H5&"; ")),1,0) -> 0 | AB5: =IF(ISNUMBER(SEARCH("; evidence judgment; ","; "&H5&"; ")),1,0) -> 0 | AC5: =IF(ISNUMBER(SEARCH("; methodological judgment; ","; "&H5&"; ")),1,0) -> 0 | AD5: =IF(ISNUMBER(SEARCH("; argumentative judgment; ","; "&H5&"; ")),1,0) -> 1 | AE5: =IF(ISNUMBER(SEARCH("; genre/writing expertise; ","; "&H5&"; ")),1,0) -> 1 | AF5: =IF(ISNUMBER(SEARCH("; none; ","; "&H5&"; ")),1,0) -> 0
A6: P2-005 | B6: 5 | C6: Initial framing | D6: give a short Abstract: and 5 Keywords | E6: Directed delegation | G6: Directive | H6: none | I6: Specifies short abstract and five keywords, without substantive argument constraints. | J6: AI provides an abstract and five keywords. | K6: p5 L15-p5 L16 | L6: p5 L17-p5 L22 | N6: Visible substantive response | P6: =SUM(Paper2Coding[[#This Row],[Open Delegation]:[Expertise]]) -> 2 | Q6: =IF(OR(E6="Delegation",ISNUMBER(SEARCH("; Delegation; ","; "&F6&"; "))),1,0) -> 0 | R6: =IF(OR(E6="Directed delegation",ISNUMBER(SEARCH("; Directed delegation; ","; "&F6&"; "))),1,0) -> 1 | S6: =IF(OR(E6="Evaluation",ISNUMBER(SEARCH("; Evaluation; ","; "&F6&"; "))),1,0) -> 0 | T6: =IF(OR(E6="Correction/Challenge",ISNUMBER(SEARCH("; Correction/Challenge; ","; "&F6&"; "))),1,0) -> 0 | U6: =IF(OR(E6="Redirection",ISNUMBER(SEARCH("; Redirection; ","; "&F6&"; "))),1,0) -> 0 | V6: =IF(OR(E6="Knowledge injection",ISNUMBER(SEARCH("; Knowledge injection; ","; "&F6&"; "))),1,0) -> 0 | W6: =IF(OR(E6="Selection/Rejection",ISNUMBER(SEARCH("; Selection/Rejection; ","; "&F6&"; "))),1,0) -> 0 | X6: =IF(OR(E6="Deliberation",ISNUMBER(SEARCH("; Deliberation; ","; "&F6&"; "))),1,0) -> 0 | Y6: =SUM(Paper2Coding[[#This Row],[Subject-matter correction]:[none]]) -> 1 | Z6: =IF(ISNUMBER(SEARCH("; domain correction; ","; "&H6&"; ")),1,0) -> 0 | AA6: =IF(ISNUMBER(SEARCH("; conceptual discrimination; ","; "&H6&"; ")),1,0) -> 0 | AB6: =IF(ISNUMBER(SEARCH("; evidence judgment; ","; "&H6&"; ")),1,0) -> 0 | AC6: =IF(ISNUMBER(SEARCH("; methodological judgment; ","; "&H6&"; ")),1,0) -> 0 | AD6: =IF(ISNUMBER(SEARCH("; argumentative judgment; ","; "&H6&"; ")),1,0) -> 0 | AE6: =IF(ISNUMBER(SEARCH("; genre/writing expertise; ","; "&H6&"; ")),1,0) -> 0 | AF6: =IF(ISNUMBER(SEARCH("; none; ","; "&H6&"; ")),1,0) -> 1
A7: P2-006 | B7: 6 | C7: Initial framing | D7: how about this: AI tools promise increased efficiency in software engineering (SE), yet their use can potentially introduce hidden costs. Software engineers must review, validate, and correct AI-generated SE artifacts—efforts that can potentially outweigh productivity gains. T... | E7: Correction/Challenge | F7: Evaluation; Knowledge injection; Redirection | G7: Critical | H7: evidence judgment; argumentative judgment; genre/writing expertise | I7: Adds potentially to moderate the strength of claims and requests assessment of the rewritten abstract. | J7: AI retains cautious claims while reducing repetition of potentially. | K7: p5 L23-p5 L27 | L7: p5 L29-p5 L36 | N7: Visible substantive response | P7: =SUM(Paper2Coding[[#This Row],[Open Delegation]:[Expertise]]) -> 7 | Q7: =IF(OR(E7="Delegation",ISNUMBER(SEARCH("; Delegation; ","; "&F7&"; "))),1,0) -> 0 | R7: =IF(OR(E7="Directed delegation",ISNUMBER(SEARCH("; Directed delegation; ","; "&F7&"; "))),1,0) -> 0 | S7: =IF(OR(E7="Evaluation",ISNUMBER(SEARCH("; Evaluation; ","; "&F7&"; "))),1,0) -> 1 | T7: =IF(OR(E7="Correction/Challenge",ISNUMBER(SEARCH("; Correction/Challenge; ","; "&F7&"; "))),1,0) -> 1 | U7: =IF(OR(E7="Redirection",ISNUMBER(SEARCH("; Redirection; ","; "&F7&"; "))),1,0) -> 1 | V7: =IF(OR(E7="Knowledge injection",ISNUMBER(SEARCH("; Knowledge injection; ","; "&F7&"; "))),1,0) -> 1 | W7: =IF(OR(E7="Selection/Rejection",ISNUMBER(SEARCH("; Selection/Rejection; ","; "&F7&"; "))),1,0) -> 0 | X7: =IF(OR(E7="Deliberation",ISNUMBER(SEARCH("; Deliberation; ","; "&F7&"; "))),1,0) -> 0 | Y7: =SUM(Paper2Coding[[#This Row],[Subject-matter correction]:[none]]) -> 3 | Z7: =IF(ISNUMBER(SEARCH("; domain correction; ","; "&H7&"; ")),1,0) -> 0 | AA7: =IF(ISNUMBER(SEARCH("; conceptual discrimination; ","; "&H7&"; ")),1,0) -> 0 | AB7: =IF(ISNUMBER(SEARCH("; evidence judgment; ","; "&H7&"; ")),1,0) -> 1 | AC7: =IF(ISNUMBER(SEARCH("; methodological judgment; ","; "&H7&"; ")),1,0) -> 0 | AD7: =IF(ISNUMBER(SEARCH("; argumentative judgment; ","; "&H7&"; ")),1,0) -> 1 | AE7: =IF(ISNUMBER(SEARCH("; genre/writing expertise; ","; "&H7&"; ")),1,0) -> 1 | AF7: =IF(ISNUMBER(SEARCH("; none; ","; "&H7&"; ")),1,0) -> 0
A8: P2-007 | B8: 7 | C8: Initial framing | D8: suggest the paper structure, recall: the MAX limit is 2600 words. consider adding two figures, each worth 250 words, thus leaving only 2100 words for text. suggest two figure topics. | E8: Directed delegation | G8: Directive | H8: genre/writing expertise | I8: Allocates a 2600-word budget, including two figures at 250 words each, and requests structure and figure topics. | J8: AI proposes sections, figure topics and word allocations using the stated budget. | K8: p5 L37-p5 L39 | L8: p5 L40-p6 L40 | N8: Visible substantive response | P8: =SUM(Paper2Coding[[#This Row],[Open Delegation]:[Expertise]]) -> 2 | Q8: =IF(OR(E8="Delegation",ISNUMBER(SEARCH("; Delegation; ","; "&F8&"; "))),1,0) -> 0 | R8: =IF(OR(E8="Directed delegation",ISNUMBER(SEARCH("; Directed delegation; ","; "&F8&"; "))),1,0) -> 1 | S8: =IF(OR(E8="Evaluation",ISNUMBER(SEARCH("; Evaluation; ","; "&F8&"; "))),1,0) -> 0 | T8: =IF(OR(E8="Correction/Challenge",ISNUMBER(SEARCH("; Correction/Challenge; ","; "&F8&"; "))),1,0) -> 0 | U8: =IF(OR(E8="Redirection",ISNUMBER(SEARCH("; Redirection; ","; "&F8&"; "))),1,0) -> 0 | V8: =IF(OR(E8="Knowledge injection",ISNUMBER(SEARCH("; Knowledge injection; ","; "&F8&"; "))),1,0) -> 0 | W8: =IF(OR(E8="Selection/Rejection",ISNUMBER(SEARCH("; Selection/Rejection; ","; "&F8&"; "))),1,0) -> 0 | X8: =IF(OR(E8="Deliberation",ISNUMBER(SEARCH("; Deliberation; ","; "&F8&"; "))),1,0) -> 0 | Y8: =SUM(Paper2Coding[[#This Row],[Subject-matter correction]:[none]]) -> 1 | Z8: =IF(ISNUMBER(SEARCH("; domain correction; ","; "&H8&"; ")),1,0) -> 0 | AA8: =IF(ISNUMBER(SEARCH("; conceptual discrimination; ","; "&H8&"; ")),1,0) -> 0 | AB8: =IF(ISNUMBER(SEARCH("; evidence judgment; ","; "&H8&"; ")),1,0) -> 0 | AC8: =IF(ISNUMBER(SEARCH("; methodological judgment; ","; "&H8&"; ")),1,0) -> 0 | AD8: =IF(ISNUMBER(SEARCH("; argumentative judgment; ","; "&H8&"; ")),1,0) -> 0 | AE8: =IF(ISNUMBER(SEARCH("; genre/writing expertise; ","; "&H8&"; ")),1,0) -> 1 | AF8: =IF(ISNUMBER(SEARCH("; none; ","; "&H8&"; ")),1,0) -> 0
A9: P2-008 | B9: 8 | C9: Source selection and citation repair | D9: search and show for me both academic and grey literature on the topic | E9: Directed delegation | G9: Directive | H9: evidence judgment | I9: Requests both academic and grey literature, specifying evidence types. | J9: AI reports an attempted search and partial progress, without a finished source list. | K9: p6 L41-p6 L41 | L9: p6 L42-p7 L28 | N9: Visible substantive response | P9: =SUM(Paper2Coding[[#This Row],[Open Delegation]:[Expertise]]) -> 2 | Q9: =IF(OR(E9="Delegation",ISNUMBER(SEARCH("; Delegation; ","; "&F9&"; "))),1,0) -> 0 | R9: =IF(OR(E9="Directed delegation",ISNUMBER(SEARCH("; Directed delegation; ","; "&F9&"; "))),1,0) -> 1 | S9: =IF(OR(E9="Evaluation",ISNUMBER(SEARCH("; Evaluation; ","; "&F9&"; "))),1,0) -> 0 | T9: =IF(OR(E9="Correction/Challenge",ISNUMBER(SEARCH("; Correction/Challenge; ","; "&F9&"; "))),1,0) -> 0 | U9: =IF(OR(E9="Redirection",ISNUMBER(SEARCH("; Redirection; ","; "&F9&"; "))),1,0) -> 0 | V9: =IF(OR(E9="Knowledge injection",ISNUMBER(SEARCH("; Knowledge injection; ","; "&F9&"; "))),1,0) -> 0 | W9: =IF(OR(E9="Selection/Rejection",ISNUMBER(SEARCH("; Selection/Rejection; ","; "&F9&"; "))),1,0) -> 0 | X9: =IF(OR(E9="Deliberation",ISNUMBER(SEARCH("; Deliberation; ","; "&F9&"; "))),1,0) -> 0 | Y9: =SUM(Paper2Coding[[#This Row],[Subject-matter correction]:[none]]) -> 1 | Z9: =IF(ISNUMBER(SEARCH("; domain correction; ","; "&H9&"; ")),1,0) -> 0 | AA9: =IF(ISNUMBER(SEARCH("; conceptual discrimination; ","; "&H9&"; ")),1,0) -> 0 | AB9: =IF(ISNUMBER(SEARCH("; evidence judgment; ","; "&H9&"; ")),1,0) -> 1 | AC9: =IF(ISNUMBER(SEARCH("; methodological judgment; ","; "&H9&"; ")),1,0) -> 0 | AD9: =IF(ISNUMBER(SEARCH("; argumentative judgment; ","; "&H9&"; ")),1,0) -> 0 | AE9: =IF(ISNUMBER(SEARCH("; genre/writing expertise; ","; "&H9&"; ")),1,0) -> 0 | AF9: =IF(ISNUMBER(SEARCH("; none; ","; "&H9&"; ")),1,0) -> 0
A10: P2-009 | B10: 9 | C10: Source selection and citation repair | D10: just list them in the chat | E10: Directed delegation | F10: Redirection | G10: Directive | H10: none | I10: Changes presentation to a direct list in chat. | J10: AI lists academic and grey sources. Later corrections establish that at least one citation was misidentified. | K10: p7 L29-p7 L29 | L10: p7 L30-p8 L14 | N10: Visible substantive response | P10: =SUM(Paper2Coding[[#This Row],[Open Delegation]:[Expertise]]) -> 3 | Q10: =IF(OR(E10="Delegation",ISNUMBER(SEARCH("; Delegation; ","; "&F10&"; "))),1,0) -> 0 | R10: =IF(OR(E10="Directed delegation",ISNUMBER(SEARCH("; Directed delegation; ","; "&F10&"; "))),1,0) -> 1 | S10: =IF(OR(E10="Evaluation",ISNUMBER(SEARCH("; Evaluation; ","; "&F10&"; "))),1,0) -> 0 | T10: =IF(OR(E10="Correction/Challenge",ISNUMBER(SEARCH("; Correction/Challenge; ","; "&F10&"; "))),1,0) -> 0 | U10: =IF(OR(E10="Redirection",ISNUMBER(SEARCH("; Redirection; ","; "&F10&"; "))),1,0) -> 1 | V10: =IF(OR(E10="Knowledge injection",ISNUMBER(SEARCH("; Knowledge injection; ","; "&F10&"; "))),1,0) -> 0 | W10: =IF(OR(E10="Selection/Rejection",ISNUMBER(SEARCH("; Selection/Rejection; ","; "&F10&"; "))),1,0) -> 0 | X10: =IF(OR(E10="Deliberation",ISNUMBER(SEARCH("; Deliberation; ","; "&F10&"; "))),1,0) -> 0 | Y10: =SUM(Paper2Coding[[#This Row],[Subject-matter correction]:[none]]) -> 1 | Z10: =IF(ISNUMBER(SEARCH("; domain correction; ","; "&H10&"; ")),1,0) -> 0 | AA10: =IF(ISNUMBER(SEARCH("; conceptual discrimination; ","; "&H10&"; ")),1,0) -> 0 | AB10: =IF(ISNUMBER(SEARCH("; evidence judgment; ","; "&H10&"; ")),1,0) -> 0 | AC10: =IF(ISNUMBER(SEARCH("; methodological judgment; ","; "&H10&"; ")),1,0) -> 0 | AD10: =IF(ISNUMBER(SEARCH("; argumentative judgment; ","; "&H10&"; ")),1,0) -> 0 | AE10: =IF(ISNUMBER(SEARCH("; genre/writing expertise; ","; "&H10&"; ")),1,0) -> 0 | AF10: =IF(ISNUMBER(SEARCH("; none; ","; "&H10&"; ")),1,0) -> 1
A11: P2-010 | B11: 10 | C11: Source selection and citation repair | D11: I found these: [seven source URLs] ... ensuring using ideas from them, mixi with my ideas, and citer them throught my paper | E11: Knowledge injection | F11: Directed delegation; Selection/Rejection | G11: Directive | H11: evidence judgment; argumentative judgment | I11: Supplies seven selected source URLs and instructs integration with the human's ideas throughout the paper. | J11: AI acknowledges the pool and intended integration; it does not draft a section in this response. | K11: p8 L15-p8 L22 | L11: p8 L24-p8 L25 | N11: Visible substantive response | P11: =SUM(Paper2Coding[[#This Row],[Open Delegation]:[Expertise]]) -> 5 | Q11: =IF(OR(E11="Delegation",ISNUMBER(SEARCH("; Delegation; ","; "&F11&"; "))),1,0) -> 0 | R11: =IF(OR(E11="Directed delegation",ISNUMBER(SEARCH("; Directed delegation; ","; "&F11&"; "))),1,0) -> 1 | S11: =IF(OR(E11="Evaluation",ISNUMBER(SEARCH("; Evaluation; ","; "&F11&"; "))),1,0) -> 0 | T11: =IF(OR(E11="Correction/Challenge",ISNUMBER(SEARCH("; Correction/Challenge; ","; "&F11&"; "))),1,0) -> 0 | U11: =IF(OR(E11="Redirection",ISNUMBER(SEARCH("; Redirection; ","; "&F11&"; "))),1,0) -> 0 | V11: =IF(OR(E11="Knowledge injection",ISNUMBER(SEARCH("; Knowledge injection; ","; "&F11&"; "))),1,0) -> 1 | W11: =IF(OR(E11="Selection/Rejection",ISNUMBER(SEARCH("; Selection/Rejection; ","; "&F11&"; "))),1,0) -> 1 | X11: =IF(OR(E11="Deliberation",ISNUMBER(SEARCH("; Deliberation; ","; "&F11&"; "))),1,0) -> 0 | Y11: =SUM(Paper2Coding[[#This Row],[Subject-matter correction]:[none]]) -> 2 | Z11: =IF(ISNUMBER(SEARCH("; domain correction; ","; "&H11&"; ")),1,0) -> 0 | AA11: =IF(ISNUMBER(SEARCH("; conceptual discrimination; ","; "&H11&"; ")),1,0) -> 0 | AB11: =IF(ISNUMBER(SEARCH("; evidence judgment; ","; "&H11&"; ")),1,0) -> 1 | AC11: =IF(ISNUMBER(SEARCH("; methodological judgment; ","; "&H11&"; ")),1,0) -> 0 | AD11: =IF(ISNUMBER(SEARCH("; argumentative judgment; ","; "&H11&"; ")),1,0) -> 1 | AE11: =IF(ISNUMBER(SEARCH("; genre/writing expertise; ","; "&H11&"; ")),1,0) -> 0 | AF11: =IF(ISNUMBER(SEARCH("; none; ","; "&H11&"; ")),1,0) -> 0
A12: P2-011 | B12: 11 | C12: Source selection and citation repair | D12: write section 1 | E12: Delegation | G12: Delegative | H12: none | I12: Requests Section 1 with no new substantive specification. Earlier constraints remain context. | J12: AI drafts an introduction using the supplied sources. | K12: p8 L26-p8 L26 | L12: p8 L27-p9 L5 | N12: Visible substantive response | P12: =SUM(Paper2Coding[[#This Row],[Open Delegation]:[Expertise]]) -> 2 | Q12: =IF(OR(E12="Delegation",ISNUMBER(SEARCH("; Delegation; ","; "&F12&"; "))),1,0) -> 1 | R12: =IF(OR(E12="Directed delegation",ISNUMBER(SEARCH("; Directed delegation; ","; "&F12&"; "))),1,0) -> 0 | S12: =IF(OR(E12="Evaluation",ISNUMBER(SEARCH("; Evaluation; ","; "&F12&"; "))),1,0) -> 0 | T12: =IF(OR(E12="Correction/Challenge",ISNUMBER(SEARCH("; Correction/Challenge; ","; "&F12&"; "))),1,0) -> 0 | U12: =IF(OR(E12="Redirection",ISNUMBER(SEARCH("; Redirection; ","; "&F12&"; "))),1,0) -> 0 | V12: =IF(OR(E12="Knowledge injection",ISNUMBER(SEARCH("; Knowledge injection; ","; "&F12&"; "))),1,0) -> 0 | W12: =IF(OR(E12="Selection/Rejection",ISNUMBER(SEARCH("; Selection/Rejection; ","; "&F12&"; "))),1,0) -> 0 | X12: =IF(OR(E12="Deliberation",ISNUMBER(SEARCH("; Deliberation; ","; "&F12&"; "))),1,0) -> 0 | Y12: =SUM(Paper2Coding[[#This Row],[Subject-matter correction]:[none]]) -> 1 | Z12: =IF(ISNUMBER(SEARCH("; domain correction; ","; "&H12&"; ")),1,0) -> 0 | AA12: =IF(ISNUMBER(SEARCH("; conceptual discrimination; ","; "&H12&"; ")),1,0) -> 0 | AB12: =IF(ISNUMBER(SEARCH("; evidence judgment; ","; "&H12&"; ")),1,0) -> 0 | AC12: =IF(ISNUMBER(SEARCH("; methodological judgment; ","; "&H12&"; ")),1,0) -> 0 | AD12: =IF(ISNUMBER(SEARCH("; argumentative judgment; ","; "&H12&"; ")),1,0) -> 0 | AE12: =IF(ISNUMBER(SEARCH("; genre/writing expertise; ","; "&H12&"; ")),1,0) -> 0 | AF12: =IF(ISNUMBER(SEARCH("; none; ","; "&H12&"; ")),1,0) -> 1
A13: P2-012 | B13: 12 | C13: Source selection and citation repair | D13: for each ref cited, give me their full list at end of each section | E13: Directed delegation | G13: Directive | H13: evidence judgment; genre/writing expertise | I13: Requires a full reference list at the end of every section for traceability. | J13: AI supplies the Section 1 list, including the subsequently challenged arXiv citation. | K13: p9 L6-p9 L6 | L13: p9 L7-p9 L21 | N13: Visible substantive response | P13: =SUM(Paper2Coding[[#This Row],[Open Delegation]:[Expertise]]) -> 3 | Q13: =IF(OR(E13="Delegation",ISNUMBER(SEARCH("; Delegation; ","; "&F13&"; "))),1,0) -> 0 | R13: =IF(OR(E13="Directed delegation",ISNUMBER(SEARCH("; Directed delegation; ","; "&F13&"; "))),1,0) -> 1 | S13: =IF(OR(E13="Evaluation",ISNUMBER(SEARCH("; Evaluation; ","; "&F13&"; "))),1,0) -> 0 | T13: =IF(OR(E13="Correction/Challenge",ISNUMBER(SEARCH("; Correction/Challenge; ","; "&F13&"; "))),1,0) -> 0 | U13: =IF(OR(E13="Redirection",ISNUMBER(SEARCH("; Redirection; ","; "&F13&"; "))),1,0) -> 0 | V13: =IF(OR(E13="Knowledge injection",ISNUMBER(SEARCH("; Knowledge injection; ","; "&F13&"; "))),1,0) -> 0 | W13: =IF(OR(E13="Selection/Rejection",ISNUMBER(SEARCH("; Selection/Rejection; ","; "&F13&"; "))),1,0) -> 0 | X13: =IF(OR(E13="Deliberation",ISNUMBER(SEARCH("; Deliberation; ","; "&F13&"; "))),1,0) -> 0 | Y13: =SUM(Paper2Coding[[#This Row],[Subject-matter correction]:[none]]) -> 2 | Z13: =IF(ISNUMBER(SEARCH("; domain correction; ","; "&H13&"; ")),1,0) -> 0 | AA13: =IF(ISNUMBER(SEARCH("; conceptual discrimination; ","; "&H13&"; ")),1,0) -> 0 | AB13: =IF(ISNUMBER(SEARCH("; evidence judgment; ","; "&H13&"; ")),1,0) -> 1 | AC13: =IF(ISNUMBER(SEARCH("; methodological judgment; ","; "&H13&"; ")),1,0) -> 0 | AD13: =IF(ISNUMBER(SEARCH("; argumentative judgment; ","; "&H13&"; ")),1,0) -> 0 | AE13: =IF(ISNUMBER(SEARCH("; genre/writing expertise; ","; "&H13&"; ")),1,0) -> 1 | AF13: =IF(ISNUMBER(SEARCH("; none; ","; "&H13&"; ")),1,0) -> 0
A14: P2-013 | B14: 13 | C14: Source selection and citation repair | D14: do not generate FAKE refernedces. verify each of the above and remove the FAKE ones | E14: Correction/Challenge | F14: Directed delegation; Selection/Rejection | G14: Critical | H14: evidence judgment; methodological judgment | I14: Explicitly challenges fake references and demands verification and removal. | J14: AI labels the list verified but repeats the misidentified arXiv citation challenged in the next turn. | K14: p9 L22-p9 L22 | L14: p9 L23-p9 L40 | N14: Visible substantive response | P14: =SUM(Paper2Coding[[#This Row],[Open Delegation]:[Expertise]]) -> 5 | Q14: =IF(OR(E14="Delegation",ISNUMBER(SEARCH("; Delegation; ","; "&F14&"; "))),1,0) -> 0 | R14: =IF(OR(E14="Directed delegation",ISNUMBER(SEARCH("; Directed delegation; ","; "&F14&"; "))),1,0) -> 1 | S14: =IF(OR(E14="Evaluation",ISNUMBER(SEARCH("; Evaluation; ","; "&F14&"; "))),1,0) -> 0 | T14: =IF(OR(E14="Correction/Challenge",ISNUMBER(SEARCH("; Correction/Challenge; ","; "&F14&"; "))),1,0) -> 1 | U14: =IF(OR(E14="Redirection",ISNUMBER(SEARCH("; Redirection; ","; "&F14&"; "))),1,0) -> 0 | V14: =IF(OR(E14="Knowledge injection",ISNUMBER(SEARCH("; Knowledge injection; ","; "&F14&"; "))),1,0) -> 0 | W14: =IF(OR(E14="Selection/Rejection",ISNUMBER(SEARCH("; Selection/Rejection; ","; "&F14&"; "))),1,0) -> 1 | X14: =IF(OR(E14="Deliberation",ISNUMBER(SEARCH("; Deliberation; ","; "&F14&"; "))),1,0) -> 0 | Y14: =SUM(Paper2Coding[[#This Row],[Subject-matter correction]:[none]]) -> 2 | Z14: =IF(ISNUMBER(SEARCH("; domain correction; ","; "&H14&"; ")),1,0) -> 0 | AA14: =IF(ISNUMBER(SEARCH("; conceptual discrimination; ","; "&H14&"; ")),1,0) -> 0 | AB14: =IF(ISNUMBER(SEARCH("; evidence judgment; ","; "&H14&"; ")),1,0) -> 1 | AC14: =IF(ISNUMBER(SEARCH("; methodological judgment; ","; "&H14&"; ")),1,0) -> 1 | AD14: =IF(ISNUMBER(SEARCH("; argumentative judgment; ","; "&H14&"; ")),1,0) -> 0 | AE14: =IF(ISNUMBER(SEARCH("; genre/writing expertise; ","; "&H14&"; ")),1,0) -> 0 | AF14: =IF(ISNUMBER(SEARCH("; none; ","; "&H14&"; ")),1,0) -> 0
A15: P2-014 | B15: 14 | C15: Source selection and citation repair | D15: A. Siddiq, A. Agashe, Y. Zhou, et al., _Evaluating Large Language Models for Code Quality: An Empirical Study_, arXiv preprint arXiv:2410.06992v1, 2024. \[Online\]. Available: [https://arxiv.org/html/2410.06992v1](https://arxiv.org/html/2410.06992v1) is still fake!! | E15: Correction/Challenge | G15: Critical | H15: evidence judgment | I15: Identifies the particular citation as still fake, challenging the earlier verification assurance. | J15: AI admits that title and authors do not match the identifier and advises removing the entry. | K15: p10 L1-p10 L3 | L15: p10 L4-p10 L19 | N15: Visible substantive response | P15: =SUM(Paper2Coding[[#This Row],[Open Delegation]:[Expertise]]) -> 2 | Q15: =IF(OR(E15="Delegation",ISNUMBER(SEARCH("; Delegation; ","; "&F15&"; "))),1,0) -> 0 | R15: =IF(OR(E15="Directed delegation",ISNUMBER(SEARCH("; Directed delegation; ","; "&F15&"; "))),1,0) -> 0 | S15: =IF(OR(E15="Evaluation",ISNUMBER(SEARCH("; Evaluation; ","; "&F15&"; "))),1,0) -> 0 | T15: =IF(OR(E15="Correction/Challenge",ISNUMBER(SEARCH("; Correction/Challenge; ","; "&F15&"; "))),1,0) -> 1 | U15: =IF(OR(E15="Redirection",ISNUMBER(SEARCH("; Redirection; ","; "&F15&"; "))),1,0) -> 0 | V15: =IF(OR(E15="Knowledge injection",ISNUMBER(SEARCH("; Knowledge injection; ","; "&F15&"; "))),1,0) -> 0 | W15: =IF(OR(E15="Selection/Rejection",ISNUMBER(SEARCH("; Selection/Rejection; ","; "&F15&"; "))),1,0) -> 0 | X15: =IF(OR(E15="Deliberation",ISNUMBER(SEARCH("; Deliberation; ","; "&F15&"; "))),1,0) -> 0 | Y15: =SUM(Paper2Coding[[#This Row],[Subject-matter correction]:[none]]) -> 1 | Z15: =IF(ISNUMBER(SEARCH("; domain correction; ","; "&H15&"; ")),1,0) -> 0 | AA15: =IF(ISNUMBER(SEARCH("; conceptual discrimination; ","; "&H15&"; ")),1,0) -> 0 | AB15: =IF(ISNUMBER(SEARCH("; evidence judgment; ","; "&H15&"; ")),1,0) -> 1 | AC15: =IF(ISNUMBER(SEARCH("; methodological judgment; ","; "&H15&"; ")),1,0) -> 0 | AD15: =IF(ISNUMBER(SEARCH("; argumentative judgment; ","; "&H15&"; ")),1,0) -> 0 | AE15: =IF(ISNUMBER(SEARCH("; genre/writing expertise; ","; "&H15&"; ")),1,0) -> 0 | AF15: =IF(ISNUMBER(SEARCH("; none; ","; "&H15&"; ")),1,0) -> 0
A16: P2-015 | B16: 15 | C16: Source selection and citation repair | D16: include also https://arxiv.org/html/2410.06992v1 | E16: Selection/Rejection | F16: Directed delegation | G16: Directive | H16: evidence judgment | I16: Retains the supplied arXiv URL despite rejecting its erroneous bibliographic description. | J16: AI agrees to include the URL; it does not establish correct metadata in this response. | K16: p10 L20-p10 L20 | L16: p10 L21-p10 L22 | N16: Visible substantive response | P16: =SUM(Paper2Coding[[#This Row],[Open Delegation]:[Expertise]]) -> 3 | Q16: =IF(OR(E16="Delegation",ISNUMBER(SEARCH("; Delegation; ","; "&F16&"; "))),1,0) -> 0 | R16: =IF(OR(E16="Directed delegation",ISNUMBER(SEARCH("; Directed delegation; ","; "&F16&"; "))),1,0) -> 1 | S16: =IF(OR(E16="Evaluation",ISNUMBER(SEARCH("; Evaluation; ","; "&F16&"; "))),1,0) -> 0 | T16: =IF(OR(E16="Correction/Challenge",ISNUMBER(SEARCH("; Correction/Challenge; ","; "&F16&"; "))),1,0) -> 0 | U16: =IF(OR(E16="Redirection",ISNUMBER(SEARCH("; Redirection; ","; "&F16&"; "))),1,0) -> 0 | V16: =IF(OR(E16="Knowledge injection",ISNUMBER(SEARCH("; Knowledge injection; ","; "&F16&"; "))),1,0) -> 0 | W16: =IF(OR(E16="Selection/Rejection",ISNUMBER(SEARCH("; Selection/Rejection; ","; "&F16&"; "))),1,0) -> 1 | X16: =IF(OR(E16="Deliberation",ISNUMBER(SEARCH("; Deliberation; ","; "&F16&"; "))),1,0) -> 0 | Y16: =SUM(Paper2Coding[[#This Row],[Subject-matter correction]:[none]]) -> 1 | Z16: =IF(ISNUMBER(SEARCH("; domain correction; ","; "&H16&"; ")),1,0) -> 0 | AA16: =IF(ISNUMBER(SEARCH("; conceptual discrimination; ","; "&H16&"; ")),1,0) -> 0 | AB16: =IF(ISNUMBER(SEARCH("; evidence judgment; ","; "&H16&"; ")),1,0) -> 1 | AC16: =IF(ISNUMBER(SEARCH("; methodological judgment; ","; "&H16&"; ")),1,0) -> 0 | AD16: =IF(ISNUMBER(SEARCH("; argumentative judgment; ","; "&H16&"; ")),1,0) -> 0 | AE16: =IF(ISNUMBER(SEARCH("; genre/writing expertise; ","; "&H16&"; ")),1,0) -> 0 | AF16: =IF(ISNUMBER(SEARCH("; none; ","; "&H16&"; ")),1,0) -> 0
A17: P2-016 | B17: 16 | C17: Source selection and citation repair | D17: give updated section 1 with citing all 7 sources | E17: Directed delegation | G17: Directive | H17: evidence judgment; genre/writing expertise | I17: Requires the revised introduction to cite all seven selected sources. | J17: AI supplies an updated introduction and reference list. | K17: p10 L23-p10 L23 | L17: p10 L24-p11 L22 | N17: Visible substantive response | P17: =SUM(Paper2Coding[[#This Row],[Open Delegation]:[Expertise]]) -> 3 | Q17: =IF(OR(E17="Delegation",ISNUMBER(SEARCH("; Delegation; ","; "&F17&"; "))),1,0) -> 0 | R17: =IF(OR(E17="Directed delegation",ISNUMBER(SEARCH("; Directed delegation; ","; "&F17&"; "))),1,0) -> 1 | S17: =IF(OR(E17="Evaluation",ISNUMBER(SEARCH("; Evaluation; ","; "&F17&"; "))),1,0) -> 0 | T17: =IF(OR(E17="Correction/Challenge",ISNUMBER(SEARCH("; Correction/Challenge; ","; "&F17&"; "))),1,0) -> 0 | U17: =IF(OR(E17="Redirection",ISNUMBER(SEARCH("; Redirection; ","; "&F17&"; "))),1,0) -> 0 | V17: =IF(OR(E17="Knowledge injection",ISNUMBER(SEARCH("; Knowledge injection; ","; "&F17&"; "))),1,0) -> 0 | W17: =IF(OR(E17="Selection/Rejection",ISNUMBER(SEARCH("; Selection/Rejection; ","; "&F17&"; "))),1,0) -> 0 | X17: =IF(OR(E17="Deliberation",ISNUMBER(SEARCH("; Deliberation; ","; "&F17&"; "))),1,0) -> 0 | Y17: =SUM(Paper2Coding[[#This Row],[Subject-matter correction]:[none]]) -> 2 | Z17: =IF(ISNUMBER(SEARCH("; domain correction; ","; "&H17&"; ")),1,0) -> 0 | AA17: =IF(ISNUMBER(SEARCH("; conceptual discrimination; ","; "&H17&"; ")),1,0) -> 0 | AB17: =IF(ISNUMBER(SEARCH("; evidence judgment; ","; "&H17&"; ")),1,0) -> 1 | AC17: =IF(ISNUMBER(SEARCH("; methodological judgment; ","; "&H17&"; ")),1,0) -> 0 | AD17: =IF(ISNUMBER(SEARCH("; argumentative judgment; ","; "&H17&"; ")),1,0) -> 0 | AE17: =IF(ISNUMBER(SEARCH("; genre/writing expertise; ","; "&H17&"; ")),1,0) -> 1 | AF17: =IF(ISNUMBER(SEARCH("; none; ","; "&H17&"; ")),1,0) -> 0
A18: P2-017 | B18: 17 | C18: Source selection and citation repair | D18: include this also: https://stackoverflow.blog/2024/12/31/generative-ai-is-not-going-to-build-your-engineering-team-for-you/ as the 8th citation | E18: Knowledge injection | F18: Directed delegation; Selection/Rejection | G18: Directive | H18: evidence judgment | I18: Adds a selected Stack Overflow source as the eighth citation. | J18: AI acknowledges the source and revises the introduction and references. | K18: p11 L23-p11 L23 | L18: p11 L24-p12 L23 | N18: Visible substantive response | P18: =SUM(Paper2Coding[[#This Row],[Open Delegation]:[Expertise]]) -> 4 | Q18: =IF(OR(E18="Delegation",ISNUMBER(SEARCH("; Delegation; ","; "&F18&"; "))),1,0) -> 0 | R18: =IF(OR(E18="Directed delegation",ISNUMBER(SEARCH("; Directed delegation; ","; "&F18&"; "))),1,0) -> 1 | S18: =IF(OR(E18="Evaluation",ISNUMBER(SEARCH("; Evaluation; ","; "&F18&"; "))),1,0) -> 0 | T18: =IF(OR(E18="Correction/Challenge",ISNUMBER(SEARCH("; Correction/Challenge; ","; "&F18&"; "))),1,0) -> 0 | U18: =IF(OR(E18="Redirection",ISNUMBER(SEARCH("; Redirection; ","; "&F18&"; "))),1,0) -> 0 | V18: =IF(OR(E18="Knowledge injection",ISNUMBER(SEARCH("; Knowledge injection; ","; "&F18&"; "))),1,0) -> 1 | W18: =IF(OR(E18="Selection/Rejection",ISNUMBER(SEARCH("; Selection/Rejection; ","; "&F18&"; "))),1,0) -> 1 | X18: =IF(OR(E18="Deliberation",ISNUMBER(SEARCH("; Deliberation; ","; "&F18&"; "))),1,0) -> 0 | Y18: =SUM(Paper2Coding[[#This Row],[Subject-matter correction]:[none]]) -> 1 | Z18: =IF(ISNUMBER(SEARCH("; domain correction; ","; "&H18&"; ")),1,0) -> 0 | AA18: =IF(ISNUMBER(SEARCH("; conceptual discrimination; ","; "&H18&"; ")),1,0) -> 0 | AB18: =IF(ISNUMBER(SEARCH("; evidence judgment; ","; "&H18&"; ")),1,0) -> 1 | AC18: =IF(ISNUMBER(SEARCH("; methodological judgment; ","; "&H18&"; ")),1,0) -> 0 | AD18: =IF(ISNUMBER(SEARCH("; argumentative judgment; ","; "&H18&"; ")),1,0) -> 0 | AE18: =IF(ISNUMBER(SEARCH("; genre/writing expertise; ","; "&H18&"; ")),1,0) -> 0 | AF18: =IF(ISNUMBER(SEARCH("; none; ","; "&H18&"; ")),1,0) -> 0
A19: P2-018 | B19: 18 | C19: Source selection and citation repair | D19: A. Siddiq, A. Agashe, Y. Zhou, et al., _Evaluating Large Language Models for Code Quality: An Empirical Study_ fix it. it is: SWE-Bench+: Enhanced Coding Benchmark for LLMs Reem Aleithan, Haoran Xue, Mohammad Mahdi Mohajer, Elijah Nnorom, Gias Uddin, Song Wang | E19: Correction/Challenge | F19: Knowledge injection; Directed delegation | G19: Critical | H19: evidence judgment | I19: Supplies the correct SWE-Bench+ title and six authors to replace the invented metadata. | J19: AI updates citation metadata. Its new claim about human repair is not independently verified here. | K19: p12 L24-p12 L26 | L19: p12 L27-p12 L34 | N19: Visible substantive response | P19: =SUM(Paper2Coding[[#This Row],[Open Delegation]:[Expertise]]) -> 4 | Q19: =IF(OR(E19="Delegation",ISNUMBER(SEARCH("; Delegation; ","; "&F19&"; "))),1,0) -> 0 | R19: =IF(OR(E19="Directed delegation",ISNUMBER(SEARCH("; Directed delegation; ","; "&F19&"; "))),1,0) -> 1 | S19: =IF(OR(E19="Evaluation",ISNUMBER(SEARCH("; Evaluation; ","; "&F19&"; "))),1,0) -> 0 | T19: =IF(OR(E19="Correction/Challenge",ISNUMBER(SEARCH("; Correction/Challenge; ","; "&F19&"; "))),1,0) -> 1 | U19: =IF(OR(E19="Redirection",ISNUMBER(SEARCH("; Redirection; ","; "&F19&"; "))),1,0) -> 0 | V19: =IF(OR(E19="Knowledge injection",ISNUMBER(SEARCH("; Knowledge injection; ","; "&F19&"; "))),1,0) -> 1 | W19: =IF(OR(E19="Selection/Rejection",ISNUMBER(SEARCH("; Selection/Rejection; ","; "&F19&"; "))),1,0) -> 0 | X19: =IF(OR(E19="Deliberation",ISNUMBER(SEARCH("; Deliberation; ","; "&F19&"; "))),1,0) -> 0 | Y19: =SUM(Paper2Coding[[#This Row],[Subject-matter correction]:[none]]) -> 1 | Z19: =IF(ISNUMBER(SEARCH("; domain correction; ","; "&H19&"; ")),1,0) -> 0 | AA19: =IF(ISNUMBER(SEARCH("; conceptual discrimination; ","; "&H19&"; ")),1,0) -> 0 | AB19: =IF(ISNUMBER(SEARCH("; evidence judgment; ","; "&H19&"; ")),1,0) -> 1 | AC19: =IF(ISNUMBER(SEARCH("; methodological judgment; ","; "&H19&"; ")),1,0) -> 0 | AD19: =IF(ISNUMBER(SEARCH("; argumentative judgment; ","; "&H19&"; ")),1,0) -> 0 | AE19: =IF(ISNUMBER(SEARCH("; genre/writing expertise; ","; "&H19&"; ")),1,0) -> 0 | AF19: =IF(ISNUMBER(SEARCH("; none; ","; "&H19&"; ")),1,0) -> 0
A20: P2-019 | B20: 19 | C20: Source selection and citation repair | D20: workflows I Do not like this term. do not use it in ANY of interactions with me. Insrtead, you can use: practices or processes | E20: Correction/Challenge | F20: Selection/Rejection; Directed delegation | G20: Critical | H20: genre/writing expertise | I20: Rejects a recurrent term and supplies preferred alternatives, asserting editorial control. | J20: AI acknowledges the wording preference. | K20: p12 L35-p12 L36 | L20: p12 L37-p12 L38 | N20: Visible substantive response | P20: =SUM(Paper2Coding[[#This Row],[Open Delegation]:[Expertise]]) -> 4 | Q20: =IF(OR(E20="Delegation",ISNUMBER(SEARCH("; Delegation; ","; "&F20&"; "))),1,0) -> 0 | R20: =IF(OR(E20="Directed delegation",ISNUMBER(SEARCH("; Directed delegation; ","; "&F20&"; "))),1,0) -> 1 | S20: =IF(OR(E20="Evaluation",ISNUMBER(SEARCH("; Evaluation; ","; "&F20&"; "))),1,0) -> 0 | T20: =IF(OR(E20="Correction/Challenge",ISNUMBER(SEARCH("; Correction/Challenge; ","; "&F20&"; "))),1,0) -> 1 | U20: =IF(OR(E20="Redirection",ISNUMBER(SEARCH("; Redirection; ","; "&F20&"; "))),1,0) -> 0 | V20: =IF(OR(E20="Knowledge injection",ISNUMBER(SEARCH("; Knowledge injection; ","; "&F20&"; "))),1,0) -> 0 | W20: =IF(OR(E20="Selection/Rejection",ISNUMBER(SEARCH("; Selection/Rejection; ","; "&F20&"; "))),1,0) -> 1 | X20: =IF(OR(E20="Deliberation",ISNUMBER(SEARCH("; Deliberation; ","; "&F20&"; "))),1,0) -> 0 | Y20: =SUM(Paper2Coding[[#This Row],[Subject-matter correction]:[none]]) -> 1 | Z20: =IF(ISNUMBER(SEARCH("; domain correction; ","; "&H20&"; ")),1,0) -> 0 | AA20: =IF(ISNUMBER(SEARCH("; conceptual discrimination; ","; "&H20&"; ")),1,0) -> 0 | AB20: =IF(ISNUMBER(SEARCH("; evidence judgment; ","; "&H20&"; ")),1,0) -> 0 | AC20: =IF(ISNUMBER(SEARCH("; methodological judgment; ","; "&H20&"; ")),1,0) -> 0 | AD20: =IF(ISNUMBER(SEARCH("; argumentative judgment; ","; "&H20&"; ")),1,0) -> 0 | AE20: =IF(ISNUMBER(SEARCH("; genre/writing expertise; ","; "&H20&"; ")),1,0) -> 1 | AF20: =IF(ISNUMBER(SEARCH("; none; ","; "&H20&"; ")),1,0) -> 0
A21: P2-020 | B21: 20 | C21: Abstract and paper positioning | D21: how about this title? Be aware of the Hidden Cost of using GenAI in Software Engineering: Efficiency or Burden . it's a bit long, can it be shortened? | E21: Evaluation | F21: Directed delegation; Knowledge injection | G21: Evaluative | H21: genre/writing expertise | I21: Proposes a title, identifies its length problem and requests shortening. | J21: AI gives shorter options without a recorded final choice. | K21: p12 L39-p12 L40 | L21: p12 L41-p13 L11 | N21: Visible substantive response | P21: =SUM(Paper2Coding[[#This Row],[Open Delegation]:[Expertise]]) -> 4 | Q21: =IF(OR(E21="Delegation",ISNUMBER(SEARCH("; Delegation; ","; "&F21&"; "))),1,0) -> 0 | R21: =IF(OR(E21="Directed delegation",ISNUMBER(SEARCH("; Directed delegation; ","; "&F21&"; "))),1,0) -> 1 | S21: =IF(OR(E21="Evaluation",ISNUMBER(SEARCH("; Evaluation; ","; "&F21&"; "))),1,0) -> 1 | T21: =IF(OR(E21="Correction/Challenge",ISNUMBER(SEARCH("; Correction/Challenge; ","; "&F21&"; "))),1,0) -> 0 | U21: =IF(OR(E21="Redirection",ISNUMBER(SEARCH("; Redirection; ","; "&F21&"; "))),1,0) -> 0 | V21: =IF(OR(E21="Knowledge injection",ISNUMBER(SEARCH("; Knowledge injection; ","; "&F21&"; "))),1,0) -> 1 | W21: =IF(OR(E21="Selection/Rejection",ISNUMBER(SEARCH("; Selection/Rejection; ","; "&F21&"; "))),1,0) -> 0 | X21: =IF(OR(E21="Deliberation",ISNUMBER(SEARCH("; Deliberation; ","; "&F21&"; "))),1,0) -> 0 | Y21: =SUM(Paper2Coding[[#This Row],[Subject-matter correction]:[none]]) -> 1 | Z21: =IF(ISNUMBER(SEARCH("; domain correction; ","; "&H21&"; ")),1,0) -> 0 | AA21: =IF(ISNUMBER(SEARCH("; conceptual discrimination; ","; "&H21&"; ")),1,0) -> 0 | AB21: =IF(ISNUMBER(SEARCH("; evidence judgment; ","; "&H21&"; ")),1,0) -> 0 | AC21: =IF(ISNUMBER(SEARCH("; methodological judgment; ","; "&H21&"; ")),1,0) -> 0 | AD21: =IF(ISNUMBER(SEARCH("; argumentative judgment; ","; "&H21&"; ")),1,0) -> 0 | AE21: =IF(ISNUMBER(SEARCH("; genre/writing expertise; ","; "&H21&"; ")),1,0) -> 1 | AF21: =IF(ISNUMBER(SEARCH("; none; ","; "&H21&"; ")),1,0) -> 0
A22: P2-021 | B22: 21 | C22: Abstract and paper positioning | D22: I slightly improved the abstract. proof read it: AI tools promise increased efficiency in software engineering (SE), yet their use can introduce hidden costs. Software engineers often need to review, validate, and correct AI-generated SE artifacts—efforts that may outweigh the... | E22: Directed delegation | F22: Knowledge injection | G22: Directive | H22: genre/writing expertise; argumentative judgment | I22: Supplies a revised abstract incorporating industrial experience and limits the task to proofreading. | J22: AI proofreads the abstract; no independent audit of the experience claim is visible. | K22: p13 L12-p13 L17 | L22: p13 L19-p13 L25 | N22: Visible substantive response | P22: =SUM(Paper2Coding[[#This Row],[Open Delegation]:[Expertise]]) -> 4 | Q22: =IF(OR(E22="Delegation",ISNUMBER(SEARCH("; Delegation; ","; "&F22&"; "))),1,0) -> 0 | R22: =IF(OR(E22="Directed delegation",ISNUMBER(SEARCH("; Directed delegation; ","; "&F22&"; "))),1,0) -> 1 | S22: =IF(OR(E22="Evaluation",ISNUMBER(SEARCH("; Evaluation; ","; "&F22&"; "))),1,0) -> 0 | T22: =IF(OR(E22="Correction/Challenge",ISNUMBER(SEARCH("; Correction/Challenge; ","; "&F22&"; "))),1,0) -> 0 | U22: =IF(OR(E22="Redirection",ISNUMBER(SEARCH("; Redirection; ","; "&F22&"; "))),1,0) -> 0 | V22: =IF(OR(E22="Knowledge injection",ISNUMBER(SEARCH("; Knowledge injection; ","; "&F22&"; "))),1,0) -> 1 | W22: =IF(OR(E22="Selection/Rejection",ISNUMBER(SEARCH("; Selection/Rejection; ","; "&F22&"; "))),1,0) -> 0 | X22: =IF(OR(E22="Deliberation",ISNUMBER(SEARCH("; Deliberation; ","; "&F22&"; "))),1,0) -> 0 | Y22: =SUM(Paper2Coding[[#This Row],[Subject-matter correction]:[none]]) -> 2 | Z22: =IF(ISNUMBER(SEARCH("; domain correction; ","; "&H22&"; ")),1,0) -> 0 | AA22: =IF(ISNUMBER(SEARCH("; conceptual discrimination; ","; "&H22&"; ")),1,0) -> 0 | AB22: =IF(ISNUMBER(SEARCH("; evidence judgment; ","; "&H22&"; ")),1,0) -> 0 | AC22: =IF(ISNUMBER(SEARCH("; methodological judgment; ","; "&H22&"; ")),1,0) -> 0 | AD22: =IF(ISNUMBER(SEARCH("; argumentative judgment; ","; "&H22&"; ")),1,0) -> 1 | AE22: =IF(ISNUMBER(SEARCH("; genre/writing expertise; ","; "&H22&"; ")),1,0) -> 1 | AF22: =IF(ISNUMBER(SEARCH("; none; ","; "&H22&"; ")),1,0) -> 0
A23: P2-022 | B23: 22 | C23: Abstract and paper positioning | D23: add that, to get productivity gains from AI in SE, it should be used in the right way, and other "right" factors | E23: Directed delegation | F23: Knowledge injection | G23: Directive | H23: argumentative judgment | I23: Adds the human's argument that productivity gains depend on appropriate AI use and other factors. | J23: AI adds engineering practice, human judgment and task-selection conditions. | K23: p13 L26-p13 L26 | L23: p13 L27-p13 L35 | N23: Visible substantive response | P23: =SUM(Paper2Coding[[#This Row],[Open Delegation]:[Expertise]]) -> 3 | Q23: =IF(OR(E23="Delegation",ISNUMBER(SEARCH("; Delegation; ","; "&F23&"; "))),1,0) -> 0 | R23: =IF(OR(E23="Directed delegation",ISNUMBER(SEARCH("; Directed delegation; ","; "&F23&"; "))),1,0) -> 1 | S23: =IF(OR(E23="Evaluation",ISNUMBER(SEARCH("; Evaluation; ","; "&F23&"; "))),1,0) -> 0 | T23: =IF(OR(E23="Correction/Challenge",ISNUMBER(SEARCH("; Correction/Challenge; ","; "&F23&"; "))),1,0) -> 0 | U23: =IF(OR(E23="Redirection",ISNUMBER(SEARCH("; Redirection; ","; "&F23&"; "))),1,0) -> 0 | V23: =IF(OR(E23="Knowledge injection",ISNUMBER(SEARCH("; Knowledge injection; ","; "&F23&"; "))),1,0) -> 1 | W23: =IF(OR(E23="Selection/Rejection",ISNUMBER(SEARCH("; Selection/Rejection; ","; "&F23&"; "))),1,0) -> 0 | X23: =IF(OR(E23="Deliberation",ISNUMBER(SEARCH("; Deliberation; ","; "&F23&"; "))),1,0) -> 0 | Y23: =SUM(Paper2Coding[[#This Row],[Subject-matter correction]:[none]]) -> 1 | Z23: =IF(ISNUMBER(SEARCH("; domain correction; ","; "&H23&"; ")),1,0) -> 0 | AA23: =IF(ISNUMBER(SEARCH("; conceptual discrimination; ","; "&H23&"; ")),1,0) -> 0 | AB23: =IF(ISNUMBER(SEARCH("; evidence judgment; ","; "&H23&"; ")),1,0) -> 0 | AC23: =IF(ISNUMBER(SEARCH("; methodological judgment; ","; "&H23&"; ")),1,0) -> 0 | AD23: =IF(ISNUMBER(SEARCH("; argumentative judgment; ","; "&H23&"; ")),1,0) -> 1 | AE23: =IF(ISNUMBER(SEARCH("; genre/writing expertise; ","; "&H23&"; ")),1,0) -> 0 | AF23: =IF(ISNUMBER(SEARCH("; none; ","; "&H23&"; ")),1,0) -> 0
A24: P2-023 | B24: 23 | C24: Abstract and paper positioning | D24: —guided by sound engineering practices, critical human judgment, and appropriate task selection good, but it is hard to read, sepaarate that sentence. also further disucss " appropriate task selection". I also like you use "right" as the adjective multiple time for those aspects | E24: Correction/Challenge | F24: Directed delegation; Selection/Rejection | G24: Critical | H24: genre/writing expertise; argumentative judgment | I24: Partly approves the idea but diagnoses poor readability, directs sentence separation and preferred wording, and requests elaboration. | J24: AI rewrites and expands task selection using the requested repeated adjective. | K24: p13 L36-p13 L38 | L24: p13 L39-p14 L10 | N24: Visible substantive response | P24: =SUM(Paper2Coding[[#This Row],[Open Delegation]:[Expertise]]) -> 5 | Q24: =IF(OR(E24="Delegation",ISNUMBER(SEARCH("; Delegation; ","; "&F24&"; "))),1,0) -> 0 | R24: =IF(OR(E24="Directed delegation",ISNUMBER(SEARCH("; Directed delegation; ","; "&F24&"; "))),1,0) -> 1 | S24: =IF(OR(E24="Evaluation",ISNUMBER(SEARCH("; Evaluation; ","; "&F24&"; "))),1,0) -> 0 | T24: =IF(OR(E24="Correction/Challenge",ISNUMBER(SEARCH("; Correction/Challenge; ","; "&F24&"; "))),1,0) -> 1 | U24: =IF(OR(E24="Redirection",ISNUMBER(SEARCH("; Redirection; ","; "&F24&"; "))),1,0) -> 0 | V24: =IF(OR(E24="Knowledge injection",ISNUMBER(SEARCH("; Knowledge injection; ","; "&F24&"; "))),1,0) -> 0 | W24: =IF(OR(E24="Selection/Rejection",ISNUMBER(SEARCH("; Selection/Rejection; ","; "&F24&"; "))),1,0) -> 1 | X24: =IF(OR(E24="Deliberation",ISNUMBER(SEARCH("; Deliberation; ","; "&F24&"; "))),1,0) -> 0 | Y24: =SUM(Paper2Coding[[#This Row],[Subject-matter correction]:[none]]) -> 2 | Z24: =IF(ISNUMBER(SEARCH("; domain correction; ","; "&H24&"; ")),1,0) -> 0 | AA24: =IF(ISNUMBER(SEARCH("; conceptual discrimination; ","; "&H24&"; ")),1,0) -> 0 | AB24: =IF(ISNUMBER(SEARCH("; evidence judgment; ","; "&H24&"; ")),1,0) -> 0 | AC24: =IF(ISNUMBER(SEARCH("; methodological judgment; ","; "&H24&"; ")),1,0) -> 0 | AD24: =IF(ISNUMBER(SEARCH("; argumentative judgment; ","; "&H24&"; ")),1,0) -> 1 | AE24: =IF(ISNUMBER(SEARCH("; genre/writing expertise; ","; "&H24&"; ")),1,0) -> 1 | AF24: =IF(ISNUMBER(SEARCH("; none; ","; "&H24&"; ")),1,0) -> 0
A25: P2-024 | B25: 24 | C25: Abstract and paper positioning | D25: yes | E25: Selection/Rejection | G25: Directive | H25: none | I25: Accepts the immediately preceding offer of an under-200-word abstract. Terse acceptance adds no independent expertise evidence. | J25: AI supplies a shorter abstract and reports 149 words. | K25: p14 L11-p14 L11 | L25: p14 L12-p14 L23 | N25: Visible substantive response | O25: Assent resolved from immediately preceding offer; not blanket approval | P25: =SUM(Paper2Coding[[#This Row],[Open Delegation]:[Expertise]]) -> 2 | Q25: =IF(OR(E25="Delegation",ISNUMBER(SEARCH("; Delegation; ","; "&F25&"; "))),1,0) -> 0 | R25: =IF(OR(E25="Directed delegation",ISNUMBER(SEARCH("; Directed delegation; ","; "&F25&"; "))),1,0) -> 0 | S25: =IF(OR(E25="Evaluation",ISNUMBER(SEARCH("; Evaluation; ","; "&F25&"; "))),1,0) -> 0 | T25: =IF(OR(E25="Correction/Challenge",ISNUMBER(SEARCH("; Correction/Challenge; ","; "&F25&"; "))),1,0) -> 0 | U25: =IF(OR(E25="Redirection",ISNUMBER(SEARCH("; Redirection; ","; "&F25&"; "))),1,0) -> 0 | V25: =IF(OR(E25="Knowledge injection",ISNUMBER(SEARCH("; Knowledge injection; ","; "&F25&"; "))),1,0) -> 0 | W25: =IF(OR(E25="Selection/Rejection",ISNUMBER(SEARCH("; Selection/Rejection; ","; "&F25&"; "))),1,0) -> 1 | X25: =IF(OR(E25="Deliberation",ISNUMBER(SEARCH("; Deliberation; ","; "&F25&"; "))),1,0) -> 0 | Y25: =SUM(Paper2Coding[[#This Row],[Subject-matter correction]:[none]]) -> 1 | Z25: =IF(ISNUMBER(SEARCH("; domain correction; ","; "&H25&"; ")),1,0) -> 0 | AA25: =IF(ISNUMBER(SEARCH("; conceptual discrimination; ","; "&H25&"; ")),1,0) -> 0 | AB25: =IF(ISNUMBER(SEARCH("; evidence judgment; ","; "&H25&"; ")),1,0) -> 0 | AC25: =IF(ISNUMBER(SEARCH("; methodological judgment; ","; "&H25&"; ")),1,0) -> 0 | AD25: =IF(ISNUMBER(SEARCH("; argumentative judgment; ","; "&H25&"; ")),1,0) -> 0 | AE25: =IF(ISNUMBER(SEARCH("; genre/writing expertise; ","; "&H25&"; ")),1,0) -> 0 | AF25: =IF(ISNUMBER(SEARCH("; none; ","; "&H25&"; ")),1,0) -> 1
