Workbook

Sheet Summary
A2: Diagnosing quality of higher education
A3: Human–AI interaction coding • single first-pass analysis • counts reflect category presence
A5: Human prompts | B5: 119 | D5: Count revised: 122 → 119 after joining continuation fragments.
A6: No next AI response | B6: 1 | D6: Expertise “none” = no explicit evidence in that prompt.
A8: Interaction type | B8: Primary count | C8: Any occurrence | D8: Share of prompts | F8: Agency mode | G8: Prompts | H8: Share | J8: Expertise evidence | K8: Prompts | L8: Share
A9: Open Delegation | B9: =COUNTIFS(Coding!$E$2:$E$120,A9) -> 0 | C9: =SUM(Coding!Q2:Q120) -> 2 | D9: =C9/$B$5 -> 0.016806723 | F9: Delegative | G9: =COUNTIFS(Coding!$G$2:$G$120,F9) -> 2 | H9: =G9/$B$5 -> 0.016806723 | J9: domain correction | K9: =SUM(Coding!Z2:Z120) -> 10 | L9: =K9/$B$5 -> 0.084033613
A10: Directed delegation | B10: =COUNTIFS(Coding!$E$2:$E$120,A10) -> 40 | C10: =SUM(Coding!R2:R120) -> 81 | D10: =C10/$B$5 -> 0.68067227 | F10: Directive | G10: =COUNTIFS(Coding!$G$2:$G$120,F10) -> 69 | H10: =G10/$B$5 -> 0.57983193 | J10: conceptual discrimination | K10: =SUM(Coding!AA2:AA120) -> 28 | L10: =K10/$B$5 -> 0.23529412
A11: Evaluation | B11: =COUNTIFS(Coding!$E$2:$E$120,A11) -> 17 | C11: =SUM(Coding!S2:S120) -> 23 | D11: =C11/$B$5 -> 0.19327731 | F11: Evaluative | G11: =COUNTIFS(Coding!$G$2:$G$120,F11) -> 18 | H11: =G11/$B$5 -> 0.1512605 | J11: evidence judgment | K11: =SUM(Coding!AB2:AB120) -> 29 | L11: =K11/$B$5 -> 0.24369748
A12: Correction/Challenge | B12: =COUNTIFS(Coding!$E$2:$E$120,A12) -> 26 | C12: =SUM(Coding!T2:T120) -> 27 | D12: =C12/$B$5 -> 0.22689076 | F12: Critical | G12: =COUNTIFS(Coding!$G$2:$G$120,F12) -> 26 | H12: =G12/$B$5 -> 0.21848739 | J12: methodological judgment | K12: =SUM(Coding!AC2:AC120) -> 23 | L12: =K12/$B$5 -> 0.19327731
A13: Redirection | B13: =COUNTIFS(Coding!$E$2:$E$120,A13) -> 10 | C13: =SUM(Coding!U2:U120) -> 26 | D13: =C13/$B$5 -> 0.21848739 | F13: Deliberative | G13: =COUNTIFS(Coding!$G$2:$G$120,F13) -> 4 | H13: =G13/$B$5 -> 0.033613445 | J13: argumentative judgment | K13: =SUM(Coding!AD2:AD120) -> 32 | L13: =K13/$B$5 -> 0.26890756
A14: Knowledge/context provision | B14: =COUNTIFS(Coding!$E$2:$E$120,A14) -> 0 | C14: =SUM(Coding!V2:V120) -> 62 | D14: =C14/$B$5 -> 0.5210084 | J14: genre/writing expertise | K14: =SUM(Coding!AE2:AE120) -> 66 | L14: =K14/$B$5 -> 0.55462185
A15: Selection/Rejection | B15: =COUNTIFS(Coding!$E$2:$E$120,A15) -> 2 | C15: =SUM(Coding!W2:W120) -> 2 | D15: =C15/$B$5 -> 0.016806723 | F15: Positive expertise evidence | G15: =$B$5-SUM(Coding!AF2:AF120) -> 105 | J15: none | K15: =SUM(Coding!AF2:AF120) -> 14 | L15: =K15/$B$5 -> 0.11764706
A16: Deliberation | B16: =COUNTIFS(Coding!$E$2:$E$120,A16) -> 4 | C16: =SUM(Coding!X2:X120) -> 4 | D16: =C16/$B$5 -> 0.033613445 | F16: Share with evidence | G16: =G15/$B$5 -> 0.88235294
A19: Phase | B19: First prompt | C19: Last prompt | D19: Prompts | E19: Delegative | F19: Directive | G19: Evaluative | H19: Critical | I19: Deliberative
A20: Conceptual framing and model | B20: 1 | C20: 25 | D20: =COUNTIFS(Coding!$C$2:$C$120,A20) -> 25 | E20: =COUNTIFS(Coding!$C$2:$C$120,$A20,Coding!$G$2:$G$120,"Delegative") -> 1 | F20: =COUNTIFS(Coding!$C$2:$C$120,$A20,Coding!$G$2:$G$120,"Directive") -> 15 | G20: =COUNTIFS(Coding!$C$2:$C$120,$A20,Coding!$G$2:$G$120,"Evaluative") -> 5 | H20: =COUNTIFS(Coding!$C$2:$C$120,$A20,Coding!$G$2:$G$120,"Critical") -> 4 | I20: =COUNTIFS(Coding!$C$2:$C$120,$A20,Coding!$G$2:$G$120,"Deliberative") -> 0
A21: Structure and research design | B21: 26 | C21: 45 | D21: =COUNTIFS(Coding!$C$2:$C$120,A21) -> 20 | E21: =COUNTIFS(Coding!$C$2:$C$120,$A21,Coding!$G$2:$G$120,"Delegative") -> 1 | F21: =COUNTIFS(Coding!$C$2:$C$120,$A21,Coding!$G$2:$G$120,"Directive") -> 13 | G21: =COUNTIFS(Coding!$C$2:$C$120,$A21,Coding!$G$2:$G$120,"Evaluative") -> 1 | H21: =COUNTIFS(Coding!$C$2:$C$120,$A21,Coding!$G$2:$G$120,"Critical") -> 5 | I21: =COUNTIFS(Coding!$C$2:$C$120,$A21,Coding!$G$2:$G$120,"Deliberative") -> 0
A22: Diagnosis, model and reforms | B22: 46 | C22: 82 | D22: =COUNTIFS(Coding!$C$2:$C$120,A22) -> 37 | E22: =COUNTIFS(Coding!$C$2:$C$120,$A22,Coding!$G$2:$G$120,"Delegative") -> 0 | F22: =COUNTIFS(Coding!$C$2:$C$120,$A22,Coding!$G$2:$G$120,"Directive") -> 20 | G22: =COUNTIFS(Coding!$C$2:$C$120,$A22,Coding!$G$2:$G$120,"Evaluative") -> 7 | H22: =COUNTIFS(Coding!$C$2:$C$120,$A22,Coding!$G$2:$G$120,"Critical") -> 9 | I22: =COUNTIFS(Coding!$C$2:$C$120,$A22,Coding!$G$2:$G$120,"Deliberative") -> 1
A23: Review and submission preparation | B23: 83 | C23: 117 | D23: =COUNTIFS(Coding!$C$2:$C$120,A23) -> 35 | E23: =COUNTIFS(Coding!$C$2:$C$120,$A23,Coding!$G$2:$G$120,"Delegative") -> 0 | F23: =COUNTIFS(Coding!$C$2:$C$120,$A23,Coding!$G$2:$G$120,"Directive") -> 20 | G23: =COUNTIFS(Coding!$C$2:$C$120,$A23,Coding!$G$2:$G$120,"Evaluative") -> 5 | H23: =COUNTIFS(Coding!$C$2:$C$120,$A23,Coding!$G$2:$G$120,"Critical") -> 7 | I23: =COUNTIFS(Coding!$C$2:$C$120,$A23,Coding!$G$2:$G$120,"Deliberative") -> 3
A24: Follow-on paper planning | B24: 118 | C24: 119 | D24: =COUNTIFS(Coding!$C$2:$C$120,A24) -> 2 | E24: =COUNTIFS(Coding!$C$2:$C$120,$A24,Coding!$G$2:$G$120,"Delegative") -> 0 | F24: =COUNTIFS(Coding!$C$2:$C$120,$A24,Coding!$G$2:$G$120,"Directive") -> 1 | G24: =COUNTIFS(Coding!$C$2:$C$120,$A24,Coding!$G$2:$G$120,"Evaluative") -> 0 | H24: =COUNTIFS(Coding!$C$2:$C$120,$A24,Coding!$G$2:$G$120,"Critical") -> 1 | I24: =COUNTIFS(Coding!$C$2:$C$120,$A24,Coding!$G$2:$G$120,"Deliberative") -> 0
A28: Key coding patterns and limits
A29: Directed delegation occurs in 81/119 prompts (68.1%); knowledge injection in 62 (52.1%). The researcher frequently supplies the substance and constrains AI drafting.
A30: Critical agency occurs in 26 prompts (21.8%). Challenges cover causal-loop terminology (25,119), study scope (29), survey omission (40), report relevance (103–107) and wording.
A31: Positive expertise evidence is coded in 105/119 prompts (88.2%); genre/writing in 66, argumentative judgment in 32, conceptual discrimination in 28, evidence judgment in 29.
A32: The model develops through researcher-supplied categories, arrows and mechanisms (5,10,24–25,60,66,93,116). Technical corrections recur alongside manuscript editing.
A33: Evidence control appears in source chronology (48–50), survey design/findings (32,40–42,53), and challenges to older or irrelevant reports (99–104,112).
A34: Two prompts after reported submission (118–119) develop a generic model paper. They are retained but separately labelled for manuscript-only comparisons.
A35: The converted Word export needs careful boundary interpretation. These 119 text-bearing prompts do not establish completeness of the original chat.

Sheet Coding
A1: Prompt ID | B1: Sequence | C1: Phase | D1: Prompt excerpt | E1: Primary interaction type | F1: Additional interaction types | G1: Agency mode | H1: Expertise evidence | I1: Coding rationale | J1: Observed outcome / notes | K1: Prompt provenance | L1: Response provenance | M1: Attachment / contextual material | N1: Response availability | O1: Coding caution | P1: Interaction codes | Q1: Type: Delegation | R1: Type: Directed delegation | S1: Type: Evaluation | T1: Type: Correction/Challenge | U1: Type: Redirection | V1: Type: Knowledge injection | W1: Type: Selection/Rejection | X1: Type: Deliberation | Y1: Expertise codes | Z1: Expertise: domain correction | AA1: Expertise: conceptual discrimination | AB1: Expertise: evidence judgment | AC1: Expertise: methodological judgment | AD1: Expertise: argumentative judgment | AE1: Expertise: genre/writing expertise | AF1: Expertise: none
A2: HE-001 | B2: 1 | C2: Conceptual framing and model | D2: paper idea: Azərbaycanımızın Təhsil Sisteminin Sistemli İslahat və İnkişafı üçün Birinci Addım: Sistemin Praqmatik və Diaqnostik Analizi a "macro"-systems analysis (country level) ---------------- -use insights from https://en.wikipedia.org/wiki/Education_in_Azerbaijan when releavant in my paperlook here https://projects.worldbank.org/en/projects-operations/project-detail/P102117 it was a major project called "Second… | E2: Directed delegation | F2: Knowledge injection; Evaluation | G2: Directive | H2: methodological judgment; evidence judgment; argumentative judgment | I2: Frames a macro diagnostic study, supplies report findings and requests checking the model/materials. | J2: AI proposes a systems analysis and interprets supplied reports; access and evidence claims remain unverified. | K2: DOCX body elements 7–15 | L2: DOCX body elements 18–212 | M2: URL(s) supplied in prompt; File/context references in prompt; inspect full text; Extended draft/quoted context; researcher-origin judgment distinguished in rationale | N2: Visible next AI response | O2: Converted DOCX: textbox continuations joined; AI completion/source-check claims are unverified. | P2: =SUM(Q2:X2) -> 3 | Q2: =IF(OR(E2="Delegation",ISNUMBER(SEARCH("; Delegation; ","; "&F2&"; "))),1,0) -> 0 | R2: =IF(OR(E2="Directed delegation",ISNUMBER(SEARCH("; Directed delegation; ","; "&F2&"; "))),1,0) -> 1 | S2: =IF(OR(E2="Evaluation",ISNUMBER(SEARCH("; Evaluation; ","; "&F2&"; "))),1,0) -> 1 | T2: =IF(OR(E2="Correction/Challenge",ISNUMBER(SEARCH("; Correction/Challenge; ","; "&F2&"; "))),1,0) -> 0 | U2: =IF(OR(E2="Redirection",ISNUMBER(SEARCH("; Redirection; ","; "&F2&"; "))),1,0) -> 0 | V2: =IF(OR(E2="Knowledge injection",ISNUMBER(SEARCH("; Knowledge injection; ","; "&F2&"; "))),1,0) -> 1 | W2: =IF(OR(E2="Selection/Rejection",ISNUMBER(SEARCH("; Selection/Rejection; ","; "&F2&"; "))),1,0) -> 0 | X2: =IF(OR(E2="Deliberation",ISNUMBER(SEARCH("; Deliberation; ","; "&F2&"; "))),1,0) -> 0 | Y2: =SUM(Z2:AE2) -> 3 | Z2: =IF(ISNUMBER(SEARCH("; domain correction; ","; "&H2&"; ")),1,0) -> 0 | AA2: =IF(ISNUMBER(SEARCH("; conceptual discrimination; ","; "&H2&"; ")),1,0) -> 0 | AB2: =IF(ISNUMBER(SEARCH("; evidence judgment; ","; "&H2&"; ")),1,0) -> 1 | AC2: =IF(ISNUMBER(SEARCH("; methodological judgment; ","; "&H2&"; ")),1,0) -> 1 | AD2: =IF(ISNUMBER(SEARCH("; argumentative judgment; ","; "&H2&"; ")),1,0) -> 1 | AE2: =IF(ISNUMBER(SEARCH("; genre/writing expertise; ","; "&H2&"; ")),1,0) -> 0 | AF2: =IF(ISNUMBER(SEARCH("; none; ","; "&H2&"; ")),1,0) -> 0
A3: HE-002 | B3: 2 | C3: Conceptual framing and model | D3: max paper legnth is 8000. target: https://www.as-journal.edu.az/instruction_az ... also, I still prefer my title: Azərbaycanımızın Təhsil Sisteminin Sistemli İslahat və İnkişafı üçün Birinci Addım: Sistemin Praqmatik və Diaqnostik Analizi --- since I need to keep the title soft (not too critical, or they will not like it, it can upset many people in AZ!) | E3: Directed delegation | F3: Redirection; Knowledge injection | G3: Directive | H3: genre/writing expertise; argumentative judgment | I3: Sets length and audience constraints and moderates a potentially confrontational title. | J3: AI proposes softer titles and a paper structure. | K3: DOCX body elements 213–213 | L3: DOCX body elements 216–717 | M3: URL(s) supplied in prompt | N3: Visible next AI response | O3: Converted DOCX: textbox continuations joined; AI completion/source-check claims are unverified. | P3: =SUM(Q3:X3) -> 3 | Q3: =IF(OR(E3="Delegation",ISNUMBER(SEARCH("; Delegation; ","; "&F3&"; "))),1,0) -> 0 | R3: =IF(OR(E3="Directed delegation",ISNUMBER(SEARCH("; Directed delegation; ","; "&F3&"; "))),1,0) -> 1 | S3: =IF(OR(E3="Evaluation",ISNUMBER(SEARCH("; Evaluation; ","; "&F3&"; "))),1,0) -> 0 | T3: =IF(OR(E3="Correction/Challenge",ISNUMBER(SEARCH("; Correction/Challenge; ","; "&F3&"; "))),1,0) -> 0 | U3: =IF(OR(E3="Redirection",ISNUMBER(SEARCH("; Redirection; ","; "&F3&"; "))),1,0) -> 1 | V3: =IF(OR(E3="Knowledge injection",ISNUMBER(SEARCH("; Knowledge injection; ","; "&F3&"; "))),1,0) -> 1 | W3: =IF(OR(E3="Selection/Rejection",ISNUMBER(SEARCH("; Selection/Rejection; ","; "&F3&"; "))),1,0) -> 0 | X3: =IF(OR(E3="Deliberation",ISNUMBER(SEARCH("; Deliberation; ","; "&F3&"; "))),1,0) -> 0 | Y3: =SUM(Z3:AE3) -> 2 | Z3: =IF(ISNUMBER(SEARCH("; domain correction; ","; "&H3&"; ")),1,0) -> 0 | AA3: =IF(ISNUMBER(SEARCH("; conceptual discrimination; ","; "&H3&"; ")),1,0) -> 0 | AB3: =IF(ISNUMBER(SEARCH("; evidence judgment; ","; "&H3&"; ")),1,0) -> 0 | AC3: =IF(ISNUMBER(SEARCH("; methodological judgment; ","; "&H3&"; ")),1,0) -> 0 | AD3: =IF(ISNUMBER(SEARCH("; argumentative judgment; ","; "&H3&"; ")),1,0) -> 1 | AE3: =IF(ISNUMBER(SEARCH("; genre/writing expertise; ","; "&H3&"; ")),1,0) -> 1 | AF3: =IF(ISNUMBER(SEARCH("; none; ","; "&H3&"; ")),1,0) -> 0
A4: HE-003 | B4: 3 | C4: Conceptual framing and model | D4: I also put the longer file pdf in the folder : "Implementation Completion and Results Report" .... read it . lots of it is about the financial transactions, of course. Ignore them completely, but some of its discussions are about the, you know, performance and technical performance. Okay. Non financials. So, yeah, use those ideas as well. By the way, you have too many sections and subsections. You need to reduce them… | E4: Directed delegation | F4: Knowledge injection; Redirection; Correction/Challenge | G4: Directive | H4: evidence judgment; genre/writing expertise | I4: Adds a report and directs nonfinancial emphasis and fewer headings. | J4: AI begins a revised plan; response is interrupted in the record. | K4: DOCX body elements 718–718 | L4: DOCX body elements 722–726 | N4: Visible next AI response | O4: Converted DOCX: textbox continuations joined; AI completion/source-check claims are unverified. | P4: =SUM(Q4:X4) -> 4 | Q4: =IF(OR(E4="Delegation",ISNUMBER(SEARCH("; Delegation; ","; "&F4&"; "))),1,0) -> 0 | R4: =IF(OR(E4="Directed delegation",ISNUMBER(SEARCH("; Directed delegation; ","; "&F4&"; "))),1,0) -> 1 | S4: =IF(OR(E4="Evaluation",ISNUMBER(SEARCH("; Evaluation; ","; "&F4&"; "))),1,0) -> 0 | T4: =IF(OR(E4="Correction/Challenge",ISNUMBER(SEARCH("; Correction/Challenge; ","; "&F4&"; "))),1,0) -> 1 | U4: =IF(OR(E4="Redirection",ISNUMBER(SEARCH("; Redirection; ","; "&F4&"; "))),1,0) -> 1 | V4: =IF(OR(E4="Knowledge injection",ISNUMBER(SEARCH("; Knowledge injection; ","; "&F4&"; "))),1,0) -> 1 | W4: =IF(OR(E4="Selection/Rejection",ISNUMBER(SEARCH("; Selection/Rejection; ","; "&F4&"; "))),1,0) -> 0 | X4: =IF(OR(E4="Deliberation",ISNUMBER(SEARCH("; Deliberation; ","; "&F4&"; "))),1,0) -> 0 | Y4: =SUM(Z4:AE4) -> 2 | Z4: =IF(ISNUMBER(SEARCH("; domain correction; ","; "&H4&"; ")),1,0) -> 0 | AA4: =IF(ISNUMBER(SEARCH("; conceptual discrimination; ","; "&H4&"; ")),1,0) -> 0 | AB4: =IF(ISNUMBER(SEARCH("; evidence judgment; ","; "&H4&"; ")),1,0) -> 1 | AC4: =IF(ISNUMBER(SEARCH("; methodological judgment; ","; "&H4&"; ")),1,0) -> 0 | AD4: =IF(ISNUMBER(SEARCH("; argumentative judgment; ","; "&H4&"; ")),1,0) -> 0 | AE4: =IF(ISNUMBER(SEARCH("; genre/writing expertise; ","; "&H4&"; ")),1,0) -> 1 | AF4: =IF(ISNUMBER(SEARCH("; none; ","; "&H4&"; ")),1,0) -> 0
A5: HE-004 | B5: 4 | C5: Conceptual framing and model | D5: Don't focus too much on that World Bank thing because I gave you several other data points. So I don't want one of them come across as the main one. The other one, um, I think, yeah, the PISA. So PISA and that world thing, uh, should be two main things. I also put the longer file pdf in the folder : "Implementation Completion and Results Report" read it . lots of it is about thefinancial transactions, of course. Igno… | E5: Redirection | F5: Directed delegation; Knowledge injection | G5: Directive | H5: evidence judgment; argumentative judgment; genre/writing expertise | I5: Rebalances the evidence sources and repeats structural constraints. | J5: AI revises emphasis and structure. | K5: DOCX body elements 728–728 | L5: DOCX body elements 731–999 | N5: Visible next AI response | O5: Converted DOCX: textbox continuations joined; AI completion/source-check claims are unverified. | P5: =SUM(Q5:X5) -> 3 | Q5: =IF(OR(E5="Delegation",ISNUMBER(SEARCH("; Delegation; ","; "&F5&"; "))),1,0) -> 0 | R5: =IF(OR(E5="Directed delegation",ISNUMBER(SEARCH("; Directed delegation; ","; "&F5&"; "))),1,0) -> 1 | S5: =IF(OR(E5="Evaluation",ISNUMBER(SEARCH("; Evaluation; ","; "&F5&"; "))),1,0) -> 0 | T5: =IF(OR(E5="Correction/Challenge",ISNUMBER(SEARCH("; Correction/Challenge; ","; "&F5&"; "))),1,0) -> 0 | U5: =IF(OR(E5="Redirection",ISNUMBER(SEARCH("; Redirection; ","; "&F5&"; "))),1,0) -> 1 | V5: =IF(OR(E5="Knowledge injection",ISNUMBER(SEARCH("; Knowledge injection; ","; "&F5&"; "))),1,0) -> 1 | W5: =IF(OR(E5="Selection/Rejection",ISNUMBER(SEARCH("; Selection/Rejection; ","; "&F5&"; "))),1,0) -> 0 | X5: =IF(OR(E5="Deliberation",ISNUMBER(SEARCH("; Deliberation; ","; "&F5&"; "))),1,0) -> 0 | Y5: =SUM(Z5:AE5) -> 3 | Z5: =IF(ISNUMBER(SEARCH("; domain correction; ","; "&H5&"; ")),1,0) -> 0 | AA5: =IF(ISNUMBER(SEARCH("; conceptual discrimination; ","; "&H5&"; ")),1,0) -> 0 | AB5: =IF(ISNUMBER(SEARCH("; evidence judgment; ","; "&H5&"; ")),1,0) -> 1 | AC5: =IF(ISNUMBER(SEARCH("; methodological judgment; ","; "&H5&"; ")),1,0) -> 0 | AD5: =IF(ISNUMBER(SEARCH("; argumentative judgment; ","; "&H5&"; ")),1,0) -> 1 | AE5: =IF(ISNUMBER(SEARCH("; genre/writing expertise; ","; "&H5&"; ")),1,0) -> 1 | AF5: =IF(ISNUMBER(SEARCH("; none; ","; "&H5&"; ")),1,0) -> 0
A6: HE-005 | B6: 5 | C6: Conceptual framing and model | D6: I want this paper design. different than yours: 2-related work 3-Diaqnostik and weakness analysis PISA results , and the worldbank project: "Second Education Sector Development Project for Azerbaijan" do not include ANY finacial data / budget discussions 4-Causal loop diagram (Systems model): focus on higer ed, AZ universities factors: motivation of lecturers (muellimler), intrinsic motivation , extrinsic motivation … | E6: Knowledge injection | F6: Directed delegation; Redirection | G6: Directive | H6: methodological judgment; argumentative judgment | I6: Supplies the proposed paper structure and causal model actors. | J6: AI develops the structure around the researcher’s model. | K6: DOCX body elements 1000–1000 | L6: DOCX body elements 1003–1144 | N6: Visible next AI response | O6: Converted DOCX: textbox continuations joined; AI completion/source-check claims are unverified. | P6: =SUM(Q6:X6) -> 3 | Q6: =IF(OR(E6="Delegation",ISNUMBER(SEARCH("; Delegation; ","; "&F6&"; "))),1,0) -> 0 | R6: =IF(OR(E6="Directed delegation",ISNUMBER(SEARCH("; Directed delegation; ","; "&F6&"; "))),1,0) -> 1 | S6: =IF(OR(E6="Evaluation",ISNUMBER(SEARCH("; Evaluation; ","; "&F6&"; "))),1,0) -> 0 | T6: =IF(OR(E6="Correction/Challenge",ISNUMBER(SEARCH("; Correction/Challenge; ","; "&F6&"; "))),1,0) -> 0 | U6: =IF(OR(E6="Redirection",ISNUMBER(SEARCH("; Redirection; ","; "&F6&"; "))),1,0) -> 1 | V6: =IF(OR(E6="Knowledge injection",ISNUMBER(SEARCH("; Knowledge injection; ","; "&F6&"; "))),1,0) -> 1 | W6: =IF(OR(E6="Selection/Rejection",ISNUMBER(SEARCH("; Selection/Rejection; ","; "&F6&"; "))),1,0) -> 0 | X6: =IF(OR(E6="Deliberation",ISNUMBER(SEARCH("; Deliberation; ","; "&F6&"; "))),1,0) -> 0 | Y6: =SUM(Z6:AE6) -> 2 | Z6: =IF(ISNUMBER(SEARCH("; domain correction; ","; "&H6&"; ")),1,0) -> 0 | AA6: =IF(ISNUMBER(SEARCH("; conceptual discrimination; ","; "&H6&"; ")),1,0) -> 0 | AB6: =IF(ISNUMBER(SEARCH("; evidence judgment; ","; "&H6&"; ")),1,0) -> 0 | AC6: =IF(ISNUMBER(SEARCH("; methodological judgment; ","; "&H6&"; ")),1,0) -> 1 | AD6: =IF(ISNUMBER(SEARCH("; argumentative judgment; ","; "&H6&"; ")),1,0) -> 1 | AE6: =IF(ISNUMBER(SEARCH("; genre/writing expertise; ","; "&H6&"; ")),1,0) -> 0 | AF6: =IF(ISNUMBER(SEARCH("; none; ","; "&H6&"; ")),1,0) -> 0
A7: HE-006 | B7: 6 | C7: Conceptual framing and model | D7: remove H1 and H2 labels use more solid azerbaijani writing include as : 1.1 Tədqiqatçının Mövqeliyi and credentials: 25 İl Qərb Universitetlerinde Təcrübəsi və Daxili-Xarici Perspektivi 26 il: Kanada, Türkiyə, Böyük Britaniya also I have been doing Kurikulumun Müasirləşdirilməsi of the AzTU İTT faculty , and capaity buiolding, coaching / mentoring of academic staff. "teaching the teachers". I also taught Fənn-"Akadem… | E7: Redirection | F7: Directed delegation; Knowledge injection | G7: Directive | H7: methodological judgment; genre/writing expertise | I7: Rejects hypothesis labels, specifies Azerbaijani prose and supplies positional experience. | J7: AI revises the outline and merges sections. | K7: DOCX body elements 1145–1145 | L7: DOCX body elements 1148–1440 | N7: Visible next AI response | O7: Converted DOCX: textbox continuations joined; AI completion/source-check claims are unverified. | P7: =SUM(Q7:X7) -> 3 | Q7: =IF(OR(E7="Delegation",ISNUMBER(SEARCH("; Delegation; ","; "&F7&"; "))),1,0) -> 0 | R7: =IF(OR(E7="Directed delegation",ISNUMBER(SEARCH("; Directed delegation; ","; "&F7&"; "))),1,0) -> 1 | S7: =IF(OR(E7="Evaluation",ISNUMBER(SEARCH("; Evaluation; ","; "&F7&"; "))),1,0) -> 0 | T7: =IF(OR(E7="Correction/Challenge",ISNUMBER(SEARCH("; Correction/Challenge; ","; "&F7&"; "))),1,0) -> 0 | U7: =IF(OR(E7="Redirection",ISNUMBER(SEARCH("; Redirection; ","; "&F7&"; "))),1,0) -> 1 | V7: =IF(OR(E7="Knowledge injection",ISNUMBER(SEARCH("; Knowledge injection; ","; "&F7&"; "))),1,0) -> 1 | W7: =IF(OR(E7="Selection/Rejection",ISNUMBER(SEARCH("; Selection/Rejection; ","; "&F7&"; "))),1,0) -> 0 | X7: =IF(OR(E7="Deliberation",ISNUMBER(SEARCH("; Deliberation; ","; "&F7&"; "))),1,0) -> 0 | Y7: =SUM(Z7:AE7) -> 2 | Z7: =IF(ISNUMBER(SEARCH("; domain correction; ","; "&H7&"; ")),1,0) -> 0 | AA7: =IF(ISNUMBER(SEARCH("; conceptual discrimination; ","; "&H7&"; ")),1,0) -> 0 | AB7: =IF(ISNUMBER(SEARCH("; evidence judgment; ","; "&H7&"; ")),1,0) -> 0 | AC7: =IF(ISNUMBER(SEARCH("; methodological judgment; ","; "&H7&"; ")),1,0) -> 1 | AD7: =IF(ISNUMBER(SEARCH("; argumentative judgment; ","; "&H7&"; ")),1,0) -> 0 | AE7: =IF(ISNUMBER(SEARCH("; genre/writing expertise; ","; "&H7&"; ")),1,0) -> 1 | AF7: =IF(ISNUMBER(SEARCH("; none; ","; "&H7&"; ")),1,0) -> 0
A8: HE-007 | B8: 7 | C8: Conceptual framing and model | D8: what u meant by: Fərqin Məzənnələrinin Məhdud Məzənnə Dəyişikliyi??? | E8: Correction/Challenge | G8: Critical | H8: genre/writing expertise | I8: Questions an apparently garbled Azerbaijani phrase. | J8: AI acknowledges a wording error and replaces it. | K8: DOCX body elements 1441–1441 | L8: DOCX body elements 1444–1452 | N8: Visible next AI response | O8: Converted DOCX: textbox continuations joined; AI completion/source-check claims are unverified. | P8: =SUM(Q8:X8) -> 1 | Q8: =IF(OR(E8="Delegation",ISNUMBER(SEARCH("; Delegation; ","; "&F8&"; "))),1,0) -> 0 | R8: =IF(OR(E8="Directed delegation",ISNUMBER(SEARCH("; Directed delegation; ","; "&F8&"; "))),1,0) -> 0 | S8: =IF(OR(E8="Evaluation",ISNUMBER(SEARCH("; Evaluation; ","; "&F8&"; "))),1,0) -> 0 | T8: =IF(OR(E8="Correction/Challenge",ISNUMBER(SEARCH("; Correction/Challenge; ","; "&F8&"; "))),1,0) -> 1 | U8: =IF(OR(E8="Redirection",ISNUMBER(SEARCH("; Redirection; ","; "&F8&"; "))),1,0) -> 0 | V8: =IF(OR(E8="Knowledge injection",ISNUMBER(SEARCH("; Knowledge injection; ","; "&F8&"; "))),1,0) -> 0 | W8: =IF(OR(E8="Selection/Rejection",ISNUMBER(SEARCH("; Selection/Rejection; ","; "&F8&"; "))),1,0) -> 0 | X8: =IF(OR(E8="Deliberation",ISNUMBER(SEARCH("; Deliberation; ","; "&F8&"; "))),1,0) -> 0 | Y8: =SUM(Z8:AE8) -> 1 | Z8: =IF(ISNUMBER(SEARCH("; domain correction; ","; "&H8&"; ")),1,0) -> 0 | AA8: =IF(ISNUMBER(SEARCH("; conceptual discrimination; ","; "&H8&"; ")),1,0) -> 0 | AB8: =IF(ISNUMBER(SEARCH("; evidence judgment; ","; "&H8&"; ")),1,0) -> 0 | AC8: =IF(ISNUMBER(SEARCH("; methodological judgment; ","; "&H8&"; ")),1,0) -> 0 | AD8: =IF(ISNUMBER(SEARCH("; argumentative judgment; ","; "&H8&"; ")),1,0) -> 0 | AE8: =IF(ISNUMBER(SEARCH("; genre/writing expertise; ","; "&H8&"; ")),1,0) -> 1 | AF8: =IF(ISNUMBER(SEARCH("; none; ","; "&H8&"; ")),1,0) -> 0
A9: HE-008 | B9: 8 | C9: Conceptual framing and model | D9: regenerate the full TOC | E9: Directed delegation | G9: Directive | H9: none | I9: Requests regeneration of the table of contents without adding a substantive criterion. | J9: AI supplies a revised contents list. | K9: DOCX body elements 1453–1453 | L9: DOCX body elements 1456–1704 | N9: Visible next AI response | O9: Converted DOCX: textbox continuations joined; AI completion/source-check claims are unverified. | P9: =SUM(Q9:X9) -> 1 | Q9: =IF(OR(E9="Delegation",ISNUMBER(SEARCH("; Delegation; ","; "&F9&"; "))),1,0) -> 0 | R9: =IF(OR(E9="Directed delegation",ISNUMBER(SEARCH("; Directed delegation; ","; "&F9&"; "))),1,0) -> 1 | S9: =IF(OR(E9="Evaluation",ISNUMBER(SEARCH("; Evaluation; ","; "&F9&"; "))),1,0) -> 0 | T9: =IF(OR(E9="Correction/Challenge",ISNUMBER(SEARCH("; Correction/Challenge; ","; "&F9&"; "))),1,0) -> 0 | U9: =IF(OR(E9="Redirection",ISNUMBER(SEARCH("; Redirection; ","; "&F9&"; "))),1,0) -> 0 | V9: =IF(OR(E9="Knowledge injection",ISNUMBER(SEARCH("; Knowledge injection; ","; "&F9&"; "))),1,0) -> 0 | W9: =IF(OR(E9="Selection/Rejection",ISNUMBER(SEARCH("; Selection/Rejection; ","; "&F9&"; "))),1,0) -> 0 | X9: =IF(OR(E9="Deliberation",ISNUMBER(SEARCH("; Deliberation; ","; "&F9&"; "))),1,0) -> 0 | Y9: =SUM(Z9:AE9) -> 0 | Z9: =IF(ISNUMBER(SEARCH("; domain correction; ","; "&H9&"; ")),1,0) -> 0 | AA9: =IF(ISNUMBER(SEARCH("; conceptual discrimination; ","; "&H9&"; ")),1,0) -> 0 | AB9: =IF(ISNUMBER(SEARCH("; evidence judgment; ","; "&H9&"; ")),1,0) -> 0 | AC9: =IF(ISNUMBER(SEARCH("; methodological judgment; ","; "&H9&"; ")),1,0) -> 0 | AD9: =IF(ISNUMBER(SEARCH("; argumentative judgment; ","; "&H9&"; ")),1,0) -> 0 | AE9: =IF(ISNUMBER(SEARCH("; genre/writing expertise; ","; "&H9&"; ")),1,0) -> 0 | AF9: =IF(ISNUMBER(SEARCH("; none; ","; "&H9&"; ")),1,0) -> 1
A10: HE-009 | B10: 9 | C10: Conceptual framing and model | D10: proof heading : 3.2 Dünya Bankı terefinden Azərbaycanin Təhsil Sektorunun İnkişafı maliyelesdirieln Layihəsi (2008-2016) | E10: Directed delegation | F10: Knowledge injection | G10: Directive | H10: none | I10: Supplies a heading for proofreading without explaining a substantive judgment. | J10: AI edits the heading. | K10: DOCX body elements 1705–1705 | L10: DOCX body elements 1708–1719 | N10: Visible next AI response | O10: Converted DOCX: textbox continuations joined; AI completion/source-check claims are unverified. | P10: =SUM(Q10:X10) -> 2 | Q10: =IF(OR(E10="Delegation",ISNUMBER(SEARCH("; Delegation; ","; "&F10&"; "))),1,0) -> 0 | R10: =IF(OR(E10="Directed delegation",ISNUMBER(SEARCH("; Directed delegation; ","; "&F10&"; "))),1,0) -> 1 | S10: =IF(OR(E10="Evaluation",ISNUMBER(SEARCH("; Evaluation; ","; "&F10&"; "))),1,0) -> 0 | T10: =IF(OR(E10="Correction/Challenge",ISNUMBER(SEARCH("; Correction/Challenge; ","; "&F10&"; "))),1,0) -> 0 | U10: =IF(OR(E10="Redirection",ISNUMBER(SEARCH("; Redirection; ","; "&F10&"; "))),1,0) -> 0 | V10: =IF(OR(E10="Knowledge injection",ISNUMBER(SEARCH("; Knowledge injection; ","; "&F10&"; "))),1,0) -> 1 | W10: =IF(OR(E10="Selection/Rejection",ISNUMBER(SEARCH("; Selection/Rejection; ","; "&F10&"; "))),1,0) -> 0 | X10: =IF(OR(E10="Deliberation",ISNUMBER(SEARCH("; Deliberation; ","; "&F10&"; "))),1,0) -> 0 | Y10: =SUM(Z10:AE10) -> 0 | Z10: =IF(ISNUMBER(SEARCH("; domain correction; ","; "&H10&"; ")),1,0) -> 0 | AA10: =IF(ISNUMBER(SEARCH("; conceptual discrimination; ","; "&H10&"; ")),1,0) -> 0 | AB10: =IF(ISNUMBER(SEARCH("; evidence judgment; ","; "&H10&"; ")),1,0) -> 0 | AC10: =IF(ISNUMBER(SEARCH("; methodological judgment; ","; "&H10&"; ")),1,0) -> 0 | AD10: =IF(ISNUMBER(SEARCH("; argumentative judgment; ","; "&H10&"; ")),1,0) -> 0 | AE10: =IF(ISNUMBER(SEARCH("; genre/writing expertise; ","; "&H10&"; ")),1,0) -> 0 | AF10: =IF(ISNUMBER(SEARCH("; none; ","; "&H10&"; ")),1,0) -> 1
A11: HE-010 | B11: 10 | C11: Conceptual framing and model | D11: İ revised the factors... here is the draft... suggest improvements / additions: (SUGGEST A GROUP NAME)- EXTERNAL?: Sovet mirası: dominant düşüncə tərzi, iş və təhsil mədəniyyəti, vs. İNSTİTUSİONAL/STRUKTUR AMİLLƏR Vəzifə/təyinat siyasətləri — irəliləyiş meyarları (araşdırma nəşri, tədris keyfiyyəti) Karyera irəliləyişi meyarı — liyaqət vs. qıdəm Sənaye-akademiya əməkdaşlığı mədəniyyəti AKADEMİK HEYƏT AMİLLƏRİ (Human … | E11: Knowledge injection | F11: Directed delegation; Redirection | G11: Directive | H11: conceptual discrimination; methodological judgment; argumentative judgment | I11: Supplies factor groups and a revised causal explanation. | J11: AI organizes and elaborates the proposed categories. | K11: DOCX body elements 1720–1720 | L11: DOCX body elements 1723–1789 | N11: Visible next AI response | O11: Converted DOCX: textbox continuations joined; AI completion/source-check claims are unverified. | P11: =SUM(Q11:X11) -> 3 | Q11: =IF(OR(E11="Delegation",ISNUMBER(SEARCH("; Delegation; ","; "&F11&"; "))),1,0) -> 0 | R11: =IF(OR(E11="Directed delegation",ISNUMBER(SEARCH("; Directed delegation; ","; "&F11&"; "))),1,0) -> 1 | S11: =IF(OR(E11="Evaluation",ISNUMBER(SEARCH("; Evaluation; ","; "&F11&"; "))),1,0) -> 0 | T11: =IF(OR(E11="Correction/Challenge",ISNUMBER(SEARCH("; Correction/Challenge; ","; "&F11&"; "))),1,0) -> 0 | U11: =IF(OR(E11="Redirection",ISNUMBER(SEARCH("; Redirection; ","; "&F11&"; "))),1,0) -> 1 | V11: =IF(OR(E11="Knowledge injection",ISNUMBER(SEARCH("; Knowledge injection; ","; "&F11&"; "))),1,0) -> 1 | W11: =IF(OR(E11="Selection/Rejection",ISNUMBER(SEARCH("; Selection/Rejection; ","; "&F11&"; "))),1,0) -> 0 | X11: =IF(OR(E11="Deliberation",ISNUMBER(SEARCH("; Deliberation; ","; "&F11&"; "))),1,0) -> 0 | Y11: =SUM(Z11:AE11) -> 3 | Z11: =IF(ISNUMBER(SEARCH("; domain correction; ","; "&H11&"; ")),1,0) -> 0 | AA11: =IF(ISNUMBER(SEARCH("; conceptual discrimination; ","; "&H11&"; ")),1,0) -> 1 | AB11: =IF(ISNUMBER(SEARCH("; evidence judgment; ","; "&H11&"; ")),1,0) -> 0 | AC11: =IF(ISNUMBER(SEARCH("; methodological judgment; ","; "&H11&"; ")),1,0) -> 1 | AD11: =IF(ISNUMBER(SEARCH("; argumentative judgment; ","; "&H11&"; ")),1,0) -> 1 | AE11: =IF(ISNUMBER(SEARCH("; genre/writing expertise; ","; "&H11&"; ")),1,0) -> 0 | AF11: =IF(ISNUMBER(SEARCH("; none; ","; "&H11&"; ")),1,0) -> 0
A12: HE-011 | B12: 11 | C12: Conceptual framing and model | D12: How would those impact the education and other factors? What kind of impacts do you think? | E12: Evaluation | G12: Evaluative | H12: none | I12: Asks AI to explain causal impacts; the question itself supplies no explicit judgment. | J12: AI explains proposed causal pathways. | K12: DOCX body elements 1792–1792 | L12: DOCX body elements 1796–1831 | N12: Visible next AI response | O12: Converted DOCX: textbox continuations joined; AI completion/source-check claims are unverified. | P12: =SUM(Q12:X12) -> 1 | Q12: =IF(OR(E12="Delegation",ISNUMBER(SEARCH("; Delegation; ","; "&F12&"; "))),1,0) -> 0 | R12: =IF(OR(E12="Directed delegation",ISNUMBER(SEARCH("; Directed delegation; ","; "&F12&"; "))),1,0) -> 0 | S12: =IF(OR(E12="Evaluation",ISNUMBER(SEARCH("; Evaluation; ","; "&F12&"; "))),1,0) -> 1 | T12: =IF(OR(E12="Correction/Challenge",ISNUMBER(SEARCH("; Correction/Challenge; ","; "&F12&"; "))),1,0) -> 0 | U12: =IF(OR(E12="Redirection",ISNUMBER(SEARCH("; Redirection; ","; "&F12&"; "))),1,0) -> 0 | V12: =IF(OR(E12="Knowledge injection",ISNUMBER(SEARCH("; Knowledge injection; ","; "&F12&"; "))),1,0) -> 0 | W12: =IF(OR(E12="Selection/Rejection",ISNUMBER(SEARCH("; Selection/Rejection; ","; "&F12&"; "))),1,0) -> 0 | X12: =IF(OR(E12="Deliberation",ISNUMBER(SEARCH("; Deliberation; ","; "&F12&"; "))),1,0) -> 0 | Y12: =SUM(Z12:AE12) -> 0 | Z12: =IF(ISNUMBER(SEARCH("; domain correction; ","; "&H12&"; ")),1,0) -> 0 | AA12: =IF(ISNUMBER(SEARCH("; conceptual discrimination; ","; "&H12&"; ")),1,0) -> 0 | AB12: =IF(ISNUMBER(SEARCH("; evidence judgment; ","; "&H12&"; ")),1,0) -> 0 | AC12: =IF(ISNUMBER(SEARCH("; methodological judgment; ","; "&H12&"; ")),1,0) -> 0 | AD12: =IF(ISNUMBER(SEARCH("; argumentative judgment; ","; "&H12&"; ")),1,0) -> 0 | AE12: =IF(ISNUMBER(SEARCH("; genre/writing expertise; ","; "&H12&"; ")),1,0) -> 0 | AF12: =IF(ISNUMBER(SEARCH("; none; ","; "&H12&"; ")),1,0) -> 1
A13: HE-012 | B13: 12 | C13: Conceptual framing and model | D13: shall ve add: Əmək bazarının ehtiyaclari, sahələr?? | E13: Knowledge injection | F13: Directed delegation | G13: Directive | H13: domain correction; conceptual discrimination | I13: Identifies labour-market needs as a missing factor. | J13: AI adds labour-market alignment. | K13: DOCX body elements 1832–1832 | L13: DOCX body elements 1835–1868 | N13: Visible next AI response | O13: Converted DOCX: textbox continuations joined; AI completion/source-check claims are unverified. | P13: =SUM(Q13:X13) -> 2 | Q13: =IF(OR(E13="Delegation",ISNUMBER(SEARCH("; Delegation; ","; "&F13&"; "))),1,0) -> 0 | R13: =IF(OR(E13="Directed delegation",ISNUMBER(SEARCH("; Directed delegation; ","; "&F13&"; "))),1,0) -> 1 | S13: =IF(OR(E13="Evaluation",ISNUMBER(SEARCH("; Evaluation; ","; "&F13&"; "))),1,0) -> 0 | T13: =IF(OR(E13="Correction/Challenge",ISNUMBER(SEARCH("; Correction/Challenge; ","; "&F13&"; "))),1,0) -> 0 | U13: =IF(OR(E13="Redirection",ISNUMBER(SEARCH("; Redirection; ","; "&F13&"; "))),1,0) -> 0 | V13: =IF(OR(E13="Knowledge injection",ISNUMBER(SEARCH("; Knowledge injection; ","; "&F13&"; "))),1,0) -> 1 | W13: =IF(OR(E13="Selection/Rejection",ISNUMBER(SEARCH("; Selection/Rejection; ","; "&F13&"; "))),1,0) -> 0 | X13: =IF(OR(E13="Deliberation",ISNUMBER(SEARCH("; Deliberation; ","; "&F13&"; "))),1,0) -> 0 | Y13: =SUM(Z13:AE13) -> 2 | Z13: =IF(ISNUMBER(SEARCH("; domain correction; ","; "&H13&"; ")),1,0) -> 1 | AA13: =IF(ISNUMBER(SEARCH("; conceptual discrimination; ","; "&H13&"; ")),1,0) -> 1 | AB13: =IF(ISNUMBER(SEARCH("; evidence judgment; ","; "&H13&"; ")),1,0) -> 0 | AC13: =IF(ISNUMBER(SEARCH("; methodological judgment; ","; "&H13&"; ")),1,0) -> 0 | AD13: =IF(ISNUMBER(SEARCH("; argumentative judgment; ","; "&H13&"; ")),1,0) -> 0 | AE13: =IF(ISNUMBER(SEARCH("; genre/writing expertise; ","; "&H13&"; ")),1,0) -> 0 | AF13: =IF(ISNUMBER(SEARCH("; none; ","; "&H13&"; ")),1,0) -> 0
A14: HE-013 | B14: 13 | C14: Conceptual framing and model | D14: explained this a little with what kind of impacts from that. | E14: Delegation | G14: Delegative | H14: none | I14: Requests further explanation without stating an independent substantive criterion. | J14: AI explains the mechanism. | K14: DOCX body elements 1871–1871 | L14: DOCX body elements 1875–1912 | N14: Visible next AI response | O14: Converted DOCX: textbox continuations joined; AI completion/source-check claims are unverified. | P14: =SUM(Q14:X14) -> 1 | Q14: =IF(OR(E14="Delegation",ISNUMBER(SEARCH("; Delegation; ","; "&F14&"; "))),1,0) -> 1 | R14: =IF(OR(E14="Directed delegation",ISNUMBER(SEARCH("; Directed delegation; ","; "&F14&"; "))),1,0) -> 0 | S14: =IF(OR(E14="Evaluation",ISNUMBER(SEARCH("; Evaluation; ","; "&F14&"; "))),1,0) -> 0 | T14: =IF(OR(E14="Correction/Challenge",ISNUMBER(SEARCH("; Correction/Challenge; ","; "&F14&"; "))),1,0) -> 0 | U14: =IF(OR(E14="Redirection",ISNUMBER(SEARCH("; Redirection; ","; "&F14&"; "))),1,0) -> 0 | V14: =IF(OR(E14="Knowledge injection",ISNUMBER(SEARCH("; Knowledge injection; ","; "&F14&"; "))),1,0) -> 0 | W14: =IF(OR(E14="Selection/Rejection",ISNUMBER(SEARCH("; Selection/Rejection; ","; "&F14&"; "))),1,0) -> 0 | X14: =IF(OR(E14="Deliberation",ISNUMBER(SEARCH("; Deliberation; ","; "&F14&"; "))),1,0) -> 0 | Y14: =SUM(Z14:AE14) -> 0 | Z14: =IF(ISNUMBER(SEARCH("; domain correction; ","; "&H14&"; ")),1,0) -> 0 | AA14: =IF(ISNUMBER(SEARCH("; conceptual discrimination; ","; "&H14&"; ")),1,0) -> 0 | AB14: =IF(ISNUMBER(SEARCH("; evidence judgment; ","; "&H14&"; ")),1,0) -> 0 | AC14: =IF(ISNUMBER(SEARCH("; methodological judgment; ","; "&H14&"; ")),1,0) -> 0 | AD14: =IF(ISNUMBER(SEARCH("; argumentative judgment; ","; "&H14&"; ")),1,0) -> 0 | AE14: =IF(ISNUMBER(SEARCH("; genre/writing expertise; ","; "&H14&"; ")),1,0) -> 0 | AF14: =IF(ISNUMBER(SEARCH("; none; ","; "&H14&"; ")),1,0) -> 1
A15: HE-014 | B15: 14 | C15: Conceptual framing and model | D15: Now I see what you mean. Uh, put the two extremes of it, the terminology. Um, give me better phrases. Perhaps something you can say, shallow versus in-depth and, uh, resolved to even something like that, uh, as the goals are accurate station and, uh, quality assurance. | E15: Directed delegation | F15: Knowledge injection | G15: Directive | H15: conceptual discrimination; genre/writing expertise | I15: Specifies shallow/deep endpoints for the model’s wording. | J15: AI proposes contrasting labels. | K15: DOCX body elements 1915–1915 | L15: DOCX body elements 1919–1956 | N15: Visible next AI response | O15: Converted DOCX: textbox continuations joined; AI completion/source-check claims are unverified. | P15: =SUM(Q15:X15) -> 2 | Q15: =IF(OR(E15="Delegation",ISNUMBER(SEARCH("; Delegation; ","; "&F15&"; "))),1,0) -> 0 | R15: =IF(OR(E15="Directed delegation",ISNUMBER(SEARCH("; Directed delegation; ","; "&F15&"; "))),1,0) -> 1 | S15: =IF(OR(E15="Evaluation",ISNUMBER(SEARCH("; Evaluation; ","; "&F15&"; "))),1,0) -> 0 | T15: =IF(OR(E15="Correction/Challenge",ISNUMBER(SEARCH("; Correction/Challenge; ","; "&F15&"; "))),1,0) -> 0 | U15: =IF(OR(E15="Redirection",ISNUMBER(SEARCH("; Redirection; ","; "&F15&"; "))),1,0) -> 0 | V15: =IF(OR(E15="Knowledge injection",ISNUMBER(SEARCH("; Knowledge injection; ","; "&F15&"; "))),1,0) -> 1 | W15: =IF(OR(E15="Selection/Rejection",ISNUMBER(SEARCH("; Selection/Rejection; ","; "&F15&"; "))),1,0) -> 0 | X15: =IF(OR(E15="Deliberation",ISNUMBER(SEARCH("; Deliberation; ","; "&F15&"; "))),1,0) -> 0 | Y15: =SUM(Z15:AE15) -> 2 | Z15: =IF(ISNUMBER(SEARCH("; domain correction; ","; "&H15&"; ")),1,0) -> 0 | AA15: =IF(ISNUMBER(SEARCH("; conceptual discrimination; ","; "&H15&"; ")),1,0) -> 1 | AB15: =IF(ISNUMBER(SEARCH("; evidence judgment; ","; "&H15&"; ")),1,0) -> 0 | AC15: =IF(ISNUMBER(SEARCH("; methodological judgment; ","; "&H15&"; ")),1,0) -> 0 | AD15: =IF(ISNUMBER(SEARCH("; argumentative judgment; ","; "&H15&"; ")),1,0) -> 0 | AE15: =IF(ISNUMBER(SEARCH("; genre/writing expertise; ","; "&H15&"; ")),1,0) -> 1 | AF15: =IF(ISNUMBER(SEARCH("; none; ","; "&H15&"; ")),1,0) -> 0
A16: HE-015 | B16: 15 | C16: Conceptual framing and model | D16: Bürokratik yük — inzibati işlərin akademik vaxtı nə qədər "yeyməsi" or "yeməsi"? | E16: Correction/Challenge | G16: Critical | H16: genre/writing expertise | I16: Identifies an Azerbaijani spelling choice requiring correction. | J16: AI corrects the spelling. | K16: DOCX body elements 1957–1957 | L16: DOCX body elements 1960–1970 | N16: Visible next AI response | O16: Converted DOCX: textbox continuations joined; AI completion/source-check claims are unverified. | P16: =SUM(Q16:X16) -> 1 | Q16: =IF(OR(E16="Delegation",ISNUMBER(SEARCH("; Delegation; ","; "&F16&"; "))),1,0) -> 0 | R16: =IF(OR(E16="Directed delegation",ISNUMBER(SEARCH("; Directed delegation; ","; "&F16&"; "))),1,0) -> 0 | S16: =IF(OR(E16="Evaluation",ISNUMBER(SEARCH("; Evaluation; ","; "&F16&"; "))),1,0) -> 0 | T16: =IF(OR(E16="Correction/Challenge",ISNUMBER(SEARCH("; Correction/Challenge; ","; "&F16&"; "))),1,0) -> 1 | U16: =IF(OR(E16="Redirection",ISNUMBER(SEARCH("; Redirection; ","; "&F16&"; "))),1,0) -> 0 | V16: =IF(OR(E16="Knowledge injection",ISNUMBER(SEARCH("; Knowledge injection; ","; "&F16&"; "))),1,0) -> 0 | W16: =IF(OR(E16="Selection/Rejection",ISNUMBER(SEARCH("; Selection/Rejection; ","; "&F16&"; "))),1,0) -> 0 | X16: =IF(OR(E16="Deliberation",ISNUMBER(SEARCH("; Deliberation; ","; "&F16&"; "))),1,0) -> 0 | Y16: =SUM(Z16:AE16) -> 1 | Z16: =IF(ISNUMBER(SEARCH("; domain correction; ","; "&H16&"; ")),1,0) -> 0 | AA16: =IF(ISNUMBER(SEARCH("; conceptual discrimination; ","; "&H16&"; ")),1,0) -> 0 | AB16: =IF(ISNUMBER(SEARCH("; evidence judgment; ","; "&H16&"; ")),1,0) -> 0 | AC16: =IF(ISNUMBER(SEARCH("; methodological judgment; ","; "&H16&"; ")),1,0) -> 0 | AD16: =IF(ISNUMBER(SEARCH("; argumentative judgment; ","; "&H16&"; ")),1,0) -> 0 | AE16: =IF(ISNUMBER(SEARCH("; genre/writing expertise; ","; "&H16&"; ")),1,0) -> 1 | AF16: =IF(ISNUMBER(SEARCH("; none; ","; "&H16&"; ")),1,0) -> 0
A17: HE-016 | B17: 16 | C17: Conceptual framing and model | D17: İngilis dili səriştəsi — beynəlxalq elmi ədəbiyyata çıxış və əməkdaşlıq üçün açar amilNotethat in this paper we focus on education quality and not research quality. So in English, yeah, language knowledge is good, but it will help in, uh, to help an academic, uh, read the latest information and follow them. So not about the research, but about his, uh, domain knowledge, uh, getting updated | E17: Correction/Challenge | F17: Redirection; Knowledge injection | G17: Critical | H17: domain correction; conceptual discrimination; argumentative judgment | I17: Distinguishes educational from research quality and supplies the knowledge-access mechanism. | J17: AI refocuses the explanation on teaching and current knowledge. | K17: DOCX body elements 1971–1971 | L17: DOCX body elements 1974–1999 | N17: Visible next AI response | O17: Converted DOCX: textbox continuations joined; AI completion/source-check claims are unverified. | P17: =SUM(Q17:X17) -> 3 | Q17: =IF(OR(E17="Delegation",ISNUMBER(SEARCH("; Delegation; ","; "&F17&"; "))),1,0) -> 0 | R17: =IF(OR(E17="Directed delegation",ISNUMBER(SEARCH("; Directed delegation; ","; "&F17&"; "))),1,0) -> 0 | S17: =IF(OR(E17="Evaluation",ISNUMBER(SEARCH("; Evaluation; ","; "&F17&"; "))),1,0) -> 0 | T17: =IF(OR(E17="Correction/Challenge",ISNUMBER(SEARCH("; Correction/Challenge; ","; "&F17&"; "))),1,0) -> 1 | U17: =IF(OR(E17="Redirection",ISNUMBER(SEARCH("; Redirection; ","; "&F17&"; "))),1,0) -> 1 | V17: =IF(OR(E17="Knowledge injection",ISNUMBER(SEARCH("; Knowledge injection; ","; "&F17&"; "))),1,0) -> 1 | W17: =IF(OR(E17="Selection/Rejection",ISNUMBER(SEARCH("; Selection/Rejection; ","; "&F17&"; "))),1,0) -> 0 | X17: =IF(OR(E17="Deliberation",ISNUMBER(SEARCH("; Deliberation; ","; "&F17&"; "))),1,0) -> 0 | Y17: =SUM(Z17:AE17) -> 3 | Z17: =IF(ISNUMBER(SEARCH("; domain correction; ","; "&H17&"; ")),1,0) -> 1 | AA17: =IF(ISNUMBER(SEARCH("; conceptual discrimination; ","; "&H17&"; ")),1,0) -> 1 | AB17: =IF(ISNUMBER(SEARCH("; evidence judgment; ","; "&H17&"; ")),1,0) -> 0 | AC17: =IF(ISNUMBER(SEARCH("; methodological judgment; ","; "&H17&"; ")),1,0) -> 0 | AD17: =IF(ISNUMBER(SEARCH("; argumentative judgment; ","; "&H17&"; ")),1,0) -> 1 | AE17: =IF(ISNUMBER(SEARCH("; genre/writing expertise; ","; "&H17&"; ")),1,0) -> 0 | AF17: =IF(ISNUMBER(SEARCH("; none; ","; "&H17&"; ")),1,0) -> 0
A18: HE-017 | B18: 17 | C18: Conceptual framing and model | D18: Ailə/sosial-iqtisadi arxa plan (təhsilə çıxış bərabərsizliyi)- Why is this important? - | E18: Evaluation | G18: Evaluative | H18: conceptual discrimination | I18: Questions the causal relevance of family background. | J18: AI explains potential mechanisms. | K18: DOCX body elements 2000–2000 | L18: DOCX body elements 2003–2032 | N18: Visible next AI response | O18: Converted DOCX: textbox continuations joined; AI completion/source-check claims are unverified. | P18: =SUM(Q18:X18) -> 1 | Q18: =IF(OR(E18="Delegation",ISNUMBER(SEARCH("; Delegation; ","; "&F18&"; "))),1,0) -> 0 | R18: =IF(OR(E18="Directed delegation",ISNUMBER(SEARCH("; Directed delegation; ","; "&F18&"; "))),1,0) -> 0 | S18: =IF(OR(E18="Evaluation",ISNUMBER(SEARCH("; Evaluation; ","; "&F18&"; "))),1,0) -> 1 | T18: =IF(OR(E18="Correction/Challenge",ISNUMBER(SEARCH("; Correction/Challenge; ","; "&F18&"; "))),1,0) -> 0 | U18: =IF(OR(E18="Redirection",ISNUMBER(SEARCH("; Redirection; ","; "&F18&"; "))),1,0) -> 0 | V18: =IF(OR(E18="Knowledge injection",ISNUMBER(SEARCH("; Knowledge injection; ","; "&F18&"; "))),1,0) -> 0 | W18: =IF(OR(E18="Selection/Rejection",ISNUMBER(SEARCH("; Selection/Rejection; ","; "&F18&"; "))),1,0) -> 0 | X18: =IF(OR(E18="Deliberation",ISNUMBER(SEARCH("; Deliberation; ","; "&F18&"; "))),1,0) -> 0 | Y18: =SUM(Z18:AE18) -> 1 | Z18: =IF(ISNUMBER(SEARCH("; domain correction; ","; "&H18&"; ")),1,0) -> 0 | AA18: =IF(ISNUMBER(SEARCH("; conceptual discrimination; ","; "&H18&"; ")),1,0) -> 1 | AB18: =IF(ISNUMBER(SEARCH("; evidence judgment; ","; "&H18&"; ")),1,0) -> 0 | AC18: =IF(ISNUMBER(SEARCH("; methodological judgment; ","; "&H18&"; ")),1,0) -> 0 | AD18: =IF(ISNUMBER(SEARCH("; argumentative judgment; ","; "&H18&"; ")),1,0) -> 0 | AE18: =IF(ISNUMBER(SEARCH("; genre/writing expertise; ","; "&H18&"; ")),1,0) -> 0 | AF18: =IF(ISNUMBER(SEARCH("; none; ","; "&H18&"; ")),1,0) -> 0
A19: HE-018 | B19: 18 | C19: Conceptual framing and model | D19: better vay of saying this: Ailə/sosial-iqtisadi arxa plan (təhsilə çıxış bərabərsizliyi) | E19: Directed delegation | G19: Directive | H19: genre/writing expertise | I19: Requests a better phrase for family background. | J19: AI proposes alternatives. | K19: DOCX body elements 2033–2033 | L19: DOCX body elements 2036–2056 | N19: Visible next AI response | O19: Converted DOCX: textbox continuations joined; AI completion/source-check claims are unverified. | P19: =SUM(Q19:X19) -> 1 | Q19: =IF(OR(E19="Delegation",ISNUMBER(SEARCH("; Delegation; ","; "&F19&"; "))),1,0) -> 0 | R19: =IF(OR(E19="Directed delegation",ISNUMBER(SEARCH("; Directed delegation; ","; "&F19&"; "))),1,0) -> 1 | S19: =IF(OR(E19="Evaluation",ISNUMBER(SEARCH("; Evaluation; ","; "&F19&"; "))),1,0) -> 0 | T19: =IF(OR(E19="Correction/Challenge",ISNUMBER(SEARCH("; Correction/Challenge; ","; "&F19&"; "))),1,0) -> 0 | U19: =IF(OR(E19="Redirection",ISNUMBER(SEARCH("; Redirection; ","; "&F19&"; "))),1,0) -> 0 | V19: =IF(OR(E19="Knowledge injection",ISNUMBER(SEARCH("; Knowledge injection; ","; "&F19&"; "))),1,0) -> 0 | W19: =IF(OR(E19="Selection/Rejection",ISNUMBER(SEARCH("; Selection/Rejection; ","; "&F19&"; "))),1,0) -> 0 | X19: =IF(OR(E19="Deliberation",ISNUMBER(SEARCH("; Deliberation; ","; "&F19&"; "))),1,0) -> 0 | Y19: =SUM(Z19:AE19) -> 1 | Z19: =IF(ISNUMBER(SEARCH("; domain correction; ","; "&H19&"; ")),1,0) -> 0 | AA19: =IF(ISNUMBER(SEARCH("; conceptual discrimination; ","; "&H19&"; ")),1,0) -> 0 | AB19: =IF(ISNUMBER(SEARCH("; evidence judgment; ","; "&H19&"; ")),1,0) -> 0 | AC19: =IF(ISNUMBER(SEARCH("; methodological judgment; ","; "&H19&"; ")),1,0) -> 0 | AD19: =IF(ISNUMBER(SEARCH("; argumentative judgment; ","; "&H19&"; ")),1,0) -> 0 | AE19: =IF(ISNUMBER(SEARCH("; genre/writing expertise; ","; "&H19&"; ")),1,0) -> 1 | AF19: =IF(ISNUMBER(SEARCH("; none; ","; "&H19&"; ")),1,0) -> 0
A20: HE-019 | B20: 19 | C20: Conceptual framing and model | D20: So just, uh, another phrase for this--- VASİTƏÇİ/YARANMA AMİLLƏRİ (Mediating) | E20: Evaluation | G20: Evaluative | H20: conceptual discrimination; genre/writing expertise | I20: Seeks an alternative category name for mediating factors. | J20: AI offers terminology options. | K20: DOCX body elements 2057–2057 | L20: DOCX body elements 2060–2081 | N20: Visible next AI response | O20: Converted DOCX: textbox continuations joined; AI completion/source-check claims are unverified. | P20: =SUM(Q20:X20) -> 1 | Q20: =IF(OR(E20="Delegation",ISNUMBER(SEARCH("; Delegation; ","; "&F20&"; "))),1,0) -> 0 | R20: =IF(OR(E20="Directed delegation",ISNUMBER(SEARCH("; Directed delegation; ","; "&F20&"; "))),1,0) -> 0 | S20: =IF(OR(E20="Evaluation",ISNUMBER(SEARCH("; Evaluation; ","; "&F20&"; "))),1,0) -> 1 | T20: =IF(OR(E20="Correction/Challenge",ISNUMBER(SEARCH("; Correction/Challenge; ","; "&F20&"; "))),1,0) -> 0 | U20: =IF(OR(E20="Redirection",ISNUMBER(SEARCH("; Redirection; ","; "&F20&"; "))),1,0) -> 0 | V20: =IF(OR(E20="Knowledge injection",ISNUMBER(SEARCH("; Knowledge injection; ","; "&F20&"; "))),1,0) -> 0 | W20: =IF(OR(E20="Selection/Rejection",ISNUMBER(SEARCH("; Selection/Rejection; ","; "&F20&"; "))),1,0) -> 0 | X20: =IF(OR(E20="Deliberation",ISNUMBER(SEARCH("; Deliberation; ","; "&F20&"; "))),1,0) -> 0 | Y20: =SUM(Z20:AE20) -> 2 | Z20: =IF(ISNUMBER(SEARCH("; domain correction; ","; "&H20&"; ")),1,0) -> 0 | AA20: =IF(ISNUMBER(SEARCH("; conceptual discrimination; ","; "&H20&"; ")),1,0) -> 1 | AB20: =IF(ISNUMBER(SEARCH("; evidence judgment; ","; "&H20&"; ")),1,0) -> 0 | AC20: =IF(ISNUMBER(SEARCH("; methodological judgment; ","; "&H20&"; ")),1,0) -> 0 | AD20: =IF(ISNUMBER(SEARCH("; argumentative judgment; ","; "&H20&"; ")),1,0) -> 0 | AE20: =IF(ISNUMBER(SEARCH("; genre/writing expertise; ","; "&H20&"; ")),1,0) -> 1 | AF20: =IF(ISNUMBER(SEARCH("; none; ","; "&H20&"; ")),1,0) -> 0
A21: HE-020 | B21: 20 | C21: Conceptual framing and model | D21: Any term that is better for every regular person to understand. | E21: Redirection | F21: Directed delegation | G21: Directive | H21: genre/writing expertise | I21: Prioritizes a term understandable to lay readers. | J21: AI suggests accessible wording. | K21: DOCX body elements 2082–2082 | L21: DOCX body elements 2085–2117 | N21: Visible next AI response | O21: Converted DOCX: textbox continuations joined; AI completion/source-check claims are unverified. | P21: =SUM(Q21:X21) -> 2 | Q21: =IF(OR(E21="Delegation",ISNUMBER(SEARCH("; Delegation; ","; "&F21&"; "))),1,0) -> 0 | R21: =IF(OR(E21="Directed delegation",ISNUMBER(SEARCH("; Directed delegation; ","; "&F21&"; "))),1,0) -> 1 | S21: =IF(OR(E21="Evaluation",ISNUMBER(SEARCH("; Evaluation; ","; "&F21&"; "))),1,0) -> 0 | T21: =IF(OR(E21="Correction/Challenge",ISNUMBER(SEARCH("; Correction/Challenge; ","; "&F21&"; "))),1,0) -> 0 | U21: =IF(OR(E21="Redirection",ISNUMBER(SEARCH("; Redirection; ","; "&F21&"; "))),1,0) -> 1 | V21: =IF(OR(E21="Knowledge injection",ISNUMBER(SEARCH("; Knowledge injection; ","; "&F21&"; "))),1,0) -> 0 | W21: =IF(OR(E21="Selection/Rejection",ISNUMBER(SEARCH("; Selection/Rejection; ","; "&F21&"; "))),1,0) -> 0 | X21: =IF(OR(E21="Deliberation",ISNUMBER(SEARCH("; Deliberation; ","; "&F21&"; "))),1,0) -> 0 | Y21: =SUM(Z21:AE21) -> 1 | Z21: =IF(ISNUMBER(SEARCH("; domain correction; ","; "&H21&"; ")),1,0) -> 0 | AA21: =IF(ISNUMBER(SEARCH("; conceptual discrimination; ","; "&H21&"; ")),1,0) -> 0 | AB21: =IF(ISNUMBER(SEARCH("; evidence judgment; ","; "&H21&"; ")),1,0) -> 0 | AC21: =IF(ISNUMBER(SEARCH("; methodological judgment; ","; "&H21&"; ")),1,0) -> 0 | AD21: =IF(ISNUMBER(SEARCH("; argumentative judgment; ","; "&H21&"; ")),1,0) -> 0 | AE21: =IF(ISNUMBER(SEARCH("; genre/writing expertise; ","; "&H21&"; ")),1,0) -> 1 | AF21: =IF(ISNUMBER(SEARCH("; none; ","; "&H21&"; ")),1,0) -> 0
A22: HE-021 | B22: 21 | C22: Conceptual framing and model | D22: Explain why this one is related to our context and what impacts. Geosiyasi kontekst: qonşu ölkələrlə (Türkiyə, Rusiya, İran) tarixi əlaqələr — təhsil və akademik istiqamətlərinə təsirləri | E22: Evaluation | G22: Evaluative | H22: conceptual discrimination; argumentative judgment | I22: Questions geopolitical factors’ relevance and effects. | J22: AI explains their proposed place in the model. | K22: DOCX body elements 2118–2118 | L22: DOCX body elements 2121–2160 | N22: Visible next AI response | O22: Converted DOCX: textbox continuations joined; AI completion/source-check claims are unverified. | P22: =SUM(Q22:X22) -> 1 | Q22: =IF(OR(E22="Delegation",ISNUMBER(SEARCH("; Delegation; ","; "&F22&"; "))),1,0) -> 0 | R22: =IF(OR(E22="Directed delegation",ISNUMBER(SEARCH("; Directed delegation; ","; "&F22&"; "))),1,0) -> 0 | S22: =IF(OR(E22="Evaluation",ISNUMBER(SEARCH("; Evaluation; ","; "&F22&"; "))),1,0) -> 1 | T22: =IF(OR(E22="Correction/Challenge",ISNUMBER(SEARCH("; Correction/Challenge; ","; "&F22&"; "))),1,0) -> 0 | U22: =IF(OR(E22="Redirection",ISNUMBER(SEARCH("; Redirection; ","; "&F22&"; "))),1,0) -> 0 | V22: =IF(OR(E22="Knowledge injection",ISNUMBER(SEARCH("; Knowledge injection; ","; "&F22&"; "))),1,0) -> 0 | W22: =IF(OR(E22="Selection/Rejection",ISNUMBER(SEARCH("; Selection/Rejection; ","; "&F22&"; "))),1,0) -> 0 | X22: =IF(OR(E22="Deliberation",ISNUMBER(SEARCH("; Deliberation; ","; "&F22&"; "))),1,0) -> 0 | Y22: =SUM(Z22:AE22) -> 2 | Z22: =IF(ISNUMBER(SEARCH("; domain correction; ","; "&H22&"; ")),1,0) -> 0 | AA22: =IF(ISNUMBER(SEARCH("; conceptual discrimination; ","; "&H22&"; ")),1,0) -> 1 | AB22: =IF(ISNUMBER(SEARCH("; evidence judgment; ","; "&H22&"; ")),1,0) -> 0 | AC22: =IF(ISNUMBER(SEARCH("; methodological judgment; ","; "&H22&"; ")),1,0) -> 0 | AD22: =IF(ISNUMBER(SEARCH("; argumentative judgment; ","; "&H22&"; ")),1,0) -> 1 | AE22: =IF(ISNUMBER(SEARCH("; genre/writing expertise; ","; "&H22&"; ")),1,0) -> 0 | AF22: =IF(ISNUMBER(SEARCH("; none; ","; "&H22&"; ")),1,0) -> 0
A23: HE-022 | B23: 22 | C23: Conceptual framing and model | D23: give a slightly expanded prhase for the diagramç:? Dinamik akademik mühit (NE demək ?) | E23: Directed delegation | G23: Directive | H23: genre/writing expertise | I23: Requests expansion of a short academic-environment label. | J23: AI supplies fuller wording. | K23: DOCX body elements 2162–2162 | L23: DOCX body elements 2165–2187 | N23: Visible next AI response | O23: Converted DOCX: textbox continuations joined; AI completion/source-check claims are unverified. | P23: =SUM(Q23:X23) -> 1 | Q23: =IF(OR(E23="Delegation",ISNUMBER(SEARCH("; Delegation; ","; "&F23&"; "))),1,0) -> 0 | R23: =IF(OR(E23="Directed delegation",ISNUMBER(SEARCH("; Directed delegation; ","; "&F23&"; "))),1,0) -> 1 | S23: =IF(OR(E23="Evaluation",ISNUMBER(SEARCH("; Evaluation; ","; "&F23&"; "))),1,0) -> 0 | T23: =IF(OR(E23="Correction/Challenge",ISNUMBER(SEARCH("; Correction/Challenge; ","; "&F23&"; "))),1,0) -> 0 | U23: =IF(OR(E23="Redirection",ISNUMBER(SEARCH("; Redirection; ","; "&F23&"; "))),1,0) -> 0 | V23: =IF(OR(E23="Knowledge injection",ISNUMBER(SEARCH("; Knowledge injection; ","; "&F23&"; "))),1,0) -> 0 | W23: =IF(OR(E23="Selection/Rejection",ISNUMBER(SEARCH("; Selection/Rejection; ","; "&F23&"; "))),1,0) -> 0 | X23: =IF(OR(E23="Deliberation",ISNUMBER(SEARCH("; Deliberation; ","; "&F23&"; "))),1,0) -> 0 | Y23: =SUM(Z23:AE23) -> 1 | Z23: =IF(ISNUMBER(SEARCH("; domain correction; ","; "&H23&"; ")),1,0) -> 0 | AA23: =IF(ISNUMBER(SEARCH("; conceptual discrimination; ","; "&H23&"; ")),1,0) -> 0 | AB23: =IF(ISNUMBER(SEARCH("; evidence judgment; ","; "&H23&"; ")),1,0) -> 0 | AC23: =IF(ISNUMBER(SEARCH("; methodological judgment; ","; "&H23&"; ")),1,0) -> 0 | AD23: =IF(ISNUMBER(SEARCH("; argumentative judgment; ","; "&H23&"; ")),1,0) -> 0 | AE23: =IF(ISNUMBER(SEARCH("; genre/writing expertise; ","; "&H23&"; ")),1,0) -> 1 | AF23: =IF(ISNUMBER(SEARCH("; none; ","; "&H23&"; ")),1,0) -> 0
A24: HE-023 | B24: 23 | C24: Conceptual framing and model | D24: trans to AZ: Employability of graduates | E24: Directed delegation | G24: Directive | H24: none | I24: Requests translation of a term without substantive elaboration. | J24: AI translates graduate employability. | K24: DOCX body elements 2188–2188 | L24: DOCX body elements 2191–2201 | N24: Visible next AI response | O24: Converted DOCX: textbox continuations joined; AI completion/source-check claims are unverified. | P24: =SUM(Q24:X24) -> 1 | Q24: =IF(OR(E24="Delegation",ISNUMBER(SEARCH("; Delegation; ","; "&F24&"; "))),1,0) -> 0 | R24: =IF(OR(E24="Directed delegation",ISNUMBER(SEARCH("; Directed delegation; ","; "&F24&"; "))),1,0) -> 1 | S24: =IF(OR(E24="Evaluation",ISNUMBER(SEARCH("; Evaluation; ","; "&F24&"; "))),1,0) -> 0 | T24: =IF(OR(E24="Correction/Challenge",ISNUMBER(SEARCH("; Correction/Challenge; ","; "&F24&"; "))),1,0) -> 0 | U24: =IF(OR(E24="Redirection",ISNUMBER(SEARCH("; Redirection; ","; "&F24&"; "))),1,0) -> 0 | V24: =IF(OR(E24="Knowledge injection",ISNUMBER(SEARCH("; Knowledge injection; ","; "&F24&"; "))),1,0) -> 0 | W24: =IF(OR(E24="Selection/Rejection",ISNUMBER(SEARCH("; Selection/Rejection; ","; "&F24&"; "))),1,0) -> 0 | X24: =IF(OR(E24="Deliberation",ISNUMBER(SEARCH("; Deliberation; ","; "&F24&"; "))),1,0) -> 0 | Y24: =SUM(Z24:AE24) -> 0 | Z24: =IF(ISNUMBER(SEARCH("; domain correction; ","; "&H24&"; ")),1,0) -> 0 | AA24: =IF(ISNUMBER(SEARCH("; conceptual discrimination; ","; "&H24&"; ")),1,0) -> 0 | AB24: =IF(ISNUMBER(SEARCH("; evidence judgment; ","; "&H24&"; ")),1,0) -> 0 | AC24: =IF(ISNUMBER(SEARCH("; methodological judgment; ","; "&H24&"; ")),1,0) -> 0 | AD24: =IF(ISNUMBER(SEARCH("; argumentative judgment; ","; "&H24&"; ")),1,0) -> 0 | AE24: =IF(ISNUMBER(SEARCH("; genre/writing expertise; ","; "&H24&"; ")),1,0) -> 0 | AF24: =IF(ISNUMBER(SEARCH("; none; ","; "&H24&"; ")),1,0) -> 1
A25: HE-024 | B25: 24 | C25: Conceptual framing and model | D25: İ designed the model.. reviev it | E25: Evaluation | F25: Knowledge injection | G25: Evaluative | H25: methodological judgment | I25: Supplies the researcher’s model for assessment. | J25: AI reviews the model and recommends refinements. | K25: DOCX body elements 2204–2204 | L25: DOCX body elements 2208–2245 | N25: Visible next AI response | O25: Converted DOCX: textbox continuations joined; AI completion/source-check claims are unverified. | P25: =SUM(Q25:X25) -> 2 | Q25: =IF(OR(E25="Delegation",ISNUMBER(SEARCH("; Delegation; ","; "&F25&"; "))),1,0) -> 0 | R25: =IF(OR(E25="Directed delegation",ISNUMBER(SEARCH("; Directed delegation; ","; "&F25&"; "))),1,0) -> 0 | S25: =IF(OR(E25="Evaluation",ISNUMBER(SEARCH("; Evaluation; ","; "&F25&"; "))),1,0) -> 1 | T25: =IF(OR(E25="Correction/Challenge",ISNUMBER(SEARCH("; Correction/Challenge; ","; "&F25&"; "))),1,0) -> 0 | U25: =IF(OR(E25="Redirection",ISNUMBER(SEARCH("; Redirection; ","; "&F25&"; "))),1,0) -> 0 | V25: =IF(OR(E25="Knowledge injection",ISNUMBER(SEARCH("; Knowledge injection; ","; "&F25&"; "))),1,0) -> 1 | W25: =IF(OR(E25="Selection/Rejection",ISNUMBER(SEARCH("; Selection/Rejection; ","; "&F25&"; "))),1,0) -> 0 | X25: =IF(OR(E25="Deliberation",ISNUMBER(SEARCH("; Deliberation; ","; "&F25&"; "))),1,0) -> 0 | Y25: =SUM(Z25:AE25) -> 1 | Z25: =IF(ISNUMBER(SEARCH("; domain correction; ","; "&H25&"; ")),1,0) -> 0 | AA25: =IF(ISNUMBER(SEARCH("; conceptual discrimination; ","; "&H25&"; ")),1,0) -> 0 | AB25: =IF(ISNUMBER(SEARCH("; evidence judgment; ","; "&H25&"; ")),1,0) -> 0 | AC25: =IF(ISNUMBER(SEARCH("; methodological judgment; ","; "&H25&"; ")),1,0) -> 1 | AD25: =IF(ISNUMBER(SEARCH("; argumentative judgment; ","; "&H25&"; ")),1,0) -> 0 | AE25: =IF(ISNUMBER(SEARCH("; genre/writing expertise; ","; "&H25&"; ")),1,0) -> 0 | AF25: =IF(ISNUMBER(SEARCH("; none; ","; "&H25&"; ")),1,0) -> 0
